Workbook

Sheet 검토요약
A1: INNONOW 통합 가상 데이터 확장 v0.2
A3: 장면 1·2 연결 / 기존사업 A제품·울산공장 / 전 항목 가상 데이터 / 기본안은 2027-07-01 적용
A5: 구분 | B5: 핵심 항목 | C5: 값·결과 | D5: 설명
A6: 검토 | B6: 공통부품 기존 → 요청 → 협상 | C6: 2,000 → 2,200 → 2,120원 | D6: 이번 가상값 제안. 기존단가 대비 요청10%, 협상6%. a·b 각1개 사용.
A7: 구매 | B7: 당해연도 잔여 구매 증가 | C7: =단가안비교!H8 -> 9364320 | D7: 협상안 / 2027-07~12 / 원
A8: 구매 | B8: 향후12개월 구매 증가 | C8: =단가안비교!I8 -> 18817440 | D8: 협상안 / 2027-07~2028-06 / 원
A9: 협상 | B9: 요청 대비 12개월 부담 감소 | C9: =단가안비교!N8 -> 12544960 | D9: 원. 가격 인상 부담은 남아 있으며 위험 해소로 보지 않음.
A10: 판단 | B10: 종합위험 / 대표 승인 | C10: =단가안비교!L9&" / "&단가안비교!M9 -> 중요 / 대표 대상 | D10: 비율 위험은 관심, 구매 증가액 위험은 중요. 결재 기준은 별도 적용.
A11: 손익 | B11: 2027 물량 감소 순영향 | C11: =통합손익!I21 -> -14000000 | D11: 장면1 F01→F02 차이 / 원
A12: 손익 | B12: 2027 단가 인상 추가 영향 | C12: =통합손익!J21 -> -9364320 | D12: 장면2 F02 수량 × 승인단가 인상 / 원
A13: 손익 | B13: 2027 통합 관리손익 | C13: =통합손익!K21 -> 3299986680 | D13: 고정비 차감 후 공장 범위 / 원
A14: 손익 | B14: 2027 Target 대비 부족 | C14: =통합손익!N21 -> 177303320 | D14: Target은 변경하지 않음 / 원
A15: 가정 | B15: 2028 내부가정 | C15: 동일월 F01의 97% | D15: 2028-01~07 제공. 판매단가·원가·월고정비는 유지. 실제 고객계획 아님.
A16: 시연 | B16: 단계별 적재 | C16: D00 초기, 이후 실행 시 생성 | D16: 향후 승인·협상 기록은 기대 fixture이며 시작 화면에 미리 노출하지 않음.
A17: 시연 | B17: 외부 협상기한 | C17: 담당자가 건별 입력 | D17: 가상 기본 기한 2027-06-21 18:00. 내부 SLA와 구분.
A18: 개발 | B18: 인계 범위 | C18: 단가·물량·원가·손익·증빙·상태·예외 | D18: U21~27, S01~14, CT21~30, D00~12 연결. 권한/API 상세는 다음 구현명세.
A19: 확인 | B19: 검토 권장 위치 | C19: 설정 / 단가안비교 / 통합손익 | D19: 가상 가격·2028 감소가정·기본 업무일정의 자연스러움을 우선 검토.
A20: 한계 | B20: 구매 증가와 CM 감소의 동일성 | C20: 시차0·재고0 단순화 | D20: 일반 회계 등식이 아님. 두 지표는 별도 보관. 향후12개월 Target은 미설정.

Sheet 설정
A1: 통합 가상 데이터 설정
A3: 노란 값은 이번 데이터 설계의 가상 입력값입니다. 날짜·금액·내부가정 변경 시 계산표가 갱신됩니다.
A5: key | B5: value | C5: 의미 | D5: 기준 및 사용법
A6: effective_date | B6: 46569 | C6: 기본 적용일 | D6: 월초만 지원. 월중 적용은 구현 확장 필요
A7: next_year_factor | B7: 0.97 | C7: 2028 물량 가정 | D7: 2027 동일월 F01 ×97%, 정수 반올림. 2028-01~07 내부가정
A8: rate_attention | B8: 0.05 | C8: 단가 인상률 관심 | D8: 품목별 기존단가 대비
A9: rate_critical | B9: 0.1 | C9: 단가 인상률 중요 | D9: 정확히 경계값 포함
A10: amount_attention | B10: 5000000 | C10: 구매 증가액 관심 | D10: 향후12개월·공급사 요청건 합계·VAT 제외
A11: amount_critical | B11: 10000000 | C11: 구매 증가액 중요 | D11: 손익 감소액과 구분
A12: ceo_threshold | B12: 10000000 | C12: 대표 승인 기준 | D12: 최종 기안 향후12개월 구매 증가액 이상
A13: old_price | B13: 2000 | C13: 기존 공통부품 단가 | D13: C01 외주비에 이미 포함된 부품 P-COM01·원/개
A14: request_price | B14: 2200 | C14: 공급사 요청 단가 | D14: 가상값·10% 인상
A15: internal_offer | B15: 2100 | C15: 내부 협상 제시 단가 | D15: 가상값·실제 합의와 구분
A16: negotiated_price | B16: 2120 | C16: 1차 협상 잠정 단가 | D16: 가상값·6% 인상·대표 승인 시연 유지
A17: proposal_price | B17: 2120 | C17: 상신 단가 | D17: 협상안과 다르면 사유 입력 및 새 분석 필요
A18: approved_price | B18: 2120 | C18: 승인 결과 예정값 | D18: 시연 D09 이후 생성할 기대값. 초기 시드에 승인값 적재 금지
A19: negotiation_due | B19: 2027-06-21 18:00:00 KST | C19: 외부협상 기한 | D19: 구매담당 수동 입력. 건별 변경 가능·내부 SLA와 별도
A20: selected_price_version | B20: PV-APP01 | C20: 장면3 최종 비교안 | D20: 승인 결과 기준 기대 데이터. 초기화 시 아직 존재하지 않음
A21: fixed_monthly | B21: 370000000 | C21: 2028 월 고정비 가정 | D21: 2027 월 기준 유지. 원가·판매단가도 C01 유지
A22: purchase_lag | B22: 0 | C22: 구매·생산·납품 시차 | D22: 기발주·재고 없음. 구매 증가와 공헌이익 감소가 같은 단순화
A23: analysis_period_end | B23: =EDATE(B6,12) -> 46935 | C23: 향후12개월 종료 경계 | D23: 종료일 미포함. 2027-07-01~2028-06-30
A24: remaining_year_end | B24: =DATE(YEAR(B6)+1,1,1) -> 46753 | C24: 당해연도 종료 경계 | D24: 종료일 미포함
A25: expected_model_months | B25: 60 | C25: 12개월 필수 원가·물량 행수 | D25: 5모델 ×12개월. 중복키·누락값 별도 검사

Sheet 단가안비교
A1: 요청부터 승인까지 구매 증가액 비교
A3: 동일 F02·EXT28-v1 물량. H: 2027 잔여기간, I: 적용일부터12개월. 승인선은 최종 기안안으로 확정하며 다른 안의 값은 사전 미리보기입니다.
A5: price_version | B5: 종류 | C5: 기존가 | D5: 단가 | E5: 인상률 | F5: 잔여구매량 | G5: 12개월구매량 | H5: 잔여구매증가 | I5: 12개월구매증가 | J5: 비율위험 | K5: 금액위험 | L5: 종합위험 | M5: 승인선미리보기 | N5: 요청대비부담감소 | O5: 12개월CM영향
A6: PV-REQ01 | B6: 요청안 | C6: =단가버전!E6 -> 2000 | D6: =단가버전!F6 -> 2200 | E6: =IF(C6>0,(D6-C6)/C6,"미산출") -> 0.1 | F6: =IF(SUMPRODUCT(월별계산!$O$6:$O$100,월별계산!$U$6:$U$100)<>SUM(월별계산!$O$6:$O$100),"미산출",SUMPRODUCT(월별계산!$J$6:$J$100,월별계산!$O$6:$O$100)) -> 78036 | G6: =IF(SUMPRODUCT(월별계산!$N$6:$N$100,월별계산!$U$6:$U$100)<>SUM(월별계산!$N$6:$N$100),"미산출",SUMPRODUCT(월별계산!$J$6:$J$100,월별계산!$N$6:$N$100)) -> 156812 | H6: =IF(ISNUMBER(F6),F6*(D6-C6),"미산출") -> 15607200 | I6: =IF(AND(ISNUMBER(G6),SUM(월별계산!$N$6:$N$100)=설정!$B$25),G6*(D6-C6),"미산출") -> 31362400 | J6: =IF(NOT(ISNUMBER(E6)),"미산출",IF(E6>=설정!$B$9,"중요",IF(E6>=설정!$B$8,"관심","정상"))) -> 중요 | K6: =IF(NOT(ISNUMBER(I6)),"미산출",IF(I6>=설정!$B$11,"중요",IF(I6>=설정!$B$10,"관심","정상"))) -> 중요 | L6: =IF(OR(J6="미산출",K6="미산출"),"미산출",IF(OR(J6="중요",K6="중요"),"중요",IF(OR(J6="관심",K6="관심"),"관심","정상"))) -> 중요 | M6: =IF(NOT(ISNUMBER(I6)),"판정 보류",IF(I6>=설정!$B$12,"대표 대상","대표 비대상")) -> 대표 대상 | N6: =IF(AND(ISNUMBER($I$6),ISNUMBER(I6)),$I$6-I6,"미산출") -> 0 | O6: =IF(ISNUMBER(I6),-I6,"미산출") -> -31362400
A7: PV-OFFER01 | B7: 내부제시안 | C7: =단가버전!E7 -> 2000 | D7: =단가버전!F7 -> 2100 | E7: =IF(C7>0,(D7-C7)/C7,"미산출") -> 0.05 | F7: =IF(SUMPRODUCT(월별계산!$O$6:$O$100,월별계산!$U$6:$U$100)<>SUM(월별계산!$O$6:$O$100),"미산출",SUMPRODUCT(월별계산!$J$6:$J$100,월별계산!$O$6:$O$100)) -> 78036 | G7: =IF(SUMPRODUCT(월별계산!$N$6:$N$100,월별계산!$U$6:$U$100)<>SUM(월별계산!$N$6:$N$100),"미산출",SUMPRODUCT(월별계산!$J$6:$J$100,월별계산!$N$6:$N$100)) -> 156812 | H7: =IF(ISNUMBER(F7),F7*(D7-C7),"미산출") -> 7803600 | I7: =IF(AND(ISNUMBER(G7),SUM(월별계산!$N$6:$N$100)=설정!$B$25),G7*(D7-C7),"미산출") -> 15681200 | J7: =IF(NOT(ISNUMBER(E7)),"미산출",IF(E7>=설정!$B$9,"중요",IF(E7>=설정!$B$8,"관심","정상"))) -> 관심 | K7: =IF(NOT(ISNUMBER(I7)),"미산출",IF(I7>=설정!$B$11,"중요",IF(I7>=설정!$B$10,"관심","정상"))) -> 중요 | L7: =IF(OR(J7="미산출",K7="미산출"),"미산출",IF(OR(J7="중요",K7="중요"),"중요",IF(OR(J7="관심",K7="관심"),"관심","정상"))) -> 중요 | M7: =IF(NOT(ISNUMBER(I7)),"판정 보류",IF(I7>=설정!$B$12,"대표 대상","대표 비대상")) -> 대표 대상 | N7: =IF(AND(ISNUMBER($I$6),ISNUMBER(I7)),$I$6-I7,"미산출") -> 15681200 | O7: =IF(ISNUMBER(I7),-I7,"미산출") -> -15681200
A8: PV-NEG01 | B8: 1차협상안 | C8: =단가버전!E8 -> 2000 | D8: =단가버전!F8 -> 2120 | E8: =IF(C8>0,(D8-C8)/C8,"미산출") -> 0.06 | F8: =IF(SUMPRODUCT(월별계산!$O$6:$O$100,월별계산!$U$6:$U$100)<>SUM(월별계산!$O$6:$O$100),"미산출",SUMPRODUCT(월별계산!$J$6:$J$100,월별계산!$O$6:$O$100)) -> 78036 | G8: =IF(SUMPRODUCT(월별계산!$N$6:$N$100,월별계산!$U$6:$U$100)<>SUM(월별계산!$N$6:$N$100),"미산출",SUMPRODUCT(월별계산!$J$6:$J$100,월별계산!$N$6:$N$100)) -> 156812 | H8: =IF(ISNUMBER(F8),F8*(D8-C8),"미산출") -> 9364320 | I8: =IF(AND(ISNUMBER(G8),SUM(월별계산!$N$6:$N$100)=설정!$B$25),G8*(D8-C8),"미산출") -> 18817440 | J8: =IF(NOT(ISNUMBER(E8)),"미산출",IF(E8>=설정!$B$9,"중요",IF(E8>=설정!$B$8,"관심","정상"))) -> 관심 | K8: =IF(NOT(ISNUMBER(I8)),"미산출",IF(I8>=설정!$B$11,"중요",IF(I8>=설정!$B$10,"관심","정상"))) -> 중요 | L8: =IF(OR(J8="미산출",K8="미산출"),"미산출",IF(OR(J8="중요",K8="중요"),"중요",IF(OR(J8="관심",K8="관심"),"관심","정상"))) -> 중요 | M8: =IF(NOT(ISNUMBER(I8)),"판정 보류",IF(I8>=설정!$B$12,"대표 대상","대표 비대상")) -> 대표 대상 | N8: =IF(AND(ISNUMBER($I$6),ISNUMBER(I8)),$I$6-I8,"미산출") -> 12544960 | O8: =IF(ISNUMBER(I8),-I8,"미산출") -> -18817440
A9: PV-PROP01 | B9: 기안안 | C9: =단가버전!E9 -> 2000 | D9: =단가버전!F9 -> 2120 | E9: =IF(C9>0,(D9-C9)/C9,"미산출") -> 0.06 | F9: =IF(SUMPRODUCT(월별계산!$O$6:$O$100,월별계산!$U$6:$U$100)<>SUM(월별계산!$O$6:$O$100),"미산출",SUMPRODUCT(월별계산!$J$6:$J$100,월별계산!$O$6:$O$100)) -> 78036 | G9: =IF(SUMPRODUCT(월별계산!$N$6:$N$100,월별계산!$U$6:$U$100)<>SUM(월별계산!$N$6:$N$100),"미산출",SUMPRODUCT(월별계산!$J$6:$J$100,월별계산!$N$6:$N$100)) -> 156812 | H9: =IF(ISNUMBER(F9),F9*(D9-C9),"미산출") -> 9364320 | I9: =IF(AND(ISNUMBER(G9),SUM(월별계산!$N$6:$N$100)=설정!$B$25),G9*(D9-C9),"미산출") -> 18817440 | J9: =IF(NOT(ISNUMBER(E9)),"미산출",IF(E9>=설정!$B$9,"중요",IF(E9>=설정!$B$8,"관심","정상"))) -> 관심 | K9: =IF(NOT(ISNUMBER(I9)),"미산출",IF(I9>=설정!$B$11,"중요",IF(I9>=설정!$B$10,"관심","정상"))) -> 중요 | L9: =IF(OR(J9="미산출",K9="미산출"),"미산출",IF(OR(J9="중요",K9="중요"),"중요",IF(OR(J9="관심",K9="관심"),"관심","정상"))) -> 중요 | M9: =IF(NOT(ISNUMBER(I9)),"판정 보류",IF(I9>=설정!$B$12,"대표 대상","대표 비대상")) -> 대표 대상 | N9: =IF(AND(ISNUMBER($I$6),ISNUMBER(I9)),$I$6-I9,"미산출") -> 12544960 | O9: =IF(ISNUMBER(I9),-I9,"미산출") -> -18817440
A10: PV-APP01 | B10: 승인안 | C10: =단가버전!E10 -> 2000 | D10: =단가버전!F10 -> 2120 | E10: =IF(C10>0,(D10-C10)/C10,"미산출") -> 0.06 | F10: =IF(SUMPRODUCT(월별계산!$O$6:$O$100,월별계산!$U$6:$U$100)<>SUM(월별계산!$O$6:$O$100),"미산출",SUMPRODUCT(월별계산!$J$6:$J$100,월별계산!$O$6:$O$100)) -> 78036 | G10: =IF(SUMPRODUCT(월별계산!$N$6:$N$100,월별계산!$U$6:$U$100)<>SUM(월별계산!$N$6:$N$100),"미산출",SUMPRODUCT(월별계산!$J$6:$J$100,월별계산!$N$6:$N$100)) -> 156812 | H10: =IF(ISNUMBER(F10),F10*(D10-C10),"미산출") -> 9364320 | I10: =IF(AND(ISNUMBER(G10),SUM(월별계산!$N$6:$N$100)=설정!$B$25),G10*(D10-C10),"미산출") -> 18817440 | J10: =IF(NOT(ISNUMBER(E10)),"미산출",IF(E10>=설정!$B$9,"중요",IF(E10>=설정!$B$8,"관심","정상"))) -> 관심 | K10: =IF(NOT(ISNUMBER(I10)),"미산출",IF(I10>=설정!$B$11,"중요",IF(I10>=설정!$B$10,"관심","정상"))) -> 중요 | L10: =IF(OR(J10="미산출",K10="미산출"),"미산출",IF(OR(J10="중요",K10="중요"),"중요",IF(OR(J10="관심",K10="관심"),"관심","정상"))) -> 중요 | M10: =IF(NOT(ISNUMBER(I10)),"판정 보류",IF(I10>=설정!$B$12,"대표 대상","대표 비대상")) -> 대표 대상 | N10: =IF(AND(ISNUMBER($I$6),ISNUMBER(I10)),$I$6-I10,"미산출") -> 12544960 | O10: =IF(ISNUMBER(I10),-I10,"미산출") -> -18817440

Sheet 통합손익
A1: 장면 1·2 통합 관리손익
A3: 모든 금액 원. 관리손익=공헌이익−공장고정비. 본사비·금융비·세금 제외. 향후12개월 Target은 미설정이며 당해연도 Target을 혼용하지 않습니다.
A5: 기간 | B5: 시작일 | C5: 종료경계 | D5: 구분 | E5: F02매출 | F5: 공장고정비 | G5: F01기준손익 | H5: 물량반영손익 | I5: 장면1물량영향 | J5: 장면2원가영향 | K5: 통합손익 | L5: 전체변동 | M5: Target손익 | N5: Target부족 | O5: 브리지차이
A6: 2027-01 | B6: 46388 | C6: 46419 | D6: 월 | E6: =SUMIFS(월별계산!$S$6:$S$100,월별계산!$B$6:$B$100,">="&B6,월별계산!$B$6:$B$100,"<"&C6) -> 5989630000 | F6: =SUMIFS(월고정비!$B$6:$B$24,월고정비!$A$6:$A$24,">="&B6,월고정비!$A$6:$A$24,"<"&C6) -> 370000000 | G6: =SUMIFS(월별계산!$K$6:$K$100,월별계산!$B$6:$B$100,">="&B6,월별계산!$B$6:$B$100,"<"&C6)-F6 -> 309349000 | H6: =SUMIFS(월별계산!$L$6:$L$100,월별계산!$B$6:$B$100,">="&B6,월별계산!$B$6:$B$100,"<"&C6)-F6 -> 309349000 | I6: =H6-G6 -> 0 | J6: =-SUMIFS(월별계산!$P$6:$P$100,월별계산!$B$6:$B$100,">="&B6,월별계산!$B$6:$B$100,"<"&C6) -> 0 | K6: =H6+J6 -> 309349000 | L6: =K6-G6 -> 0 | M6: =SUMIFS(월별계산!$R$6:$R$100,월별계산!$B$6:$B$100,">="&B6,월별계산!$B$6:$B$100,"<"&C6)-F6 -> 310340000 | N6: =M6-K6 -> 991000 | O6: =K6-(G6+I6+J6) -> 0
A7: 2027-02 | B7: 46419 | C7: 46447 | D7: 월 | E7: =SUMIFS(월별계산!$S$6:$S$100,월별계산!$B$6:$B$100,">="&B7,월별계산!$B$6:$B$100,"<"&C7) -> 5257980000 | F7: =SUMIFS(월고정비!$B$6:$B$24,월고정비!$A$6:$A$24,">="&B7,월고정비!$A$6:$A$24,"<"&C7) -> 370000000 | G7: =SUMIFS(월별계산!$K$6:$K$100,월별계산!$B$6:$B$100,">="&B7,월별계산!$B$6:$B$100,"<"&C7)-F7 -> 226547000 | H7: =SUMIFS(월별계산!$L$6:$L$100,월별계산!$B$6:$B$100,">="&B7,월별계산!$B$6:$B$100,"<"&C7)-F7 -> 226547000 | I7: =H7-G7 -> 0 | J7: =-SUMIFS(월별계산!$P$6:$P$100,월별계산!$B$6:$B$100,">="&B7,월별계산!$B$6:$B$100,"<"&C7) -> 0 | K7: =H7+J7 -> 226547000 | L7: =K7-G7 -> 0 | M7: =SUMIFS(월별계산!$R$6:$R$100,월별계산!$B$6:$B$100,">="&B7,월별계산!$B$6:$B$100,"<"&C7)-F7 -> 230300000 | N7: =M7-K7 -> 3753000 | O7: =K7-(G7+I7+J7) -> 0
A8: 2027-03 | B8: 46447 | C8: 46478 | D8: 월 | E8: =SUMIFS(월별계산!$S$6:$S$100,월별계산!$B$6:$B$100,">="&B8,월별계산!$B$6:$B$100,"<"&C8) -> 6102990000 | F8: =SUMIFS(월고정비!$B$6:$B$24,월고정비!$A$6:$A$24,">="&B8,월고정비!$A$6:$A$24,"<"&C8) -> 370000000 | G8: =SUMIFS(월별계산!$K$6:$K$100,월별계산!$B$6:$B$100,">="&B8,월별계산!$B$6:$B$100,"<"&C8)-F8 -> 322633000 | H8: =SUMIFS(월별계산!$L$6:$L$100,월별계산!$B$6:$B$100,">="&B8,월별계산!$B$6:$B$100,"<"&C8)-F8 -> 322633000 | I8: =H8-G8 -> 0 | J8: =-SUMIFS(월별계산!$P$6:$P$100,월별계산!$B$6:$B$100,">="&B8,월별계산!$B$6:$B$100,"<"&C8) -> 0 | K8: =H8+J8 -> 322633000 | L8: =K8-G8 -> 0 | M8: =SUMIFS(월별계산!$R$6:$R$100,월별계산!$B$6:$B$100,">="&B8,월별계산!$B$6:$B$100,"<"&C8)-F8 -> 330350000 | N8: =M8-K8 -> 7717000 | O8: =K8-(G8+I8+J8) -> 0
A9: 2027-04 | B9: 46478 | C9: 46508 | D9: 월 | E9: =SUMIFS(월별계산!$S$6:$S$100,월별계산!$B$6:$B$100,">="&B9,월별계산!$B$6:$B$100,"<"&C9) -> 5782200000 | F9: =SUMIFS(월고정비!$B$6:$B$24,월고정비!$A$6:$A$24,">="&B9,월고정비!$A$6:$A$24,"<"&C9) -> 370000000 | G9: =SUMIFS(월별계산!$K$6:$K$100,월별계산!$B$6:$B$100,">="&B9,월별계산!$B$6:$B$100,"<"&C9)-F9 -> 286430000 | H9: =SUMIFS(월별계산!$L$6:$L$100,월별계산!$B$6:$B$100,">="&B9,월별계산!$B$6:$B$100,"<"&C9)-F9 -> 286430000 | I9: =H9-G9 -> 0 | J9: =-SUMIFS(월별계산!$P$6:$P$100,월별계산!$B$6:$B$100,">="&B9,월별계산!$B$6:$B$100,"<"&C9) -> 0 | K9: =H9+J9 -> 286430000 | L9: =K9-G9 -> 0 | M9: =SUMIFS(월별계산!$R$6:$R$100,월별계산!$B$6:$B$100,">="&B9,월별계산!$B$6:$B$100,"<"&C9)-F9 -> 297000000 | N9: =M9-K9 -> 10570000 | O9: =K9-(G9+I9+J9) -> 0
A10: 2027-05 | B10: 46508 | C10: 46539 | D10: 월 | E10: =SUMIFS(월별계산!$S$6:$S$100,월별계산!$B$6:$B$100,">="&B10,월별계산!$B$6:$B$100,"<"&C10) -> 5637110000 | F10: =SUMIFS(월고정비!$B$6:$B$24,월고정비!$A$6:$A$24,">="&B10,월고정비!$A$6:$A$24,"<"&C10) -> 370000000 | G10: =SUMIFS(월별계산!$K$6:$K$100,월별계산!$B$6:$B$100,">="&B10,월별계산!$B$6:$B$100,"<"&C10)-F10 -> 270161000 | H10: =SUMIFS(월별계산!$L$6:$L$100,월별계산!$B$6:$B$100,">="&B10,월별계산!$B$6:$B$100,"<"&C10)-F10 -> 270161000 | I10: =H10-G10 -> 0 | J10: =-SUMIFS(월별계산!$P$6:$P$100,월별계산!$B$6:$B$100,">="&B10,월별계산!$B$6:$B$100,"<"&C10) -> 0 | K10: =H10+J10 -> 270161000 | L10: =K10-G10 -> 0 | M10: =SUMIFS(월별계산!$R$6:$R$100,월별계산!$B$6:$B$100,">="&B10,월별계산!$B$6:$B$100,"<"&C10)-F10 -> 283660000 | N10: =M10-K10 -> 13499000 | O10: =K10-(G10+I10+J10) -> 0
A11: 2027-06 | B11: 46539 | C11: 46569 | D11: 월 | E11: =SUMIFS(월별계산!$S$6:$S$100,월별계산!$B$6:$B$100,">="&B11,월별계산!$B$6:$B$100,"<"&C11) -> 5722200000 | F11: =SUMIFS(월고정비!$B$6:$B$24,월고정비!$A$6:$A$24,">="&B11,월고정비!$A$6:$A$24,"<"&C11) -> 370000000 | G11: =SUMIFS(월별계산!$K$6:$K$100,월별계산!$B$6:$B$100,">="&B11,월별계산!$B$6:$B$100,"<"&C11)-F11 -> 280030000 | H11: =SUMIFS(월별계산!$L$6:$L$100,월별계산!$B$6:$B$100,">="&B11,월별계산!$B$6:$B$100,"<"&C11)-F11 -> 280030000 | I11: =H11-G11 -> 0 | J11: =-SUMIFS(월별계산!$P$6:$P$100,월별계산!$B$6:$B$100,">="&B11,월별계산!$B$6:$B$100,"<"&C11) -> 0 | K11: =H11+J11 -> 280030000 | L11: =K11-G11 -> 0 | M11: =SUMIFS(월별계산!$R$6:$R$100,월별계산!$B$6:$B$100,">="&B11,월별계산!$B$6:$B$100,"<"&C11)-F11 -> 297000000 | N11: =M11-K11 -> 16970000 | O11: =K11-(G11+I11+J11) -> 0
A12: 2027-07 | B12: 46569 | C12: 46600 | D12: 월 | E12: =SUMIFS(월별계산!$S$6:$S$100,월별계산!$B$6:$B$100,">="&B12,월별계산!$B$6:$B$100,"<"&C12) -> 5596200000 | F12: =SUMIFS(월고정비!$B$6:$B$24,월고정비!$A$6:$A$24,">="&B12,월고정비!$A$6:$A$24,"<"&C12) -> 370000000 | G12: =SUMIFS(월별계산!$K$6:$K$100,월별계산!$B$6:$B$100,">="&B12,월별계산!$B$6:$B$100,"<"&C12)-F12 -> 280030000 | H12: =SUMIFS(월별계산!$L$6:$L$100,월별계산!$B$6:$B$100,">="&B12,월별계산!$B$6:$B$100,"<"&C12)-F12 -> 266030000 | I12: =H12-G12 -> -14000000 | J12: =-SUMIFS(월별계산!$P$6:$P$100,월별계산!$B$6:$B$100,">="&B12,월별계산!$B$6:$B$100,"<"&C12) -> -1512000 | K12: =H12+J12 -> 264518000 | L12: =K12-G12 -> -15512000 | M12: =SUMIFS(월별계산!$R$6:$R$100,월별계산!$B$6:$B$100,">="&B12,월별계산!$B$6:$B$100,"<"&C12)-F12 -> 297000000 | N12: =M12-K12 -> 32482000 | O12: =K12-(G12+I12+J12) -> 0
A13: 2027-08 | B13: 46600 | C13: 46631 | D13: 월 | E13: =SUMIFS(월별계산!$S$6:$S$100,월별계산!$B$6:$B$100,">="&B13,월별계산!$B$6:$B$100,"<"&C13) -> 5264410000 | F13: =SUMIFS(월고정비!$B$6:$B$24,월고정비!$A$6:$A$24,">="&B13,월고정비!$A$6:$A$24,"<"&C13) -> 370000000 | G13: =SUMIFS(월별계산!$K$6:$K$100,월별계산!$B$6:$B$100,">="&B13,월별계산!$B$6:$B$100,"<"&C13)-F13 -> 228026000 | H13: =SUMIFS(월별계산!$L$6:$L$100,월별계산!$B$6:$B$100,">="&B13,월별계산!$B$6:$B$100,"<"&C13)-F13 -> 228026000 | I13: =H13-G13 -> 0 | J13: =-SUMIFS(월별계산!$P$6:$P$100,월별계산!$B$6:$B$100,">="&B13,월별계산!$B$6:$B$100,"<"&C13) -> -1468320 | K13: =H13+J13 -> 226557680 | L13: =K13-G13 -> -1468320 | M13: =SUMIFS(월별계산!$R$6:$R$100,월별계산!$B$6:$B$100,">="&B13,월별계산!$B$6:$B$100,"<"&C13)-F13 -> 243640000 | N13: =M13-K13 -> 17082320 | O13: =K13-(G13+I13+J13) -> 0
A14: 2027-09 | B14: 46631 | C14: 46661 | D14: 월 | E14: =SUMIFS(월별계산!$S$6:$S$100,월별계산!$B$6:$B$100,">="&B14,월별계산!$B$6:$B$100,"<"&C14) -> 5893910000 | F14: =SUMIFS(월고정비!$B$6:$B$24,월고정비!$A$6:$A$24,">="&B14,월고정비!$A$6:$A$24,"<"&C14) -> 370000000 | G14: =SUMIFS(월별계산!$K$6:$K$100,월별계산!$B$6:$B$100,">="&B14,월별계산!$B$6:$B$100,"<"&C14)-F14 -> 299536000 | H14: =SUMIFS(월별계산!$L$6:$L$100,월별계산!$B$6:$B$100,">="&B14,월별계산!$B$6:$B$100,"<"&C14)-F14 -> 299536000 | I14: =H14-G14 -> 0 | J14: =-SUMIFS(월별계산!$P$6:$P$100,월별계산!$B$6:$B$100,">="&B14,월별계산!$B$6:$B$100,"<"&C14) -> -1643880 | K14: =H14+J14 -> 297892120 | L14: =K14-G14 -> -1643880 | M14: =SUMIFS(월별계산!$R$6:$R$100,월별계산!$B$6:$B$100,">="&B14,월별계산!$B$6:$B$100,"<"&C14)-F14 -> 317010000 | N14: =M14-K14 -> 19117880 | O14: =K14-(G14+I14+J14) -> 0
A15: 2027-10 | B15: 46661 | C15: 46692 | D15: 월 | E15: =SUMIFS(월별계산!$S$6:$S$100,월별계산!$B$6:$B$100,">="&B15,월별계산!$B$6:$B$100,"<"&C15) -> 5836630000 | F15: =SUMIFS(월고정비!$B$6:$B$24,월고정비!$A$6:$A$24,">="&B15,월고정비!$A$6:$A$24,"<"&C15) -> 370000000 | G15: =SUMIFS(월별계산!$K$6:$K$100,월별계산!$B$6:$B$100,">="&B15,월별계산!$B$6:$B$100,"<"&C15)-F15 -> 293029000 | H15: =SUMIFS(월별계산!$L$6:$L$100,월별계산!$B$6:$B$100,">="&B15,월별계산!$B$6:$B$100,"<"&C15)-F15 -> 293029000 | I15: =H15-G15 -> 0 | J15: =-SUMIFS(월별계산!$P$6:$P$100,월별계산!$B$6:$B$100,">="&B15,월별계산!$B$6:$B$100,"<"&C15) -> -1627920 | K15: =H15+J15 -> 291401080 | L15: =K15-G15 -> -1627920 | M15: =SUMIFS(월별계산!$R$6:$R$100,월별계산!$B$6:$B$100,">="&B15,월별계산!$B$6:$B$100,"<"&C15)-F15 -> 310340000 | N15: =M15-K15 -> 18938920 | O15: =K15-(G15+I15+J15) -> 0
A16: 2027-11 | B16: 46692 | C16: 46722 | D16: 월 | E16: =SUMIFS(월별계산!$S$6:$S$100,월별계산!$B$6:$B$100,">="&B16,월별계산!$B$6:$B$100,"<"&C16) -> 5722200000 | F16: =SUMIFS(월고정비!$B$6:$B$24,월고정비!$A$6:$A$24,">="&B16,월고정비!$A$6:$A$24,"<"&C16) -> 370000000 | G16: =SUMIFS(월별계산!$K$6:$K$100,월별계산!$B$6:$B$100,">="&B16,월별계산!$B$6:$B$100,"<"&C16)-F16 -> 280030000 | H16: =SUMIFS(월별계산!$L$6:$L$100,월별계산!$B$6:$B$100,">="&B16,월별계산!$B$6:$B$100,"<"&C16)-F16 -> 280030000 | I16: =H16-G16 -> 0 | J16: =-SUMIFS(월별계산!$P$6:$P$100,월별계산!$B$6:$B$100,">="&B16,월별계산!$B$6:$B$100,"<"&C16) -> -1596000 | K16: =H16+J16 -> 278434000 | L16: =K16-G16 -> -1596000 | M16: =SUMIFS(월별계산!$R$6:$R$100,월별계산!$B$6:$B$100,">="&B16,월별계산!$B$6:$B$100,"<"&C16)-F16 -> 297000000 | N16: =M16-K16 -> 18566000 | O16: =K16-(G16+I16+J16) -> 0
A17: 2027-12 | B17: 46722 | C17: 46753 | D17: 월 | E17: =SUMIFS(월별계산!$S$6:$S$100,월별계산!$B$6:$B$100,">="&B17,월별계산!$B$6:$B$100,"<"&C17) -> 5436270000 | F17: =SUMIFS(월고정비!$B$6:$B$24,월고정비!$A$6:$A$24,">="&B17,월고정비!$A$6:$A$24,"<"&C17) -> 370000000 | G17: =SUMIFS(월별계산!$K$6:$K$100,월별계산!$B$6:$B$100,">="&B17,월별계산!$B$6:$B$100,"<"&C17)-F17 -> 247550000 | H17: =SUMIFS(월별계산!$L$6:$L$100,월별계산!$B$6:$B$100,">="&B17,월별계산!$B$6:$B$100,"<"&C17)-F17 -> 247550000 | I17: =H17-G17 -> 0 | J17: =-SUMIFS(월별계산!$P$6:$P$100,월별계산!$B$6:$B$100,">="&B17,월별계산!$B$6:$B$100,"<"&C17) -> -1516200 | K17: =H17+J17 -> 246033800 | L17: =K17-G17 -> -1516200 | M17: =SUMIFS(월별계산!$R$6:$R$100,월별계산!$B$6:$B$100,">="&B17,월별계산!$B$6:$B$100,"<"&C17)-F17 -> 263650000 | N17: =M17-K17 -> 17616200 | O17: =K17-(G17+I17+J17) -> 0
... A19: 2027 Q4 | B19: 46661 | C19: 46753 | D19: 분기 | E19: =SUMIFS(월별계산!$S$6:$S$100,월별계산!$B$6:$B$100,">="&B19,월별계산!$B$6:$B$100,"<"&C19) -> 16995100000 | F19: =SUMIFS(월고정비!$B$6:$B$24,월고정비!$A$6:$A$24,">="&B19,월고정비!$A$6:$A$24,"<"&C19) -> 1110000000 | G19: =SUMIFS(월별계산!$K$6:$K$100,월별계산!$B$6:$B$100,">="&B19,월별계산!$B$6:$B$100,"<"&C19)-F19 -> 820609000 | H19: =SUMIFS(월별계산!$L$6:$L$100,월별계산!$B$6:$B$100,">="&B19,월별계산!$B$6:$B$100,"<"&C19)-F19 -> 820609000 | I19: =H19-G19 -> 0 | J19: =-SUMIFS(월별계산!$P$6:$P$100,월별계산!$B$6:$B$100,">="&B19,월별계산!$B$6:$B$100,"<"&C19) -> -4740120 | K19: =H19+J19 -> 815868880 | L19: =K19-G19 -> -4740120 | M19: =SUMIFS(월별계산!$R$6:$R$100,월별계산!$B$6:$B$100,">="&B19,월별계산!$B$6:$B$100,"<"&C19)-F19 -> 870990000 | N19: =M19-K19 -> 55121120 | O19: =K19-(G19+I19+J19) -> 0
A20: 2027 잔여 | B20: =설정!B6 -> 46569 | C20: 46753 | D20: 잔여 | E20: =SUMIFS(월별계산!$S$6:$S$100,월별계산!$B$6:$B$100,">="&B20,월별계산!$B$6:$B$100,"<"&C20) -> 33749620000 | F20: =SUMIFS(월고정비!$B$6:$B$24,월고정비!$A$6:$A$24,">="&B20,월고정비!$A$6:$A$24,"<"&C20) -> 2220000000 | G20: =SUMIFS(월별계산!$K$6:$K$100,월별계산!$B$6:$B$100,">="&B20,월별계산!$B$6:$B$100,"<"&C20)-F20 -> 1628201000 | H20: =SUMIFS(월별계산!$L$6:$L$100,월별계산!$B$6:$B$100,">="&B20,월별계산!$B$6:$B$100,"<"&C20)-F20 -> 1614201000 | I20: =H20-G20 -> -14000000 | J20: =-SUMIFS(월별계산!$P$6:$P$100,월별계산!$B$6:$B$100,">="&B20,월별계산!$B$6:$B$100,"<"&C20) -> -9364320 | K20: =H20+J20 -> 1604836680 | L20: =K20-G20 -> -23364320 | M20: =SUMIFS(월별계산!$R$6:$R$100,월별계산!$B$6:$B$100,">="&B20,월별계산!$B$6:$B$100,"<"&C20)-F20 -> 1728640000 | N20: =M20-K20 -> 123803320 | O20: =K20-(G20+I20+J20) -> 0
A21: 2027 연간 | B21: 46388 | C21: 46753 | D21: 연간 | E21: =SUMIFS(월별계산!$S$6:$S$100,월별계산!$B$6:$B$100,">="&B21,월별계산!$B$6:$B$100,"<"&C21) -> 68241730000 | F21: =SUMIFS(월고정비!$B$6:$B$24,월고정비!$A$6:$A$24,">="&B21,월고정비!$A$6:$A$24,"<"&C21) -> 4440000000 | G21: =SUMIFS(월별계산!$K$6:$K$100,월별계산!$B$6:$B$100,">="&B21,월별계산!$B$6:$B$100,"<"&C21)-F21 -> 3323351000 | H21: =SUMIFS(월별계산!$L$6:$L$100,월별계산!$B$6:$B$100,">="&B21,월별계산!$B$6:$B$100,"<"&C21)-F21 -> 3309351000 | I21: =H21-G21 -> -14000000 | J21: =-SUMIFS(월별계산!$P$6:$P$100,월별계산!$B$6:$B$100,">="&B21,월별계산!$B$6:$B$100,"<"&C21) -> -9364320 | K21: =H21+J21 -> 3299986680 | L21: =K21-G21 -> -23364320 | M21: =SUMIFS(월별계산!$R$6:$R$100,월별계산!$B$6:$B$100,">="&B21,월별계산!$B$6:$B$100,"<"&C21)-F21 -> 3477290000 | N21: =M21-K21 -> 177303320 | O21: =K21-(G21+I21+J21) -> 0
A22: 향후12개월 | B22: =설정!B6 -> 46569 | C22: =설정!B23 -> 46935 | D22: 12개월 | E22: =SUMIFS(월별계산!$S$6:$S$100,월별계산!$B$6:$B$100,">="&B22,월별계산!$B$6:$B$100,"<"&C22) -> 67207730000 | F22: =SUMIFS(월고정비!$B$6:$B$24,월고정비!$A$6:$A$24,">="&B22,월고정비!$A$6:$A$24,"<"&C22) -> 4440000000 | G22: =SUMIFS(월별계산!$K$6:$K$100,월별계산!$B$6:$B$100,">="&B22,월별계산!$B$6:$B$100,"<"&C22)-F22 -> 3205981000 | H22: =SUMIFS(월별계산!$L$6:$L$100,월별계산!$B$6:$B$100,">="&B22,월별계산!$B$6:$B$100,"<"&C22)-F22 -> 3191981000 | I22: =H22-G22 -> -14000000 | J22: =-SUMIFS(월별계산!$P$6:$P$100,월별계산!$B$6:$B$100,">="&B22,월별계산!$B$6:$B$100,"<"&C22) -> -18817440 | K22: =H22+J22 -> 3173163560 | L22: =K22-G22 -> -32817440 | O22: =K22-(G22+I22+J22) -> 0
A25: 2027 Q3 모델 | B25: F01 공헌이익 | C25: 물량영향 | D25: 원가영향 | E25: 통합 공헌이익 | F25: 고정비 처리
A26: A-a | B26: =SUMIFS(월별계산!$K$6:$K$100,월별계산!$C$6:$C$100,A26,월별계산!$B$6:$B$100,">="&DATE(2027,7,1),월별계산!$B$6:$B$100,"<"&DATE(2027,10,1)) -> 336300000 | C26: =SUMIFS(월별계산!$M$6:$M$100,월별계산!$C$6:$C$100,A26,월별계산!$B$6:$B$100,">="&DATE(2027,7,1),월별계산!$B$6:$B$100,"<"&DATE(2027,10,1)) -> 0 | D26: =-SUMIFS(월별계산!$P$6:$P$100,월별계산!$C$6:$C$100,A26,월별계산!$B$6:$B$100,">="&DATE(2027,7,1),월별계산!$B$6:$B$100,"<"&DATE(2027,10,1)) -> -1345200 | E26: =SUMIFS(월별계산!$Q$6:$Q$100,월별계산!$C$6:$C$100,A26,월별계산!$B$6:$B$100,">="&DATE(2027,7,1),월별계산!$B$6:$B$100,"<"&DATE(2027,10,1)) -> 334954800 | F26: 공장 합계에서만 차감
A27: A-b | B27: =SUMIFS(월별계산!$K$6:$K$100,월별계산!$C$6:$C$100,A27,월별계산!$B$6:$B$100,">="&DATE(2027,7,1),월별계산!$B$6:$B$100,"<"&DATE(2027,10,1)) -> 560500000 | C27: =SUMIFS(월별계산!$M$6:$M$100,월별계산!$C$6:$C$100,A27,월별계산!$B$6:$B$100,">="&DATE(2027,7,1),월별계산!$B$6:$B$100,"<"&DATE(2027,10,1)) -> -14000000 | D27: =-SUMIFS(월별계산!$P$6:$P$100,월별계산!$C$6:$C$100,A27,월별계산!$B$6:$B$100,">="&DATE(2027,7,1),월별계산!$B$6:$B$100,"<"&DATE(2027,10,1)) -> -3279000 | E27: =SUMIFS(월별계산!$Q$6:$Q$100,월별계산!$C$6:$C$100,A27,월별계산!$B$6:$B$100,">="&DATE(2027,7,1),월별계산!$B$6:$B$100,"<"&DATE(2027,10,1)) -> 543221000 | F27: 공장 합계에서만 차감
A28: A-c | B28: =SUMIFS(월별계산!$K$6:$K$100,월별계산!$C$6:$C$100,A28,월별계산!$B$6:$B$100,">="&DATE(2027,7,1),월별계산!$B$6:$B$100,"<"&DATE(2027,10,1)) -> 490644000 | C28: =SUMIFS(월별계산!$M$6:$M$100,월별계산!$C$6:$C$100,A28,월별계산!$B$6:$B$100,">="&DATE(2027,7,1),월별계산!$B$6:$B$100,"<"&DATE(2027,10,1)) -> 0 | D28: =-SUMIFS(월별계산!$P$6:$P$100,월별계산!$C$6:$C$100,A28,월별계산!$B$6:$B$100,">="&DATE(2027,7,1),월별계산!$B$6:$B$100,"<"&DATE(2027,10,1)) -> 0 | E28: =SUMIFS(월별계산!$Q$6:$Q$100,월별계산!$C$6:$C$100,A28,월별계산!$B$6:$B$100,">="&DATE(2027,7,1),월별계산!$B$6:$B$100,"<"&DATE(2027,10,1)) -> 490644000 | F28: 공장 합계에서만 차감
A29: A-d | B29: =SUMIFS(월별계산!$K$6:$K$100,월별계산!$C$6:$C$100,A29,월별계산!$B$6:$B$100,">="&DATE(2027,7,1),월별계산!$B$6:$B$100,"<"&DATE(2027,10,1)) -> 372450000 | C29: =SUMIFS(월별계산!$M$6:$M$100,월별계산!$C$6:$C$100,A29,월별계산!$B$6:$B$100,">="&DATE(2027,7,1),월별계산!$B$6:$B$100,"<"&DATE(2027,10,1)) -> 0 | D29: =-SUMIFS(월별계산!$P$6:$P$100,월별계산!$C$6:$C$100,A29,월별계산!$B$6:$B$100,">="&DATE(2027,7,1),월별계산!$B$6:$B$100,"<"&DATE(2027,10,1)) -> 0 | E29: =SUMIFS(월별계산!$Q$6:$Q$100,월별계산!$C$6:$C$100,A29,월별계산!$B$6:$B$100,">="&DATE(2027,7,1),월별계산!$B$6:$B$100,"<"&DATE(2027,10,1)) -> 372450000 | F29: 공장 합계에서만 차감
A30: A-e | B30: =SUMIFS(월별계산!$K$6:$K$100,월별계산!$C$6:$C$100,A30,월별계산!$B$6:$B$100,">="&DATE(2027,7,1),월별계산!$B$6:$B$100,"<"&DATE(2027,10,1)) -> 157698000 | C30: =SUMIFS(월별계산!$M$6:$M$100,월별계산!$C$6:$C$100,A30,월별계산!$B$6:$B$100,">="&DATE(2027,7,1),월별계산!$B$6:$B$100,"<"&DATE(2027,10,1)) -> 0 | D30: =-SUMIFS(월별계산!$P$6:$P$100,월별계산!$C$6:$C$100,A30,월별계산!$B$6:$B$100,">="&DATE(2027,7,1),월별계산!$B$6:$B$100,"<"&DATE(2027,10,1)) -> 0 | E30: =SUMIFS(월별계산!$Q$6:$Q$100,월별계산!$C$6:$C$100,A30,월별계산!$B$6:$B$100,">="&DATE(2027,7,1),월별계산!$B$6:$B$100,"<"&DATE(2027,10,1)) -> 157698000 | F30: 공장 합계에서만 차감

Sheet 월별계산
A1: 월별·모델별 손익 및 구매수량
A3: 금액 원, 수량 개/대분. 가격 인상은 적용일 이후에만 반영합니다. 2028년 비교안은 모두 같은 내부가정·원가·고정비 범위를 사용합니다.
A5: row_key | B5: period | C5: model_id | D5: F01_qty | E5: F02_qty | F5: 판매단가 | G5: C01변동비 | H5: 기준단위CM | I5: 부품소요량 | J5: 부품구매량 | K5: F01_CM | L5: F02_CM | M5: 물량순영향 | N5: 12개월포함 | O5: 당해잔여포함 | P5: 승인안원가증가 | Q5: 통합_CM | R5: Target_CM | S5: F02매출 | T5: 승인안외주비 | U5: 원천유효
A6: =물량원가기준!A6 -> 2027-01|A-a | B6: =물량원가기준!B6 -> 46388 | C6: =물량원가기준!C6 -> A-a | D6: =물량원가기준!E6 -> 4080 | E6: =물량원가기준!F6 -> 4080 | F6: =물량원가기준!G6 -> 300000 | G6: =SUM(물량원가기준!H6:J6) -> 270000 | H6: =F6-G6 -> 30000 | I6: =부품모델매핑!D6 -> 1 | J6: =IF(ISNUMBER(물량원가기준!F6),E6*I6,"미산출") -> 4080 | K6: =D6*H6 -> 122400000 | L6: =E6*H6 -> 122400000 | M6: =L6-K6 -> 0 | N6: =IF(AND(B6>=설정!$B$6,B6<설정!$B$23),1,0) -> 0 | O6: =IF(AND(B6>=설정!$B$6,B6<설정!$B$24),1,0) -> 0 | P6: =IF(B6>=설정!$B$6,J6*(설정!$B$18-설정!$B$13),0) -> 0 | Q6: =L6-P6 -> 122400000 | R6: =IF(물량원가기준!D6="","",물량원가기준!D6*H6) -> 122400000 | S6: =E6*F6 -> 1224000000 | T6: =물량원가기준!I6+IF(B6>=설정!$B$6,I6*(설정!$B$18-설정!$B$13),0) -> 75000 | U6: =IF(OR(COUNT(물량원가기준!E6:J6)<>6,COUNTIFS(물량원가기준!$A$6:$A$100,A6)<>1),0,1) -> 1
A7: =물량원가기준!A7 -> 2027-01|A-b | B7: =물량원가기준!B7 -> 46388 | C7: =물량원가기준!C7 -> A-b | D7: =물량원가기준!E7 -> 10200 | E7: =물량원가기준!F7 -> 10200 | F7: =물량원가기준!G7 -> 180000 | G7: =SUM(물량원가기준!H7:J7) -> 160000 | H7: =F7-G7 -> 20000 | I7: =부품모델매핑!D7 -> 1 | J7: =IF(ISNUMBER(물량원가기준!F7),E7*I7,"미산출") -> 10200 | K7: =D7*H7 -> 204000000 | L7: =E7*H7 -> 204000000 | M7: =L7-K7 -> 0 | N7: =IF(AND(B7>=설정!$B$6,B7<설정!$B$23),1,0) -> 0 | O7: =IF(AND(B7>=설정!$B$6,B7<설정!$B$24),1,0) -> 0 | P7: =IF(B7>=설정!$B$6,J7*(설정!$B$18-설정!$B$13),0) -> 0 | Q7: =L7-P7 -> 204000000 | R7: =IF(물량원가기준!D7="","",물량원가기준!D7*H7) -> 204000000 | S7: =E7*F7 -> 1836000000 | T7: =물량원가기준!I7+IF(B7>=설정!$B$6,I7*(설정!$B$18-설정!$B$13),0) -> 95000 | U7: =IF(OR(COUNT(물량원가기준!E7:J7)<>6,COUNTIFS(물량원가기준!$A$6:$A$100,A7)<>1),0,1) -> 1
A8: =물량원가기준!A8 -> 2027-01|A-c | B8: =물량원가기준!B8 -> 46388 | C8: =물량원가기준!C8 -> A-c | D8: =물량원가기준!E8 -> 6059 | E8: =물량원가기준!F8 -> 6059 | F8: =물량원가기준!G8 -> 230000 | G8: =SUM(물량원가기준!H8:J8) -> 202000 | H8: =F8-G8 -> 28000 | I8: =부품모델매핑!D8 -> 0 | J8: =IF(ISNUMBER(물량원가기준!F8),E8*I8,"미산출") -> 0 | K8: =D8*H8 -> 169652000 | L8: =E8*H8 -> 169652000 | M8: =L8-K8 -> 0 | N8: =IF(AND(B8>=설정!$B$6,B8<설정!$B$23),1,0) -> 0 | O8: =IF(AND(B8>=설정!$B$6,B8<설정!$B$24),1,0) -> 0 | P8: =IF(B8>=설정!$B$6,J8*(설정!$B$18-설정!$B$13),0) -> 0 | Q8: =L8-P8 -> 169652000 | R8: =IF(물량원가기준!D8="","",물량원가기준!D8*H8) -> 171360000 | S8: =E8*F8 -> 1393570000 | T8: =물량원가기준!I8+IF(B8>=설정!$B$6,I8*(설정!$B$18-설정!$B$13),0) -> 60000 | U8: =IF(OR(COUNT(물량원가기준!E8:J8)<>6,COUNTIFS(물량원가기준!$A$6:$A$100,A8)<>1),0,1) -> 1
A9: =물량원가기준!A9 -> 2027-01|A-d | B9: =물량원가기준!B9 -> 46388 | C9: =물량원가기준!C9 -> A-d | D9: =물량원가기준!E9 -> 5151 | E9: =물량원가기준!F9 -> 5151 | F9: =물량원가기준!G9 -> 210000 | G9: =SUM(물량원가기준!H9:J9) -> 185000 | H9: =F9-G9 -> 25000 | I9: =부품모델매핑!D9 -> 0 | J9: =IF(ISNUMBER(물량원가기준!F9),E9*I9,"미산출") -> 0 | K9: =D9*H9 -> 128775000 | L9: =E9*H9 -> 128775000 | M9: =L9-K9 -> 0 | N9: =IF(AND(B9>=설정!$B$6,B9<설정!$B$23),1,0) -> 0 | O9: =IF(AND(B9>=설정!$B$6,B9<설정!$B$24),1,0) -> 0 | P9: =IF(B9>=설정!$B$6,J9*(설정!$B$18-설정!$B$13),0) -> 0 | Q9: =L9-P9 -> 128775000 | R9: =IF(물량원가기준!D9="","",물량원가기준!D9*H9) -> 127500000 | S9: =E9*F9 -> 1081710000 | T9: =물량원가기준!I9+IF(B9>=설정!$B$6,I9*(설정!$B$18-설정!$B$13),0) -> 65000 | U9: =IF(OR(COUNT(물량원가기준!E9:J9)<>6,COUNTIFS(물량원가기준!$A$6:$A$100,A9)<>1),0,1) -> 1
A10: =물량원가기준!A10 -> 2027-01|A-e | B10: =물량원가기준!B10 -> 46388 | C10: =물량원가기준!C10 -> A-e | D10: =물량원가기준!E10 -> 3029 | E10: =물량원가기준!F10 -> 3029 | F10: =물량원가기준!G10 -> 150000 | G10: =SUM(물량원가기준!H10:J10) -> 132000 | H10: =F10-G10 -> 18000 | I10: =부품모델매핑!D10 -> 0 | J10: =IF(ISNUMBER(물량원가기준!F10),E10*I10,"미산출") -> 0 | K10: =D10*H10 -> 54522000 | L10: =E10*H10 -> 54522000 | M10: =L10-K10 -> 0 | N10: =IF(AND(B10>=설정!$B$6,B10<설정!$B$23),1,0) -> 0 | O10: =IF(AND(B10>=설정!$B$6,B10<설정!$B$24),1,0) -> 0 | P10: =IF(B10>=설정!$B$6,J10*(설정!$B$18-설정!$B$13),0) -> 0 | Q10: =L10-P10 -> 54522000 | R10: =IF(물량원가기준!D10="","",물량원가기준!D10*H10) -> 55080000 | S10: =E10*F10 -> 454350000 | T10: =물량원가기준!I10+IF(B10>=설정!$B$6,I10*(설정!$B$18-설정!$B$13),0) -> 50000 | U10: =IF(OR(COUNT(물량원가기준!E10:J10)<>6,COUNTIFS(물량원가기준!$A$6:$A$100,A10)<>1),0,1) -> 1
A11: =물량원가기준!A11 -> 2027-02|A-a | B11: =물량원가기준!B11 -> 46419 | C11: =물량원가기준!C11 -> A-a | D11: =물량원가기준!E11 -> 3564 | E11: =물량원가기준!F11 -> 3564 | F11: =물량원가기준!G11 -> 300000 | G11: =SUM(물량원가기준!H11:J11) -> 270000 | H11: =F11-G11 -> 30000 | I11: =부품모델매핑!D6 -> 1 | J11: =IF(ISNUMBER(물량원가기준!F11),E11*I11,"미산출") -> 3564 | K11: =D11*H11 -> 106920000 | L11: =E11*H11 -> 106920000 | M11: =L11-K11 -> 0 | N11: =IF(AND(B11>=설정!$B$6,B11<설정!$B$23),1,0) -> 0 | O11: =IF(AND(B11>=설정!$B$6,B11<설정!$B$24),1,0) -> 0 | P11: =IF(B11>=설정!$B$6,J11*(설정!$B$18-설정!$B$13),0) -> 0 | Q11: =L11-P11 -> 106920000 | R11: =IF(물량원가기준!D11="","",물량원가기준!D11*H11) -> 108000000 | S11: =E11*F11 -> 1069200000 | T11: =물량원가기준!I11+IF(B11>=설정!$B$6,I11*(설정!$B$18-설정!$B$13),0) -> 75000 | U11: =IF(OR(COUNT(물량원가기준!E11:J11)<>6,COUNTIFS(물량원가기준!$A$6:$A$100,A11)<>1),0,1) -> 1
A12: =물량원가기준!A12 -> 2027-02|A-b | B12: =물량원가기준!B12 -> 46419 | C12: =물량원가기준!C12 -> A-b | D12: =물량원가기준!E12 -> 8910 | E12: =물량원가기준!F12 -> 8910 | F12: =물량원가기준!G12 -> 180000 | G12: =SUM(물량원가기준!H12:J12) -> 160000 | H12: =F12-G12 -> 20000 | I12: =부품모델매핑!D7 -> 1 | J12: =IF(ISNUMBER(물량원가기준!F12),E12*I12,"미산출") -> 8910 | K12: =D12*H12 -> 178200000 | L12: =E12*H12 -> 178200000 | M12: =L12-K12 -> 0 | N12: =IF(AND(B12>=설정!$B$6,B12<설정!$B$23),1,0) -> 0 | O12: =IF(AND(B12>=설정!$B$6,B12<설정!$B$24),1,0) -> 0 | P12: =IF(B12>=설정!$B$6,J12*(설정!$B$18-설정!$B$13),0) -> 0 | Q12: =L12-P12 -> 178200000 | R12: =IF(물량원가기준!D12="","",물량원가기준!D12*H12) -> 180000000 | S12: =E12*F12 -> 1603800000 | T12: =물량원가기준!I12+IF(B12>=설정!$B$6,I12*(설정!$B$18-설정!$B$13),0) -> 95000 | U12: =IF(OR(COUNT(물량원가기준!E12:J12)<>6,COUNTIFS(물량원가기준!$A$6:$A$100,A12)<>1),0,1) -> 1
A13: =물량원가기준!A13 -> 2027-02|A-c | B13: =물량원가기준!B13 -> 46419 | C13: =물량원가기준!C13 -> A-c | D13: =물량원가기준!E13 -> 5346 | E13: =물량원가기준!F13 -> 5346 | F13: =물량원가기준!G13 -> 230000 | G13: =SUM(물량원가기준!H13:J13) -> 202000 | H13: =F13-G13 -> 28000 | I13: =부품모델매핑!D8 -> 0 | J13: =IF(ISNUMBER(물량원가기준!F13),E13*I13,"미산출") -> 0 | K13: =D13*H13 -> 149688000 | L13: =E13*H13 -> 149688000 | M13: =L13-K13 -> 0 | N13: =IF(AND(B13>=설정!$B$6,B13<설정!$B$23),1,0) -> 0 | O13: =IF(AND(B13>=설정!$B$6,B13<설정!$B$24),1,0) -> 0 | P13: =IF(B13>=설정!$B$6,J13*(설정!$B$18-설정!$B$13),0) -> 0 | Q13: =L13-P13 -> 149688000 | R13: =IF(물량원가기준!D13="","",물량원가기준!D13*H13) -> 151200000 | S13: =E13*F13 -> 1229580000 | T13: =물량원가기준!I13+IF(B13>=설정!$B$6,I13*(설정!$B$18-설정!$B$13),0) -> 60000 | U13: =IF(OR(COUNT(물량원가기준!E13:J13)<>6,COUNTIFS(물량원가기준!$A$6:$A$100,A13)<>1),0,1) -> 1
A14: =물량원가기준!A14 -> 2027-02|A-d | B14: =물량원가기준!B14 -> 46419 | C14: =물량원가기준!C14 -> A-d | D14: =물량원가기준!E14 -> 4545 | E14: =물량원가기준!F14 -> 4545 | F14: =물량원가기준!G14 -> 210000 | G14: =SUM(물량원가기준!H14:J14) -> 185000 | H14: =F14-G14 -> 25000 | I14: =부품모델매핑!D9 -> 0 | J14: =IF(ISNUMBER(물량원가기준!F14),E14*I14,"미산출") -> 0 | K14: =D14*H14 -> 113625000 | L14: =E14*H14 -> 113625000 | M14: =L14-K14 -> 0 | N14: =IF(AND(B14>=설정!$B$6,B14<설정!$B$23),1,0) -> 0 | O14: =IF(AND(B14>=설정!$B$6,B14<설정!$B$24),1,0) -> 0 | P14: =IF(B14>=설정!$B$6,J14*(설정!$B$18-설정!$B$13),0) -> 0 | Q14: =L14-P14 -> 113625000 | R14: =IF(물량원가기준!D14="","",물량원가기준!D14*H14) -> 112500000 | S14: =E14*F14 -> 954450000 | T14: =물량원가기준!I14+IF(B14>=설정!$B$6,I14*(설정!$B$18-설정!$B$13),0) -> 65000 | U14: =IF(OR(COUNT(물량원가기준!E14:J14)<>6,COUNTIFS(물량원가기준!$A$6:$A$100,A14)<>1),0,1) -> 1
A15: =물량원가기준!A15 -> 2027-02|A-e | B15: =물량원가기준!B15 -> 46419 | C15: =물량원가기준!C15 -> A-e | D15: =물량원가기준!E15 -> 2673 | E15: =물량원가기준!F15 -> 2673 | F15: =물량원가기준!G15 -> 150000 | G15: =SUM(물량원가기준!H15:J15) -> 132000 | H15: =F15-G15 -> 18000 | I15: =부품모델매핑!D10 -> 0 | J15: =IF(ISNUMBER(물량원가기준!F15),E15*I15,"미산출") -> 0 | K15: =D15*H15 -> 48114000 | L15: =E15*H15 -> 48114000 | M15: =L15-K15 -> 0 | N15: =IF(AND(B15>=설정!$B$6,B15<설정!$B$23),1,0) -> 0 | O15: =IF(AND(B15>=설정!$B$6,B15<설정!$B$24),1,0) -> 0 | P15: =IF(B15>=설정!$B$6,J15*(설정!$B$18-설정!$B$13),0) -> 0 | Q15: =L15-P15 -> 48114000 | R15: =IF(물량원가기준!D15="","",물량원가기준!D15*H15) -> 48600000 | S15: =E15*F15 -> 400950000 | T15: =물량원가기준!I15+IF(B15>=설정!$B$6,I15*(설정!$B$18-설정!$B$13),0) -> 50000 | U15: =IF(OR(COUNT(물량원가기준!E15:J15)<>6,COUNTIFS(물량원가기준!$A$6:$A$100,A15)<>1),0,1) -> 1
A16: =물량원가기준!A16 -> 2027-03|A-a | B16: =물량원가기준!B16 -> 46447 | C16: =물량원가기준!C16 -> A-a | D16: =물량원가기준!E16 -> 4116 | E16: =물량원가기준!F16 -> 4116 | F16: =물량원가기준!G16 -> 300000 | G16: =SUM(물량원가기준!H16:J16) -> 270000 | H16: =F16-G16 -> 30000 | I16: =부품모델매핑!D6 -> 1 | J16: =IF(ISNUMBER(물량원가기준!F16),E16*I16,"미산출") -> 4116 | K16: =D16*H16 -> 123480000 | L16: =E16*H16 -> 123480000 | M16: =L16-K16 -> 0 | N16: =IF(AND(B16>=설정!$B$6,B16<설정!$B$23),1,0) -> 0 | O16: =IF(AND(B16>=설정!$B$6,B16<설정!$B$24),1,0) -> 0 | P16: =IF(B16>=설정!$B$6,J16*(설정!$B$18-설정!$B$13),0) -> 0 | Q16: =L16-P16 -> 123480000 | R16: =IF(물량원가기준!D16="","",물량원가기준!D16*H16) -> 126000000 | S16: =E16*F16 -> 1234800000 | T16: =물량원가기준!I16+IF(B16>=설정!$B$6,I16*(설정!$B$18-설정!$B$13),0) -> 75000 | U16: =IF(OR(COUNT(물량원가기준!E16:J16)<>6,COUNTIFS(물량원가기준!$A$6:$A$100,A16)<>1),0,1) -> 1
A17: =물량원가기준!A17 -> 2027-03|A-b | B17: =물량원가기준!B17 -> 46447 | C17: =물량원가기준!C17 -> A-b | D17: =물량원가기준!E17 -> 10290 | E17: =물량원가기준!F17 -> 10290 | F17: =물량원가기준!G17 -> 180000 | G17: =SUM(물량원가기준!H17:J17) -> 160000 | H17: =F17-G17 -> 20000 | I17: =부품모델매핑!D7 -> 1 | J17: =IF(ISNUMBER(물량원가기준!F17),E17*I17,"미산출") -> 10290 | K17: =D17*H17 -> 205800000 | L17: =E17*H17 -> 205800000 | M17: =L17-K17 -> 0 | N17: =IF(AND(B17>=설정!$B$6,B17<설정!$B$23),1,0) -> 0 | O17: =IF(AND(B17>=설정!$B$6,B17<설정!$B$24),1,0) -> 0 | P17: =IF(B17>=설정!$B$6,J17*(설정!$B$18-설정!$B$13),0) -> 0 | Q17: =L17-P17 -> 205800000 | R17: =IF(물량원가기준!D17="","",물량원가기준!D17*H17) -> 210000000 | S17: =E17*F17 -> 1852200000 | T17: =물량원가기준!I17+IF(B17>=설정!$B$6,I17*(설정!$B$18-설정!$B$13),0) -> 95000 | U17: =IF(OR(COUNT(물량원가기준!E17:J17)<>6,COUNTIFS(물량원가기준!$A$6:$A$100,A17)<>1),0,1) -> 1
A18: =물량원가기준!A18 -> 2027-03|A-c | B18: =물량원가기준!B18 -> 46447 | C18: =물량원가기준!C18 -> A-c | D18: =물량원가기준!E18 -> 6237 | E18: =물량원가기준!F18 -> 6237 | F18: =물량원가기준!G18 -> 230000 | G18: =SUM(물량원가기준!H18:J18) -> 202000 | H18: =F18-G18 -> 28000 | I18: =부품모델매핑!D8 -> 0 | J18: =IF(ISNUMBER(물량원가기준!F18),E18*I18,"미산출") -> 0 | K18: =D18*H18 -> 174636000 | L18: =E18*H18 -> 174636000 | M18: =L18-K18 -> 0 | N18: =IF(AND(B18>=설정!$B$6,B18<설정!$B$23),1,0) -> 0 | O18: =IF(AND(B18>=설정!$B$6,B18<설정!$B$24),1,0) -> 0 | P18: =IF(B18>=설정!$B$6,J18*(설정!$B$18-설정!$B$13),0) -> 0 | Q18: =L18-P18 -> 174636000 | R18: =IF(물량원가기준!D18="","",물량원가기준!D18*H18) -> 176400000 | S18: =E18*F18 -> 1434510000 | T18: =물량원가기준!I18+IF(B18>=설정!$B$6,I18*(설정!$B$18-설정!$B$13),0) -> 60000 | U18: =IF(OR(COUNT(물량원가기준!E18:J18)<>6,COUNTIFS(물량원가기준!$A$6:$A$100,A18)<>1),0,1) -> 1
A19: =물량원가기준!A19 -> 2027-03|A-d | B19: =물량원가기준!B19 -> 46447 | C19: =물량원가기준!C19 -> A-d | D19: =물량원가기준!E19 -> 5303 | E19: =물량원가기준!F19 -> 5303 | F19: =물량원가기준!G19 -> 210000 | G19: =SUM(물량원가기준!H19:J19) -> 185000 | H19: =F19-G19 -> 25000 | I19: =부품모델매핑!D9 -> 0 | J19: =IF(ISNUMBER(물량원가기준!F19),E19*I19,"미산출") -> 0 | K19: =D19*H19 -> 132575000 | L19: =E19*H19 -> 132575000 | M19: =L19-K19 -> 0 | N19: =IF(AND(B19>=설정!$B$6,B19<설정!$B$23),1,0) -> 0 | O19: =IF(AND(B19>=설정!$B$6,B19<설정!$B$24),1,0) -> 0 | P19: =IF(B19>=설정!$B$6,J19*(설정!$B$18-설정!$B$13),0) -> 0 | Q19: =L19-P19 -> 132575000 | R19: =IF(물량원가기준!D19="","",물량원가기준!D19*H19) -> 131250000 | S19: =E19*F19 -> 1113630000 | T19: =물량원가기준!I19+IF(B19>=설정!$B$6,I19*(설정!$B$18-설정!$B$13),0) -> 65000 | U19: =IF(OR(COUNT(물량원가기준!E19:J19)<>6,COUNTIFS(물량원가기준!$A$6:$A$100,A19)<>1),0,1) -> 1
A20: =물량원가기준!A20 -> 2027-03|A-e | B20: =물량원가기준!B20 -> 46447 | C20: =물량원가기준!C20 -> A-e | D20: =물량원가기준!E20 -> 3119 | E20: =물량원가기준!F20 -> 3119 | F20: =물량원가기준!G20 -> 150000 | G20: =SUM(물량원가기준!H20:J20) -> 132000 | H20: =F20-G20 -> 18000 | I20: =부품모델매핑!D10 -> 0 | J20: =IF(ISNUMBER(물량원가기준!F20),E20*I20,"미산출") -> 0 | K20: =D20*H20 -> 56142000 | L20: =E20*H20 -> 56142000 | M20: =L20-K20 -> 0 | N20: =IF(AND(B20>=설정!$B$6,B20<설정!$B$23),1,0) -> 0 | O20: =IF(AND(B20>=설정!$B$6,B20<설정!$B$24),1,0) -> 0 | P20: =IF(B20>=설정!$B$6,J20*(설정!$B$18-설정!$B$13),0) -> 0 | Q20: =L20-P20 -> 56142000 | R20: =IF(물량원가기준!D20="","",물량원가기준!D20*H20) -> 56700000 | S20: =E20*F20 -> 467850000 | T20: =물량원가기준!I20+IF(B20>=설정!$B$6,I20*(설정!$B$18-설정!$B$13),0) -> 50000 | U20: =IF(OR(COUNT(물량원가기준!E20:J20)<>6,COUNTIFS(물량원가기준!$A$6:$A$100,A20)<>1),0,1) -> 1
A21: =물량원가기준!A21 -> 2027-04|A-a | B21: =물량원가기준!B21 -> 46478 | C21: =물량원가기준!C21 -> A-a | D21: =물량원가기준!E21 -> 3880 | E21: =물량원가기준!F21 -> 3880 | F21: =물량원가기준!G21 -> 300000 | G21: =SUM(물량원가기준!H21:J21) -> 270000 | H21: =F21-G21 -> 30000 | I21: =부품모델매핑!D6 -> 1 | J21: =IF(ISNUMBER(물량원가기준!F21),E21*I21,"미산출") -> 3880 | K21: =D21*H21 -> 116400000 | L21: =E21*H21 -> 116400000 | M21: =L21-K21 -> 0 | N21: =IF(AND(B21>=설정!$B$6,B21<설정!$B$23),1,0) -> 0 | O21: =IF(AND(B21>=설정!$B$6,B21<설정!$B$24),1,0) -> 0 | P21: =IF(B21>=설정!$B$6,J21*(설정!$B$18-설정!$B$13),0) -> 0 | Q21: =L21-P21 -> 116400000 | R21: =IF(물량원가기준!D21="","",물량원가기준!D21*H21) -> 120000000 | S21: =E21*F21 -> 1164000000 | T21: =물량원가기준!I21+IF(B21>=설정!$B$6,I21*(설정!$B$18-설정!$B$13),0) -> 75000 | U21: =IF(OR(COUNT(물량원가기준!E21:J21)<>6,COUNTIFS(물량원가기준!$A$6:$A$100,A21)<>1),0,1) -> 1
A22: =물량원가기준!A22 -> 2027-04|A-b | B22: =물량원가기준!B22 -> 46478 | C22: =물량원가기준!C22 -> A-b | D22: =물량원가기준!E22 -> 9700 | E22: =물량원가기준!F22 -> 9700 | F22: =물량원가기준!G22 -> 180000 | G22: =SUM(물량원가기준!H22:J22) -> 160000 | H22: =F22-G22 -> 20000 | I22: =부품모델매핑!D7 -> 1 | J22: =IF(ISNUMBER(물량원가기준!F22),E22*I22,"미산출") -> 9700 | K22: =D22*H22 -> 194000000 | L22: =E22*H22 -> 194000000 | M22: =L22-K22 -> 0 | N22: =IF(AND(B22>=설정!$B$6,B22<설정!$B$23),1,0) -> 0 | O22: =IF(AND(B22>=설정!$B$6,B22<설정!$B$24),1,0) -> 0 | P22: =IF(B22>=설정!$B$6,J22*(설정!$B$18-설정!$B$13),0) -> 0 | Q22: =L22-P22 -> 194000000 | R22: =IF(물량원가기준!D22="","",물량원가기준!D22*H22) -> 200000000 | S22: =E22*F22 -> 1746000000 | T22: =물량원가기준!I22+IF(B22>=설정!$B$6,I22*(설정!$B$18-설정!$B$13),0) -> 95000 | U22: =IF(OR(COUNT(물량원가기준!E22:J22)<>6,COUNTIFS(물량원가기준!$A$6:$A$100,A22)<>1),0,1) -> 1
A23: =물량원가기준!A23 -> 2027-04|A-c | B23: =물량원가기준!B23 -> 46478 | C23: =물량원가기준!C23 -> A-c | D23: =물량원가기준!E23 -> 5940 | E23: =물량원가기준!F23 -> 5940 | F23: =물량원가기준!G23 -> 230000 | G23: =SUM(물량원가기준!H23:J23) -> 202000 | H23: =F23-G23 -> 28000 | I23: =부품모델매핑!D8 -> 0 | J23: =IF(ISNUMBER(물량원가기준!F23),E23*I23,"미산출") -> 0 | K23: =D23*H23 -> 166320000 | L23: =E23*H23 -> 166320000 | M23: =L23-K23 -> 0 | N23: =IF(AND(B23>=설정!$B$6,B23<설정!$B$23),1,0) -> 0 | O23: =IF(AND(B23>=설정!$B$6,B23<설정!$B$24),1,0) -> 0 | P23: =IF(B23>=설정!$B$6,J23*(설정!$B$18-설정!$B$13),0) -> 0 | Q23: =L23-P23 -> 166320000 | R23: =IF(물량원가기준!D23="","",물량원가기준!D23*H23) -> 168000000 | S23: =E23*F23 -> 1366200000 | T23: =물량원가기준!I23+IF(B23>=설정!$B$6,I23*(설정!$B$18-설정!$B$13),0) -> 60000 | U23: =IF(OR(COUNT(물량원가기준!E23:J23)<>6,COUNTIFS(물량원가기준!$A$6:$A$100,A23)<>1),0,1) -> 1
A24: =물량원가기준!A24 -> 2027-04|A-d | B24: =물량원가기준!B24 -> 46478 | C24: =물량원가기준!C24 -> A-d | D24: =물량원가기준!E24 -> 5050 | E24: =물량원가기준!F24 -> 5050 | F24: =물량원가기준!G24 -> 210000 | G24: =SUM(물량원가기준!H24:J24) -> 185000 | H24: =F24-G24 -> 25000 | I24: =부품모델매핑!D9 -> 0 | J24: =IF(ISNUMBER(물량원가기준!F24),E24*I24,"미산출") -> 0 | K24: =D24*H24 -> 126250000 | L24: =E24*H24 -> 126250000 | M24: =L24-K24 -> 0 | N24: =IF(AND(B24>=설정!$B$6,B24<설정!$B$23),1,0) -> 0 | O24: =IF(AND(B24>=설정!$B$6,B24<설정!$B$24),1,0) -> 0 | P24: =IF(B24>=설정!$B$6,J24*(설정!$B$18-설정!$B$13),0) -> 0 | Q24: =L24-P24 -> 126250000 | R24: =IF(물량원가기준!D24="","",물량원가기준!D24*H24) -> 125000000 | S24: =E24*F24 -> 1060500000 | T24: =물량원가기준!I24+IF(B24>=설정!$B$6,I24*(설정!$B$18-설정!$B$13),0) -> 65000 | U24: =IF(OR(COUNT(물량원가기준!E24:J24)<>6,COUNTIFS(물량원가기준!$A$6:$A$100,A24)<>1),0,1) -> 1
A25: =물량원가기준!A25 -> 2027-04|A-e | B25: =물량원가기준!B25 -> 46478 | C25: =물량원가기준!C25 -> A-e | D25: =물량원가기준!E25 -> 2970 | E25: =물량원가기준!F25 -> 2970 | F25: =물량원가기준!G25 -> 150000 | G25: =SUM(물량원가기준!H25:J25) -> 132000 | H25: =F25-G25 -> 18000 | I25: =부품모델매핑!D10 -> 0 | J25: =IF(ISNUMBER(물량원가기준!F25),E25*I25,"미산출") -> 0 | K25: =D25*H25 -> 53460000 | L25: =E25*H25 -> 53460000 | M25: =L25-K25 -> 0 | N25: =IF(AND(B25>=설정!$B$6,B25<설정!$B$23),1,0) -> 0 | O25: =IF(AND(B25>=설정!$B$6,B25<설정!$B$24),1,0) -> 0 | P25: =IF(B25>=설정!$B$6,J25*(설정!$B$18-설정!$B$13),0) -> 0 | Q25: =L25-P25 -> 53460000 | R25: =IF(물량원가기준!D25="","",물량원가기준!D25*H25) -> 54000000 | S25: =E25*F25 -> 445500000 | T25: =물량원가기준!I25+IF(B25>=설정!$B$6,I25*(설정!$B$18-설정!$B$13),0) -> 50000 | U25: =IF(OR(COUNT(물량원가기준!E25:J25)<>6,COUNTIFS(물량원가기준!$A$6:$A$100,A25)<>1),0,1) -> 1
A26: =물량원가기준!A26 -> 2027-05|A-a | B26: =물량원가기준!B26 -> 46508 | C26: =물량원가기준!C26 -> A-a | D26: =물량원가기준!E26 -> 3763 | E26: =물량원가기준!F26 -> 3763 | F26: =물량원가기준!G26 -> 300000 | G26: =SUM(물량원가기준!H26:J26) -> 270000 | H26: =F26-G26 -> 30000 | I26: =부품모델매핑!D6 -> 1 | J26: =IF(ISNUMBER(물량원가기준!F26),E26*I26,"미산출") -> 3763 | K26: =D26*H26 -> 112890000 | L26: =E26*H26 -> 112890000 | M26: =L26-K26 -> 0 | N26: =IF(AND(B26>=설정!$B$6,B26<설정!$B$23),1,0) -> 0 | O26: =IF(AND(B26>=설정!$B$6,B26<설정!$B$24),1,0) -> 0 | P26: =IF(B26>=설정!$B$6,J26*(설정!$B$18-설정!$B$13),0) -> 0 | Q26: =L26-P26 -> 112890000 | R26: =IF(물량원가기준!D26="","",물량원가기준!D26*H26) -> 117600000 | S26: =E26*F26 -> 1128900000 | T26: =물량원가기준!I26+IF(B26>=설정!$B$6,I26*(설정!$B$18-설정!$B$13),0) -> 75000 | U26: =IF(OR(COUNT(물량원가기준!E26:J26)<>6,COUNTIFS(물량원가기준!$A$6:$A$100,A26)<>1),0,1) -> 1
A27: =물량원가기준!A27 -> 2027-05|A-b | B27: =물량원가기준!B27 -> 46508 | C27: =물량원가기준!C27 -> A-b | D27: =물량원가기준!E27 -> 9408 | E27: =물량원가기준!F27 -> 9408 | F27: =물량원가기준!G27 -> 180000 | G27: =SUM(물량원가기준!H27:J27) -> 160000 | H27: =F27-G27 -> 20000 | I27: =부품모델매핑!D7 -> 1 | J27: =IF(ISNUMBER(물량원가기준!F27),E27*I27,"미산출") -> 9408 | K27: =D27*H27 -> 188160000 | L27: =E27*H27 -> 188160000 | M27: =L27-K27 -> 0 | N27: =IF(AND(B27>=설정!$B$6,B27<설정!$B$23),1,0) -> 0 | O27: =IF(AND(B27>=설정!$B$6,B27<설정!$B$24),1,0) -> 0 | P27: =IF(B27>=설정!$B$6,J27*(설정!$B$18-설정!$B$13),0) -> 0 | Q27: =L27-P27 -> 188160000 | R27: =IF(물량원가기준!D27="","",물량원가기준!D27*H27) -> 196000000 | S27: =E27*F27 -> 1693440000 | T27: =물량원가기준!I27+IF(B27>=설정!$B$6,I27*(설정!$B$18-설정!$B$13),0) -> 95000 | U27: =IF(OR(COUNT(물량원가기준!E27:J27)<>6,COUNTIFS(물량원가기준!$A$6:$A$100,A27)<>1),0,1) -> 1
A28: =물량원가기준!A28 -> 2027-05|A-c | B28: =물량원가기준!B28 -> 46508 | C28: =물량원가기준!C28 -> A-c | D28: =물량원가기준!E28 -> 5821 | E28: =물량원가기준!F28 -> 5821 | F28: =물량원가기준!G28 -> 230000 | G28: =SUM(물량원가기준!H28:J28) -> 202000 | H28: =F28-G28 -> 28000 | I28: =부품모델매핑!D8 -> 0 | J28: =IF(ISNUMBER(물량원가기준!F28),E28*I28,"미산출") -> 0 | K28: =D28*H28 -> 162988000 | L28: =E28*H28 -> 162988000 | M28: =L28-K28 -> 0 | N28: =IF(AND(B28>=설정!$B$6,B28<설정!$B$23),1,0) -> 0 | O28: =IF(AND(B28>=설정!$B$6,B28<설정!$B$24),1,0) -> 0 | P28: =IF(B28>=설정!$B$6,J28*(설정!$B$18-설정!$B$13),0) -> 0 | Q28: =L28-P28 -> 162988000 | R28: =IF(물량원가기준!D28="","",물량원가기준!D28*H28) -> 164640000 | S28: =E28*F28 -> 1338830000 | T28: =물량원가기준!I28+IF(B28>=설정!$B$6,I28*(설정!$B$18-설정!$B$13),0) -> 60000 | U28: =IF(OR(COUNT(물량원가기준!E28:J28)<>6,COUNTIFS(물량원가기준!$A$6:$A$100,A28)<>1),0,1) -> 1
A29: =물량원가기준!A29 -> 2027-05|A-d | B29: =물량원가기준!B29 -> 46508 | C29: =물량원가기준!C29 -> A-d | D29: =물량원가기준!E29 -> 4949 | E29: =물량원가기준!F29 -> 4949 | F29: =물량원가기준!G29 -> 210000 | G29: =SUM(물량원가기준!H29:J29) -> 185000 | H29: =F29-G29 -> 25000 | I29: =부품모델매핑!D9 -> 0 | J29: =IF(ISNUMBER(물량원가기준!F29),E29*I29,"미산출") -> 0 | K29: =D29*H29 -> 123725000 | L29: =E29*H29 -> 123725000 | M29: =L29-K29 -> 0 | N29: =IF(AND(B29>=설정!$B$6,B29<설정!$B$23),1,0) -> 0 | O29: =IF(AND(B29>=설정!$B$6,B29<설정!$B$24),1,0) -> 0 | P29: =IF(B29>=설정!$B$6,J29*(설정!$B$18-설정!$B$13),0) -> 0 | Q29: =L29-P29 -> 123725000 | R29: =IF(물량원가기준!D29="","",물량원가기준!D29*H29) -> 122500000 | S29: =E29*F29 -> 1039290000 | T29: =물량원가기준!I29+IF(B29>=설정!$B$6,I29*(설정!$B$18-설정!$B$13),0) -> 65000 | U29: =IF(OR(COUNT(물량원가기준!E29:J29)<>6,COUNTIFS(물량원가기준!$A$6:$A$100,A29)<>1),0,1) -> 1
A30: =물량원가기준!A30 -> 2027-05|A-e | B30: =물량원가기준!B30 -> 46508 | C30: =물량원가기준!C30 -> A-e | D30: =물량원가기준!E30 -> 2911 | E30: =물량원가기준!F30 -> 2911 | F30: =물량원가기준!G30 -> 150000 | G30: =SUM(물량원가기준!H30:J30) -> 132000 | H30: =F30-G30 -> 18000 | I30: =부품모델매핑!D10 -> 0 | J30: =IF(ISNUMBER(물량원가기준!F30),E30*I30,"미산출") -> 0 | K30: =D30*H30 -> 52398000 | L30: =E30*H30 -> 52398000 | M30: =L30-K30 -> 0 | N30: =IF(AND(B30>=설정!$B$6,B30<설정!$B$23),1,0) -> 0 | O30: =IF(AND(B30>=설정!$B$6,B30<설정!$B$24),1,0) -> 0 | P30: =IF(B30>=설정!$B$6,J30*(설정!$B$18-설정!$B$13),0) -> 0 | Q30: =L30-P30 -> 52398000 | R30: =IF(물량원가기준!D30="","",물량원가기준!D30*H30) -> 52920000 | S30: =E30*F30 -> 436650000 | T30: =물량원가기준!I30+IF(B30>=설정!$B$6,I30*(설정!$B$18-설정!$B$13),0) -> 50000 | U30: =IF(OR(COUNT(물량원가기준!E30:J30)<>6,COUNTIFS(물량원가기준!$A$6:$A$100,A30)<>1),0,1) -> 1
A31: =물량원가기준!A31 -> 2027-06|A-a | B31: =물량원가기준!B31 -> 46539 | C31: =물량원가기준!C31 -> A-a | D31: =물량원가기준!E31 -> 3800 | E31: =물량원가기준!F31 -> 3800 | F31: =물량원가기준!G31 -> 300000 | G31: =SUM(물량원가기준!H31:J31) -> 270000 | H31: =F31-G31 -> 30000 | I31: =부품모델매핑!D6 -> 1 | J31: =IF(ISNUMBER(물량원가기준!F31),E31*I31,"미산출") -> 3800 | K31: =D31*H31 -> 114000000 | L31: =E31*H31 -> 114000000 | M31: =L31-K31 -> 0 | N31: =IF(AND(B31>=설정!$B$6,B31<설정!$B$23),1,0) -> 0 | O31: =IF(AND(B31>=설정!$B$6,B31<설정!$B$24),1,0) -> 0 | P31: =IF(B31>=설정!$B$6,J31*(설정!$B$18-설정!$B$13),0) -> 0 | Q31: =L31-P31 -> 114000000 | R31: =IF(물량원가기준!D31="","",물량원가기준!D31*H31) -> 120000000 | S31: =E31*F31 -> 1140000000 | T31: =물량원가기준!I31+IF(B31>=설정!$B$6,I31*(설정!$B$18-설정!$B$13),0) -> 75000 | U31: =IF(OR(COUNT(물량원가기준!E31:J31)<>6,COUNTIFS(물량원가기준!$A$6:$A$100,A31)<>1),0,1) -> 1
A32: =물량원가기준!A32 -> 2027-06|A-b | B32: =물량원가기준!B32 -> 46539 | C32: =물량원가기준!C32 -> A-b | D32: =물량원가기준!E32 -> 9500 | E32: =물량원가기준!F32 -> 9500 | F32: =물량원가기준!G32 -> 180000 | G32: =SUM(물량원가기준!H32:J32) -> 160000 | H32: =F32-G32 -> 20000 | I32: =부품모델매핑!D7 -> 1 | J32: =IF(ISNUMBER(물량원가기준!F32),E32*I32,"미산출") -> 9500 | K32: =D32*H32 -> 190000000 | L32: =E32*H32 -> 190000000 | M32: =L32-K32 -> 0 | N32: =IF(AND(B32>=설정!$B$6,B32<설정!$B$23),1,0) -> 0 | O32: =IF(AND(B32>=설정!$B$6,B32<설정!$B$24),1,0) -> 0 | P32: =IF(B32>=설정!$B$6,J32*(설정!$B$18-설정!$B$13),0) -> 0 | Q32: =L32-P32 -> 190000000 | R32: =IF(물량원가기준!D32="","",물량원가기준!D32*H32) -> 200000000 | S32: =E32*F32 -> 1710000000 | T32: =물량원가기준!I32+IF(B32>=설정!$B$6,I32*(설정!$B$18-설정!$B$13),0) -> 95000 | U32: =IF(OR(COUNT(물량원가기준!E32:J32)<>6,COUNTIFS(물량원가기준!$A$6:$A$100,A32)<>1),0,1) -> 1
A33: =물량원가기준!A33 -> 2027-06|A-c | B33: =물량원가기준!B33 -> 46539 | C33: =물량원가기준!C33 -> A-c | D33: =물량원가기준!E33 -> 5940 | E33: =물량원가기준!F33 -> 5940 | F33: =물량원가기준!G33 -> 230000 | G33: =SUM(물량원가기준!H33:J33) -> 202000 | H33: =F33-G33 -> 28000 | I33: =부품모델매핑!D8 -> 0 | J33: =IF(ISNUMBER(물량원가기준!F33),E33*I33,"미산출") -> 0 | K33: =D33*H33 -> 166320000 | L33: =E33*H33 -> 166320000 | M33: =L33-K33 -> 0 | N33: =IF(AND(B33>=설정!$B$6,B33<설정!$B$23),1,0) -> 0 | O33: =IF(AND(B33>=설정!$B$6,B33<설정!$B$24),1,0) -> 0 | P33: =IF(B33>=설정!$B$6,J33*(설정!$B$18-설정!$B$13),0) -> 0 | Q33: =L33-P33 -> 166320000 | R33: =IF(물량원가기준!D33="","",물량원가기준!D33*H33) -> 168000000 | S33: =E33*F33 -> 1366200000 | T33: =물량원가기준!I33+IF(B33>=설정!$B$6,I33*(설정!$B$18-설정!$B$13),0) -> 60000 | U33: =IF(OR(COUNT(물량원가기준!E33:J33)<>6,COUNTIFS(물량원가기준!$A$6:$A$100,A33)<>1),0,1) -> 1
A34: =물량원가기준!A34 -> 2027-06|A-d | B34: =물량원가기준!B34 -> 46539 | C34: =물량원가기준!C34 -> A-d | D34: =물량원가기준!E34 -> 5050 | E34: =물량원가기준!F34 -> 5050 | F34: =물량원가기준!G34 -> 210000 | G34: =SUM(물량원가기준!H34:J34) -> 185000 | H34: =F34-G34 -> 25000 | I34: =부품모델매핑!D9 -> 0 | J34: =IF(ISNUMBER(물량원가기준!F34),E34*I34,"미산출") -> 0 | K34: =D34*H34 -> 126250000 | L34: =E34*H34 -> 126250000 | M34: =L34-K34 -> 0 | N34: =IF(AND(B34>=설정!$B$6,B34<설정!$B$23),1,0) -> 0 | O34: =IF(AND(B34>=설정!$B$6,B34<설정!$B$24),1,0) -> 0 | P34: =IF(B34>=설정!$B$6,J34*(설정!$B$18-설정!$B$13),0) -> 0 | Q34: =L34-P34 -> 126250000 | R34: =IF(물량원가기준!D34="","",물량원가기준!D34*H34) -> 125000000 | S34: =E34*F34 -> 1060500000 | T34: =물량원가기준!I34+IF(B34>=설정!$B$6,I34*(설정!$B$18-설정!$B$13),0) -> 65000 | U34: =IF(OR(COUNT(물량원가기준!E34:J34)<>6,COUNTIFS(물량원가기준!$A$6:$A$100,A34)<>1),0,1) -> 1
A35: =물량원가기준!A35 -> 2027-06|A-e | B35: =물량원가기준!B35 -> 46539 | C35: =물량원가기준!C35 -> A-e | D35: =물량원가기준!E35 -> 2970 | E35: =물량원가기준!F35 -> 2970 | F35: =물량원가기준!G35 -> 150000 | G35: =SUM(물량원가기준!H35:J35) -> 132000 | H35: =F35-G35 -> 18000 | I35: =부품모델매핑!D10 -> 0 | J35: =IF(ISNUMBER(물량원가기준!F35),E35*I35,"미산출") -> 0 | K35: =D35*H35 -> 53460000 | L35: =E35*H35 -> 53460000 | M35: =L35-K35 -> 0 | N35: =IF(AND(B35>=설정!$B$6,B35<설정!$B$23),1,0) -> 0 | O35: =IF(AND(B35>=설정!$B$6,B35<설정!$B$24),1,0) -> 0 | P35: =IF(B35>=설정!$B$6,J35*(설정!$B$18-설정!$B$13),0) -> 0 | Q35: =L35-P35 -> 53460000 | R35: =IF(물량원가기준!D35="","",물량원가기준!D35*H35) -> 54000000 | S35: =E35*F35 -> 445500000 | T35: =물량원가기준!I35+IF(B35>=설정!$B$6,I35*(설정!$B$18-설정!$B$13),0) -> 50000 | U35: =IF(OR(COUNT(물량원가기준!E35:J35)<>6,COUNTIFS(물량원가기준!$A$6:$A$100,A35)<>1),0,1) -> 1
A36: =물량원가기준!A36 -> 2027-07|A-a | B36: =물량원가기준!B36 -> 46569 | C36: =물량원가기준!C36 -> A-a | D36: =물량원가기준!E36 -> 3800 | E36: =물량원가기준!F36 -> 3800 | F36: =물량원가기준!G36 -> 300000 | G36: =SUM(물량원가기준!H36:J36) -> 270000 | H36: =F36-G36 -> 30000 | I36: =부품모델매핑!D6 -> 1 | J36: =IF(ISNUMBER(물량원가기준!F36),E36*I36,"미산출") -> 3800 | K36: =D36*H36 -> 114000000 | L36: =E36*H36 -> 114000000 | M36: =L36-K36 -> 0 | N36: =IF(AND(B36>=설정!$B$6,B36<설정!$B$23),1,0) -> 1 | O36: =IF(AND(B36>=설정!$B$6,B36<설정!$B$24),1,0) -> 1 | P36: =IF(B36>=설정!$B$6,J36*(설정!$B$18-설정!$B$13),0) -> 456000 | Q36: =L36-P36 -> 113544000 | R36: =IF(물량원가기준!D36="","",물량원가기준!D36*H36) -> 120000000 | S36: =E36*F36 -> 1140000000 | T36: =물량원가기준!I36+IF(B36>=설정!$B$6,I36*(설정!$B$18-설정!$B$13),0) -> 75120 | U36: =IF(OR(COUNT(물량원가기준!E36:J36)<>6,COUNTIFS(물량원가기준!$A$6:$A$100,A36)<>1),0,1) -> 1
A37: =물량원가기준!A37 -> 2027-07|A-b | B37: =물량원가기준!B37 -> 46569 | C37: =물량원가기준!C37 -> A-b | D37: =물량원가기준!E37 -> 9500 | E37: =물량원가기준!F37 -> 8800 | F37: =물량원가기준!G37 -> 180000 | G37: =SUM(물량원가기준!H37:J37) -> 160000 | H37: =F37-G37 -> 20000 | I37: =부품모델매핑!D7 -> 1 | J37: =IF(ISNUMBER(물량원가기준!F37),E37*I37,"미산출") -> 8800 | K37: =D37*H37 -> 190000000 | L37: =E37*H37 -> 176000000 | M37: =L37-K37 -> -14000000 | N37: =IF(AND(B37>=설정!$B$6,B37<설정!$B$23),1,0) -> 1 | O37: =IF(AND(B37>=설정!$B$6,B37<설정!$B$24),1,0) -> 1 | P37: =IF(B37>=설정!$B$6,J37*(설정!$B$18-설정!$B$13),0) -> 1056000 | Q37: =L37-P37 -> 174944000 | R37: =IF(물량원가기준!D37="","",물량원가기준!D37*H37) -> 200000000 | S37: =E37*F37 -> 1584000000 | T37: =물량원가기준!I37+IF(B37>=설정!$B$6,I37*(설정!$B$18-설정!$B$13),0) -> 95120 | U37: =IF(OR(COUNT(물량원가기준!E37:J37)<>6,COUNTIFS(물량원가기준!$A$6:$A$100,A37)<>1),0,1) -> 1
A38: =물량원가기준!A38 -> 2027-07|A-c | B38: =물량원가기준!B38 -> 46569 | C38: =물량원가기준!C38 -> A-c | D38: =물량원가기준!E38 -> 5940 | E38: =물량원가기준!F38 -> 5940 | F38: =물량원가기준!G38 -> 230000 | G38: =SUM(물량원가기준!H38:J38) -> 202000 | H38: =F38-G38 -> 28000 | I38: =부품모델매핑!D8 -> 0 | J38: =IF(ISNUMBER(물량원가기준!F38),E38*I38,"미산출") -> 0 | K38: =D38*H38 -> 166320000 | L38: =E38*H38 -> 166320000 | M38: =L38-K38 -> 0 | N38: =IF(AND(B38>=설정!$B$6,B38<설정!$B$23),1,0) -> 1 | O38: =IF(AND(B38>=설정!$B$6,B38<설정!$B$24),1,0) -> 1 | P38: =IF(B38>=설정!$B$6,J38*(설정!$B$18-설정!$B$13),0) -> 0 | Q38: =L38-P38 -> 166320000 | R38: =IF(물량원가기준!D38="","",물량원가기준!D38*H38) -> 168000000 | S38: =E38*F38 -> 1366200000 | T38: =물량원가기준!I38+IF(B38>=설정!$B$6,I38*(설정!$B$18-설정!$B$13),0) -> 60000 | U38: =IF(OR(COUNT(물량원가기준!E38:J38)<>6,COUNTIFS(물량원가기준!$A$6:$A$100,A38)<>1),0,1) -> 1
A39: =물량원가기준!A39 -> 2027-07|A-d | B39: =물량원가기준!B39 -> 46569 | C39: =물량원가기준!C39 -> A-d | D39: =물량원가기준!E39 -> 5050 | E39: =물량원가기준!F39 -> 5050 | F39: =물량원가기준!G39 -> 210000 | G39: =SUM(물량원가기준!H39:J39) -> 185000 | H39: =F39-G39 -> 25000 | I39: =부품모델매핑!D9 -> 0 | J39: =IF(ISNUMBER(물량원가기준!F39),E39*I39,"미산출") -> 0 | K39: =D39*H39 -> 126250000 | L39: =E39*H39 -> 126250000 | M39: =L39-K39 -> 0 | N39: =IF(AND(B39>=설정!$B$6,B39<설정!$B$23),1,0) -> 1 | O39: =IF(AND(B39>=설정!$B$6,B39<설정!$B$24),1,0) -> 1 | P39: =IF(B39>=설정!$B$6,J39*(설정!$B$18-설정!$B$13),0) -> 0 | Q39: =L39-P39 -> 126250000 | R39: =IF(물량원가기준!D39="","",물량원가기준!D39*H39) -> 125000000 | S39: =E39*F39 -> 1060500000 | T39: =물량원가기준!I39+IF(B39>=설정!$B$6,I39*(설정!$B$18-설정!$B$13),0) -> 65000 | U39: =IF(OR(COUNT(물량원가기준!E39:J39)<>6,COUNTIFS(물량원가기준!$A$6:$A$100,A39)<>1),0,1) -> 1
A40: =물량원가기준!A40 -> 2027-07|A-e | B40: =물량원가기준!B40 -> 46569 | C40: =물량원가기준!C40 -> A-e | D40: =물량원가기준!E40 -> 2970 | E40: =물량원가기준!F40 -> 2970 | F40: =물량원가기준!G40 -> 150000 | G40: =SUM(물량원가기준!H40:J40) -> 132000 | H40: =F40-G40 -> 18000 | I40: =부품모델매핑!D10 -> 0 | J40: =IF(ISNUMBER(물량원가기준!F40),E40*I40,"미산출") -> 0 | K40: =D40*H40 -> 53460000 | L40: =E40*H40 -> 53460000 | M40: =L40-K40 -> 0 | N40: =IF(AND(B40>=설정!$B$6,B40<설정!$B$23),1,0) -> 1 | O40: =IF(AND(B40>=설정!$B$6,B40<설정!$B$24),1,0) -> 1 | P40: =IF(B40>=설정!$B$6,J40*(설정!$B$18-설정!$B$13),0) -> 0 | Q40: =L40-P40 -> 53460000 | R40: =IF(물량원가기준!D40="","",물량원가기준!D40*H40) -> 54000000 | S40: =E40*F40 -> 445500000 | T40: =물량원가기준!I40+IF(B40>=설정!$B$6,I40*(설정!$B$18-설정!$B$13),0) -> 50000 | U40: =IF(OR(COUNT(물량원가기준!E40:J40)<>6,COUNTIFS(물량원가기준!$A$6:$A$100,A40)<>1),0,1) -> 1
A41: =물량원가기준!A41 -> 2027-08|A-a | B41: =물량원가기준!B41 -> 46600 | C41: =물량원가기준!C41 -> A-a | D41: =물량원가기준!E41 -> 3496 | E41: =물량원가기준!F41 -> 3496 | F41: =물량원가기준!G41 -> 300000 | G41: =SUM(물량원가기준!H41:J41) -> 270000 | H41: =F41-G41 -> 30000 | I41: =부품모델매핑!D6 -> 1 | J41: =IF(ISNUMBER(물량원가기준!F41),E41*I41,"미산출") -> 3496 | K41: =D41*H41 -> 104880000 | L41: =E41*H41 -> 104880000 | M41: =L41-K41 -> 0 | N41: =IF(AND(B41>=설정!$B$6,B41<설정!$B$23),1,0) -> 1 | O41: =IF(AND(B41>=설정!$B$6,B41<설정!$B$24),1,0) -> 1 | P41: =IF(B41>=설정!$B$6,J41*(설정!$B$18-설정!$B$13),0) -> 419520 | Q41: =L41-P41 -> 104460480 | R41: =IF(물량원가기준!D41="","",물량원가기준!D41*H41) -> 110400000 | S41: =E41*F41 -> 1048800000 | T41: =물량원가기준!I41+IF(B41>=설정!$B$6,I41*(설정!$B$18-설정!$B$13),0) -> 75120 | U41: =IF(OR(COUNT(물량원가기준!E41:J41)<>6,COUNTIFS(물량원가기준!$A$6:$A$100,A41)<>1),0,1) -> 1
A42: =물량원가기준!A42 -> 2027-08|A-b | B42: =물량원가기준!B42 -> 46600 | C42: =물량원가기준!C42 -> A-b | D42: =물량원가기준!E42 -> 8740 | E42: =물량원가기준!F42 -> 8740 | F42: =물량원가기준!G42 -> 180000 | G42: =SUM(물량원가기준!H42:J42) -> 160000 | H42: =F42-G42 -> 20000 | I42: =부품모델매핑!D7 -> 1 | J42: =IF(ISNUMBER(물량원가기준!F42),E42*I42,"미산출") -> 8740 | K42: =D42*H42 -> 174800000 | L42: =E42*H42 -> 174800000 | M42: =L42-K42 -> 0 | N42: =IF(AND(B42>=설정!$B$6,B42<설정!$B$23),1,0) -> 1 | O42: =IF(AND(B42>=설정!$B$6,B42<설정!$B$24),1,0) -> 1 | P42: =IF(B42>=설정!$B$6,J42*(설정!$B$18-설정!$B$13),0) -> 1048800 | Q42: =L42-P42 -> 173751200 | R42: =IF(물량원가기준!D42="","",물량원가기준!D42*H42) -> 184000000 | S42: =E42*F42 -> 1573200000 | T42: =물량원가기준!I42+IF(B42>=설정!$B$6,I42*(설정!$B$18-설정!$B$13),0) -> 95120 | U42: =IF(OR(COUNT(물량원가기준!E42:J42)<>6,COUNTIFS(물량원가기준!$A$6:$A$100,A42)<>1),0,1) -> 1
...

Sheet 물량원가기준
A1: 2027 기준 및 2028 내부가정
A3: 출처: INNONOW_SC01_통합가상데이터설계_v0.1.xlsx 손익계산·단위원가. 2027 값 보존. 수량은 당사 배정 대분이며 40%를 재적용하지 않습니다.
A5: row_key | B5: period | C5: model_id | D5: T01_qty | E5: F01_qty | F5: F02_qty | G5: 판매단가 | H5: 재료비 | I5: 기존외주비 | J5: 변동가공비 | K5: 실적수량 | L5: 기간성격 | M5: source_ref | N5: 확실성
A6: 2027-01|A-a | B6: 46388 | C6: A-a | D6: 4080 | E6: 4080 | F6: 4080 | G6: 300000 | H6: 175000 | I6: 75000 | J6: 20000 | K6: 4080 | L6: 확정실적 포함 | M6: SC01 v0.1 / F01·F02·C01 | N6: 내부전망 또는 실적
A7: 2027-01|A-b | B7: 46388 | C7: A-b | D7: 10200 | E7: 10200 | F7: 10200 | G7: 180000 | H7: 55000 | I7: 95000 | J7: 10000 | K7: 10200 | L7: 확정실적 포함 | M7: SC01 v0.1 / F01·F02·C01 | N7: 내부전망 또는 실적
A8: 2027-01|A-c | B8: 46388 | C8: A-c | D8: 6120 | E8: 6059 | F8: 6059 | G8: 230000 | H8: 125000 | I8: 60000 | J8: 17000 | K8: 6059 | L8: 확정실적 포함 | M8: SC01 v0.1 / F01·F02·C01 | N8: 내부전망 또는 실적
A9: 2027-01|A-d | B9: 46388 | C9: A-d | D9: 5100 | E9: 5151 | F9: 5151 | G9: 210000 | H9: 105000 | I9: 65000 | J9: 15000 | K9: 5151 | L9: 확정실적 포함 | M9: SC01 v0.1 / F01·F02·C01 | N9: 내부전망 또는 실적
A10: 2027-01|A-e | B10: 46388 | C10: A-e | D10: 3060 | E10: 3029 | F10: 3029 | G10: 150000 | H10: 70000 | I10: 50000 | J10: 12000 | K10: 3029 | L10: 확정실적 포함 | M10: SC01 v0.1 / F01·F02·C01 | N10: 내부전망 또는 실적
A11: 2027-02|A-a | B11: 46419 | C11: A-a | D11: 3600 | E11: 3564 | F11: 3564 | G11: 300000 | H11: 175000 | I11: 75000 | J11: 20000 | K11: 3564 | L11: 확정실적 포함 | M11: SC01 v0.1 / F01·F02·C01 | N11: 내부전망 또는 실적
A12: 2027-02|A-b | B12: 46419 | C12: A-b | D12: 9000 | E12: 8910 | F12: 8910 | G12: 180000 | H12: 55000 | I12: 95000 | J12: 10000 | K12: 8910 | L12: 확정실적 포함 | M12: SC01 v0.1 / F01·F02·C01 | N12: 내부전망 또는 실적
A13: 2027-02|A-c | B13: 46419 | C13: A-c | D13: 5400 | E13: 5346 | F13: 5346 | G13: 230000 | H13: 125000 | I13: 60000 | J13: 17000 | K13: 5346 | L13: 확정실적 포함 | M13: SC01 v0.1 / F01·F02·C01 | N13: 내부전망 또는 실적
A14: 2027-02|A-d | B14: 46419 | C14: A-d | D14: 4500 | E14: 4545 | F14: 4545 | G14: 210000 | H14: 105000 | I14: 65000 | J14: 15000 | K14: 4545 | L14: 확정실적 포함 | M14: SC01 v0.1 / F01·F02·C01 | N14: 내부전망 또는 실적
A15: 2027-02|A-e | B15: 46419 | C15: A-e | D15: 2700 | E15: 2673 | F15: 2673 | G15: 150000 | H15: 70000 | I15: 50000 | J15: 12000 | K15: 2673 | L15: 확정실적 포함 | M15: SC01 v0.1 / F01·F02·C01 | N15: 내부전망 또는 실적
A16: 2027-03|A-a | B16: 46447 | C16: A-a | D16: 4200 | E16: 4116 | F16: 4116 | G16: 300000 | H16: 175000 | I16: 75000 | J16: 20000 | K16: 4116 | L16: 확정실적 포함 | M16: SC01 v0.1 / F01·F02·C01 | N16: 내부전망 또는 실적
A17: 2027-03|A-b | B17: 46447 | C17: A-b | D17: 10500 | E17: 10290 | F17: 10290 | G17: 180000 | H17: 55000 | I17: 95000 | J17: 10000 | K17: 10290 | L17: 확정실적 포함 | M17: SC01 v0.1 / F01·F02·C01 | N17: 내부전망 또는 실적
... A35: 2027-06|A-e | B35: 46539 | C35: A-e | D35: 3000 | E35: 2970 | F35: 2970 | G35: 150000 | H35: 70000 | I35: 50000 | J35: 12000 | K35: 1336 | L35: 6/15 실적+잔여전망 | M35: SC01 v0.1 / F01·F02·C01 | N35: 내부전망 또는 실적
A36: 2027-07|A-a | B36: 46569 | C36: A-a | D36: 4000 | E36: 3800 | F36: 3800 | G36: 300000 | H36: 175000 | I36: 75000 | J36: 20000 | L36: 미래전망 | M36: SC01 v0.1 / F01·F02·C01 | N36: CP02 확인물량
A37: 2027-07|A-b | B37: 46569 | C37: A-b | D37: 10000 | E37: 9500 | F37: 8800 | G37: 180000 | H37: 55000 | I37: 95000 | J37: 10000 | L37: 미래전망 | M37: SC01 v0.1 / F01·F02·C01 | N37: CP02 확인물량
A38: 2027-07|A-c | B38: 46569 | C38: A-c | D38: 6000 | E38: 5940 | F38: 5940 | G38: 230000 | H38: 125000 | I38: 60000 | J38: 17000 | L38: 미래전망 | M38: SC01 v0.1 / F01·F02·C01 | N38: CP02 확인물량
A39: 2027-07|A-d | B39: 46569 | C39: A-d | D39: 5000 | E39: 5050 | F39: 5050 | G39: 210000 | H39: 105000 | I39: 65000 | J39: 15000 | L39: 미래전망 | M39: SC01 v0.1 / F01·F02·C01 | N39: CP02 확인물량
A40: 2027-07|A-e | B40: 46569 | C40: A-e | D40: 3000 | E40: 2970 | F40: 2970 | G40: 150000 | H40: 70000 | I40: 50000 | J40: 12000 | L40: 미래전망 | M40: SC01 v0.1 / F01·F02·C01 | N40: CP02 확인물량
A41: 2027-08|A-a | B41: 46600 | C41: A-a | D41: 3680 | E41: 3496 | F41: 3496 | G41: 300000 | H41: 175000 | I41: 75000 | J41: 20000 | L41: 미래전망 | M41: SC01 v0.1 / F01·F02·C01 | N41: CP02 확인물량
A42: 2027-08|A-b | B42: 46600 | C42: A-b | D42: 9200 | E42: 8740 | F42: 8740 | G42: 180000 | H42: 55000 | I42: 95000 | J42: 10000 | L42: 미래전망 | M42: SC01 v0.1 / F01·F02·C01 | N42: CP02 확인물량
A43: 2027-08|A-c | B43: 46600 | C43: A-c | D43: 5520 | E43: 5465 | F43: 5465 | G43: 230000 | H43: 125000 | I43: 60000 | J43: 17000 | L43: 미래전망 | M43: SC01 v0.1 / F01·F02·C01 | N43: CP02 확인물량
A44: 2027-08|A-d | B44: 46600 | C44: A-d | D44: 4600 | E44: 4646 | F44: 4646 | G44: 210000 | H44: 105000 | I44: 65000 | J44: 15000 | L44: 미래전망 | M44: SC01 v0.1 / F01·F02·C01 | N44: CP02 확인물량
A45: 2027-08|A-e | B45: 46600 | C45: A-e | D45: 2760 | E45: 2732 | F45: 2732 | G45: 150000 | H45: 70000 | I45: 50000 | J45: 12000 | L45: 미래전망 | M45: SC01 v0.1 / F01·F02·C01 | N45: CP02 확인물량
A46: 2027-09|A-a | B46: 46631 | C46: A-a | D46: 4120 | E46: 3914 | F46: 3914 | G46: 300000 | H46: 175000 | I46: 75000 | J46: 20000 | L46: 미래전망 | M46: SC01 v0.1 / F01·F02·C01 | N46: CP02 확인물량
