Workbook

Sheet 설계안
A2: SC01 통합 가상 데이터 설계 v0.1
A3: 작성일 2026-10-18 | 실제 운영연도와 무관한 가상 시점 2027년 | 금액 원, 물량 대분
A5: ID | B5: 주제 | C5: 설계 내용 | D5: 상태·메모
A6: D01 | B6: 데이터 목적 | C6: UI01~UI06을 동일한 가상 데이터로 채우고 장면1의 재현·검증에 사용. 새로운 수치·회사 규모 배분·달력은 제안. | D6: 공동 검토
A7: D02 | B7: 배경과 범위 | C7: 회사 전체 매출 약1조원은 배경. 상세 데이터는 A제품·울산공장의 가상 5모델 집계 범위. 전사 1조원과 이 범위를 억지로 맞추지 않음. | D7: UI01에 범위 명시
A8: D03 | B8: 원천 | C8: 수치 출처: 본 대화의 b모델 10000/9500/8800, 단위공헌이익20000 및 경보. 나머지는 작성한 가상 가정. 실제 회사 자료 없음. | D8: 가상 데이터
A9: D04 | B9: 시간 | C9: 가상 2027-06-16 수신. 실적마감 5월, 누계실적 컷오프6/15. 7월 사건. 원천은7~9월 전체물량. 10~12월은 내부가정. | D9: 제안
A10: D05 | B10: 고객·공장 | C10: CUS-HK=현대·기아 합산 가상 고객군. ULS=울산. A-a~A-e. 실제 적용에서는 고객 법인별로 분리. 40% 일괄 곱셈 금지. | D10: 배정물량 직접 사용
A11: D06 | B11: 모델 | C11: a 고단가·소량, b 저단가·다량. c~e 비교용. 단위공헌이익은 분석용 가정이며 고급모델 수익성 우월을 의미하지 않음. | D11: 원가 검토 필요
A12: D07 | B12: 계획과 승인 | C12: T01 고정 목표. F01 승인 전망. F02 확인된 검토중 전망. UI01 기본승인값 F01, 사건 영향보기 F02. F02를 자동 공식 전망으로 승격하지 않음. | D12: 합의 원칙 반영
A13: D08 | B13: 완성월과 월중 | C13: F01/F02의1~5월=확정실적. 6월=6/15누계+6/16~30잔여전망. 월전체 전망에 누계를 재가산하지 않음. | D13: 6월 실적 숫자는 월 누계
A14: D09 | B14: 미래 정보 | C14: 7월 b 감소만 반영. 8·9월 원천은 직전과 동일. 10~12월은 변화가 없다는 내부 가정. 700 감소를 이후월에 자동 전파하지 않음. | D14: 가정과 고객정보 분리
A15: D10 | B15: 재무 기준 | C15: 매출=납품수량×단가. 변동비=재료+외주+내부변동가공비. 공헌이익=매출−변동비. 공장관리손익=공헌이익−공장고정비. | D15: 납품=생산 가정·재고효과 제외
A16: D11 | B16: 손익 범위 | C16: 본사공통비·금융비용·세금 제외. 공장고정비는 한 번만 차감하고 모델별 배부손익은 만들지 않음. | D16: 회계 전사 영업이익과 구분
... A26: D21 | B26: 읽는 순서 | C26: 설계안→월분기연간→SC01검증→업무이력→원천·사전. 숫자수정시 정합성검증 확인. 개발은 row5의 영문 키로 적재 가능. | D26: 자료형·키는 데이터사전

Sheet 월분기연간
A2: A제품·울산공장 관리손익
A3: 원. F01=승인 전망, F02=검토중 전망. a~e만 집계. 회사 전체1조원과 구분.
A5: 기간 | B5: 시작월 | C5: 종료월 | D5: 기간 성격 | E5: T매출 | F5: F01매출 | G5: F02매출 | H5: T공헌이익 | I5: F01공헌이익 | J5: F02공헌이익 | K5: 공장고정비 | L5: T관리손익 | M5: F01관리손익 | N5: F02관리손익 | O5: 사건순영향 | P5: 목표차이 | Q5: 6월잔여물량
A6: 1월 | B6: 1 | C6: 1 | D6: 확정실적 | E6: =SUM(손익계산!J6:J10) -> 5997600000 | F6: =SUM(손익계산!K6:K10) -> 5989630000 | G6: =SUM(손익계산!L6:L10) -> 5989630000 | H6: =SUM(손익계산!M6:M10) -> 680340000 | I6: =SUM(손익계산!N6:N10) -> 679349000 | J6: =SUM(손익계산!O6:O10) -> 679349000 | K6: =고정비!I6 -> 370000000 | L6: =H6-K6 -> 310340000 | M6: =I6-K6 -> 309349000 | N6: =J6-K6 -> 309349000 | O6: =N6-M6 -> 0 | P6: =L6-N6 -> 991000
A7: 2월 | B7: 2 | C7: 2 | D7: 확정실적 | E7: =SUM(손익계산!J11:J15) -> 5292000000 | F7: =SUM(손익계산!K11:K15) -> 5257980000 | G7: =SUM(손익계산!L11:L15) -> 5257980000 | H7: =SUM(손익계산!M11:M15) -> 600300000 | I7: =SUM(손익계산!N11:N15) -> 596547000 | J7: =SUM(손익계산!O11:O15) -> 596547000 | K7: =고정비!I7 -> 370000000 | L7: =H7-K7 -> 230300000 | M7: =I7-K7 -> 226547000 | N7: =J7-K7 -> 226547000 | O7: =N7-M7 -> 0 | P7: =L7-N7 -> 3753000
A8: 3월 | B8: 3 | C8: 3 | D8: 확정실적 | E8: =SUM(손익계산!J16:J20) -> 6174000000 | F8: =SUM(손익계산!K16:K20) -> 6102990000 | G8: =SUM(손익계산!L16:L20) -> 6102990000 | H8: =SUM(손익계산!M16:M20) -> 700350000 | I8: =SUM(손익계산!N16:N20) -> 692633000 | J8: =SUM(손익계산!O16:O20) -> 692633000 | K8: =고정비!I8 -> 370000000 | L8: =H8-K8 -> 330350000 | M8: =I8-K8 -> 322633000 | N8: =J8-K8 -> 322633000 | O8: =N8-M8 -> 0 | P8: =L8-N8 -> 7717000
A9: 4월 | B9: 4 | C9: 4 | D9: 확정실적 | E9: =SUM(손익계산!J21:J25) -> 5880000000 | F9: =SUM(손익계산!K21:K25) -> 5782200000 | G9: =SUM(손익계산!L21:L25) -> 5782200000 | H9: =SUM(손익계산!M21:M25) -> 667000000 | I9: =SUM(손익계산!N21:N25) -> 656430000 | J9: =SUM(손익계산!O21:O25) -> 656430000 | K9: =고정비!I9 -> 370000000 | L9: =H9-K9 -> 297000000 | M9: =I9-K9 -> 286430000 | N9: =J9-K9 -> 286430000 | O9: =N9-M9 -> 0 | P9: =L9-N9 -> 10570000
A10: 5월 | B10: 5 | C10: 5 | D10: 확정실적 | E10: =SUM(손익계산!J26:J30) -> 5762400000 | F10: =SUM(손익계산!K26:K30) -> 5637110000 | G10: =SUM(손익계산!L26:L30) -> 5637110000 | H10: =SUM(손익계산!M26:M30) -> 653660000 | I10: =SUM(손익계산!N26:N30) -> 640161000 | J10: =SUM(손익계산!O26:O30) -> 640161000 | K10: =고정비!I10 -> 370000000 | L10: =H10-K10 -> 283660000 | M10: =I10-K10 -> 270161000 | N10: =J10-K10 -> 270161000 | O10: =N10-M10 -> 0 | P10: =L10-N10 -> 13499000
A11: 6월 | B11: 6 | C11: 6 | D11: 6/15누계+잔여전망 | E11: =SUM(손익계산!J31:J35) -> 5880000000 | F11: =SUM(손익계산!K31:K35) -> 5722200000 | G11: =SUM(손익계산!L31:L35) -> 5722200000 | H11: =SUM(손익계산!M31:M35) -> 667000000 | I11: =SUM(손익계산!N31:N35) -> 650030000 | J11: =SUM(손익계산!O31:O35) -> 650030000 | K11: =고정비!I11 -> 370000000 | L11: =H11-K11 -> 297000000 | M11: =I11-K11 -> 280030000 | N11: =J11-K11 -> 280030000 | O11: =N11-M11 -> 0 | P11: =L11-N11 -> 16970000 | Q11: =SUM(손익계산!F31:F35)-SUM(손익계산!P31:P35) -> 14994
A12: 7월 | B12: 7 | C12: 7 | D12: 전망 | E12: =SUM(손익계산!J36:J40) -> 5880000000 | F12: =SUM(손익계산!K36:K40) -> 5722200000 | G12: =SUM(손익계산!L36:L40) -> 5596200000 | H12: =SUM(손익계산!M36:M40) -> 667000000 | I12: =SUM(손익계산!N36:N40) -> 650030000 | J12: =SUM(손익계산!O36:O40) -> 636030000 | K12: =고정비!I12 -> 370000000 | L12: =H12-K12 -> 297000000 | M12: =I12-K12 -> 280030000 | N12: =J12-K12 -> 266030000 | O12: =N12-M12 -> -14000000 | P12: =L12-N12 -> 30970000
A13: 8월 | B13: 8 | C13: 8 | D13: 전망 | E13: =SUM(손익계산!J41:J45) -> 5409600000 | F13: =SUM(손익계산!K41:K45) -> 5264410000 | G13: =SUM(손익계산!L41:L45) -> 5264410000 | H13: =SUM(손익계산!M41:M45) -> 613640000 | I13: =SUM(손익계산!N41:N45) -> 598026000 | J13: =SUM(손익계산!O41:O45) -> 598026000 | K13: =고정비!I13 -> 370000000 | L13: =H13-K13 -> 243640000 | M13: =I13-K13 -> 228026000 | N13: =J13-K13 -> 228026000 | O13: =N13-M13 -> 0 | P13: =L13-N13 -> 15614000
A14: 9월 | B14: 9 | C14: 9 | D14: 전망 | E14: =SUM(손익계산!J46:J50) -> 6056400000 | F14: =SUM(손익계산!K46:K50) -> 5893910000 | G14: =SUM(손익계산!L46:L50) -> 5893910000 | H14: =SUM(손익계산!M46:M50) -> 687010000 | I14: =SUM(손익계산!N46:N50) -> 669536000 | J14: =SUM(손익계산!O46:O50) -> 669536000 | K14: =고정비!I14 -> 370000000 | L14: =H14-K14 -> 317010000 | M14: =I14-K14 -> 299536000 | N14: =J14-K14 -> 299536000 | O14: =N14-M14 -> 0 | P14: =L14-N14 -> 17474000
A15: 10월 | B15: 10 | C15: 10 | D15: 전망 | E15: =SUM(손익계산!J51:J55) -> 5997600000 | F15: =SUM(손익계산!K51:K55) -> 5836630000 | G15: =SUM(손익계산!L51:L55) -> 5836630000 | H15: =SUM(손익계산!M51:M55) -> 680340000 | I15: =SUM(손익계산!N51:N55) -> 663029000 | J15: =SUM(손익계산!O51:O55) -> 663029000 | K15: =고정비!I15 -> 370000000 | L15: =H15-K15 -> 310340000 | M15: =I15-K15 -> 293029000 | N15: =J15-K15 -> 293029000 | O15: =N15-M15 -> 0 | P15: =L15-N15 -> 17311000
A16: 11월 | B16: 11 | C16: 11 | D16: 전망 | E16: =SUM(손익계산!J56:J60) -> 5880000000 | F16: =SUM(손익계산!K56:K60) -> 5722200000 | G16: =SUM(손익계산!L56:L60) -> 5722200000 | H16: =SUM(손익계산!M56:M60) -> 667000000 | I16: =SUM(손익계산!N56:N60) -> 650030000 | J16: =SUM(손익계산!O56:O60) -> 650030000 | K16: =고정비!I16 -> 370000000 | L16: =H16-K16 -> 297000000 | M16: =I16-K16 -> 280030000 | N16: =J16-K16 -> 280030000 | O16: =N16-M16 -> 0 | P16: =L16-N16 -> 16970000
A17: 12월 | B17: 12 | C17: 12 | D17: 전망 | E17: =SUM(손익계산!J61:J65) -> 5586000000 | F17: =SUM(손익계산!K61:K65) -> 5436270000 | G17: =SUM(손익계산!L61:L65) -> 5436270000 | H17: =SUM(손익계산!M61:M65) -> 633650000 | I17: =SUM(손익계산!N61:N65) -> 617550000 | J17: =SUM(손익계산!O61:O65) -> 617550000 | K17: =고정비!I17 -> 370000000 | L17: =H17-K17 -> 263650000 | M17: =I17-K17 -> 247550000 | N17: =J17-K17 -> 247550000 | O17: =N17-M17 -> 0 | P17: =L17-N17 -> 16100000
A18: Q1 | B18: 1 | C18: 3 | D18: 확정실적 | E18: =SUM(E6:E8) -> 17463600000 | F18: =SUM(F6:F8) -> 17350600000 | G18: =SUM(G6:G8) -> 17350600000 | H18: =SUM(H6:H8) -> 1980990000 | I18: =SUM(I6:I8) -> 1968529000 | J18: =SUM(J6:J8) -> 1968529000 | K18: =SUM(K6:K8) -> 1110000000 | L18: =SUM(L6:L8) -> 870990000 | ... P18: =SUM(P6:P8) -> 12461000
A19: Q2 | B19: 4 | C19: 6 | D19: 실적+전망 | E19: =SUM(E9:E11) -> 17522400000 | F19: =SUM(F9:F11) -> 17141510000 | G19: =SUM(G9:G11) -> 17141510000 | H19: =SUM(H9:H11) -> 1987660000 | I19: =SUM(I9:I11) -> 1946621000 | J19: =SUM(J9:J11) -> 1946621000 | K19: =SUM(K9:K11) -> 1110000000 | L19: =SUM(L9:L11) -> 877660000 | ... P19: =SUM(P9:P11) -> 41039000
A20: Q3 | B20: 7 | C20: 9 | D20: 전망 | E20: =SUM(E12:E14) -> 17346000000 | F20: =SUM(F12:F14) -> 16880520000 | G20: =SUM(G12:G14) -> 16754520000 | H20: =SUM(H12:H14) -> 1967650000 | I20: =SUM(I12:I14) -> 1917592000 | J20: =SUM(J12:J14) -> 1903592000 | K20: =SUM(K12:K14) -> 1110000000 | L20: =SUM(L12:L14) -> 857650000 | ... P20: =SUM(P12:P14) -> 64058000
A21: Q4 | B21: 10 | C21: 12 | D21: 전망 | E21: =SUM(E15:E17) -> 17463600000 | F21: =SUM(F15:F17) -> 16995100000 | G21: =SUM(G15:G17) -> 16995100000 | H21: =SUM(H15:H17) -> 1980990000 | I21: =SUM(I15:I17) -> 1930609000 | J21: =SUM(J15:J17) -> 1930609000 | K21: =SUM(K15:K17) -> 1110000000 | L21: =SUM(L15:L17) -> 870990000 | ... P21: =SUM(P15:P17) -> 50381000
A22: 연간 | B22: 1 | C22: 12 | D22: 실적+전망 | E22: =SUM(E6:E17) -> 69795600000 | F22: =SUM(F6:F17) -> 68367730000 | G22: =SUM(G6:G17) -> 68241730000 | H22: =SUM(H6:H17) -> 7917290000 | I22: =SUM(I6:I17) -> 7763351000 | J22: =SUM(J6:J17) -> 7749351000 | K22: =SUM(K6:K17) -> 4440000000 | L22: =SUM(L6:L17) -> 3477290000 | ... P22: =SUM(P6:P17) -> 167939000

Sheet SC01검증
A2: 공급전망 변경·위험 검증
A3: 3개월×5모델. F01→F02 비교. a의 기존 관심, b의 중요 상승, c~e의 정상 유지를 확인.
A5: run_id | B5: period | C5: model_id | D5: Target | E5: Prior | F5: Latest | G5: 달성률 | H5: 추가감소 | I5: 감소율 | J5: 순손익영향 | K5: 감소액 | L5: 목표부족률 | M5: 위험수준 | N5: 업무 연결
A6: RUN-F02-001 | B6: 46569 | C6: A-a | D6: =손익계산!D36 -> 4000 | E6: =손익계산!E36 -> 3800 | F6: =손익계산!F36 -> 3800 | G6: =IF(D6=0,"미산출",F6/D6) -> 0.95 | H6: =E6-F6 -> 0 | I6: =IF(E6=0,"미산출",ROUND(H6/E6,8)) -> 0 | J6: =(F6-E6)*손익계산!I36 -> 0 | K6: =MAX(-J6,0) -> 0 | L6: =IF(D6=0,"미산출",ROUND(MAX(1-G6,0),8)) -> 0.05 | M6: =IF(OR(I6>=버전기준!$B$17,K6>=버전기준!$B$19,L6>=버전기준!$B$21),"중요",IF(OR(I6>=버전기준!$B$16,K6>=버전기준!$B$18,L6>=버전기준!$B$20),"관심","기준 이내")) -> 관심 | N6: =IF(M6="중요","기존 이슈 상향·Review",IF(H6<>0,"현업 변경검토",IF(M6="관심","기존 관심 추적","추가 변경없음"))) -> 기존 관심 추적
A7: RUN-F02-001 | B7: 46569 | C7: A-b | D7: =손익계산!D37 -> 10000 | E7: =손익계산!E37 -> 9500 | F7: =손익계산!F37 -> 8800 | G7: =IF(D7=0,"미산출",F7/D7) -> 0.88 | H7: =E7-F7 -> 700 | I7: =IF(E7=0,"미산출",ROUND(H7/E7,8)) -> 0.07368421 | J7: =(F7-E7)*손익계산!I37 -> -14000000 | K7: =MAX(-J7,0) -> 14000000 | L7: =IF(D7=0,"미산출",ROUND(MAX(1-G7,0),8)) -> 0.12 | M7: =IF(OR(I7>=버전기준!$B$17,K7>=버전기준!$B$19,L7>=버전기준!$B$21),"중요",IF(OR(I7>=버전기준!$B$16,K7>=버전기준!$B$18,L7>=버전기준!$B$20),"관심","기준 이내")) -> 중요 | N7: =IF(M7="중요","기존 이슈 상향·Review",IF(H7<>0,"현업 변경검토",IF(M7="관심","기존 관심 추적","추가 변경없음"))) -> 기존 이슈 상향·Review
A8: RUN-F02-001 | B8: 46569 | C8: A-c | D8: =손익계산!D38 -> 6000 | E8: =손익계산!E38 -> 5940 | F8: =손익계산!F38 -> 5940 | G8: =IF(D8=0,"미산출",F8/D8) -> 0.99 | H8: =E8-F8 -> 0 | I8: =IF(E8=0,"미산출",ROUND(H8/E8,8)) -> 0 | J8: =(F8-E8)*손익계산!I38 -> 0 | K8: =MAX(-J8,0) -> 0 | L8: =IF(D8=0,"미산출",ROUND(MAX(1-G8,0),8)) -> 0.01 | M8: =IF(OR(I8>=버전기준!$B$17,K8>=버전기준!$B$19,L8>=버전기준!$B$21),"중요",IF(OR(I8>=버전기준!$B$16,K8>=버전기준!$B$18,L8>=버전기준!$B$20),"관심","기준 이내")) -> 기준 이내 | N8: =IF(M8="중요","기존 이슈 상향·Review",IF(H8<>0,"현업 변경검토",IF(M8="관심","기존 관심 추적","추가 변경없음"))) -> 추가 변경없음
A9: RUN-F02-001 | B9: 46569 | C9: A-d | D9: =손익계산!D39 -> 5000 | E9: =손익계산!E39 -> 5050 | F9: =손익계산!F39 -> 5050 | G9: =IF(D9=0,"미산출",F9/D9) -> 1.01 | H9: =E9-F9 -> 0 | I9: =IF(E9=0,"미산출",ROUND(H9/E9,8)) -> 0 | J9: =(F9-E9)*손익계산!I39 -> 0 | K9: =MAX(-J9,0) -> 0 | L9: =IF(D9=0,"미산출",ROUND(MAX(1-G9,0),8)) -> 0 | M9: =IF(OR(I9>=버전기준!$B$17,K9>=버전기준!$B$19,L9>=버전기준!$B$21),"중요",IF(OR(I9>=버전기준!$B$16,K9>=버전기준!$B$18,L9>=버전기준!$B$20),"관심","기준 이내")) -> 기준 이내 | N9: =IF(M9="중요","기존 이슈 상향·Review",IF(H9<>0,"현업 변경검토",IF(M9="관심","기존 관심 추적","추가 변경없음"))) -> 추가 변경없음
A10: RUN-F02-001 | B10: 46569 | C10: A-e | D10: =손익계산!D40 -> 3000 | E10: =손익계산!E40 -> 2970 | F10: =손익계산!F40 -> 2970 | G10: =IF(D10=0,"미산출",F10/D10) -> 0.99 | H10: =E10-F10 -> 0 | I10: =IF(E10=0,"미산출",ROUND(H10/E10,8)) -> 0 | J10: =(F10-E10)*손익계산!I40 -> 0 | K10: =MAX(-J10,0) -> 0 | L10: =IF(D10=0,"미산출",ROUND(MAX(1-G10,0),8)) -> 0.01 | M10: =IF(OR(I10>=버전기준!$B$17,K10>=버전기준!$B$19,L10>=버전기준!$B$21),"중요",IF(OR(I10>=버전기준!$B$16,K10>=버전기준!$B$18,L10>=버전기준!$B$20),"관심","기준 이내")) -> 기준 이내 | N10: =IF(M10="중요","기존 이슈 상향·Review",IF(H10<>0,"현업 변경검토",IF(M10="관심","기존 관심 추적","추가 변경없음"))) -> 추가 변경없음
A11: RUN-F02-001 | B11: 46600 | C11: A-a | D11: =손익계산!D41 -> 3680 | E11: =손익계산!E41 -> 3496 | F11: =손익계산!F41 -> 3496 | G11: =IF(D11=0,"미산출",F11/D11) -> 0.95 | H11: =E11-F11 -> 0 | I11: =IF(E11=0,"미산출",ROUND(H11/E11,8)) -> 0 | J11: =(F11-E11)*손익계산!I41 -> 0 | K11: =MAX(-J11,0) -> 0 | L11: =IF(D11=0,"미산출",ROUND(MAX(1-G11,0),8)) -> 0.05 | M11: =IF(OR(I11>=버전기준!$B$17,K11>=버전기준!$B$19,L11>=버전기준!$B$21),"중요",IF(OR(I11>=버전기준!$B$16,K11>=버전기준!$B$18,L11>=버전기준!$B$20),"관심","기준 이내")) -> 관심 | N11: =IF(M11="중요","기존 이슈 상향·Review",IF(H11<>0,"현업 변경검토",IF(M11="관심","기존 관심 추적","추가 변경없음"))) -> 기존 관심 추적
A12: RUN-F02-001 | B12: 46600 | C12: A-b | D12: =손익계산!D42 -> 9200 | E12: =손익계산!E42 -> 8740 | F12: =손익계산!F42 -> 8740 | G12: =IF(D12=0,"미산출",F12/D12) -> 0.95 | H12: =E12-F12 -> 0 | I12: =IF(E12=0,"미산출",ROUND(H12/E12,8)) -> 0 | J12: =(F12-E12)*손익계산!I42 -> 0 | K12: =MAX(-J12,0) -> 0 | L12: =IF(D12=0,"미산출",ROUND(MAX(1-G12,0),8)) -> 0.05 | M12: =IF(OR(I12>=버전기준!$B$17,K12>=버전기준!$B$19,L12>=버전기준!$B$21),"중요",IF(OR(I12>=버전기준!$B$16,K12>=버전기준!$B$18,L12>=버전기준!$B$20),"관심","기준 이내")) -> 관심 | N12: =IF(M12="중요","기존 이슈 상향·Review",IF(H12<>0,"현업 변경검토",IF(M12="관심","기존 관심 추적","추가 변경없음"))) -> 기존 관심 추적
A13: RUN-F02-001 | B13: 46600 | C13: A-c | D13: =손익계산!D43 -> 5520 | E13: =손익계산!E43 -> 5465 | F13: =손익계산!F43 -> 5465 | G13: =IF(D13=0,"미산출",F13/D13) -> 0.99003623 | H13: =E13-F13 -> 0 | I13: =IF(E13=0,"미산출",ROUND(H13/E13,8)) -> 0 | J13: =(F13-E13)*손익계산!I43 -> 0 | K13: =MAX(-J13,0) -> 0 | L13: =IF(D13=0,"미산출",ROUND(MAX(1-G13,0),8)) -> 0.00996377 | M13: =IF(OR(I13>=버전기준!$B$17,K13>=버전기준!$B$19,L13>=버전기준!$B$21),"중요",IF(OR(I13>=버전기준!$B$16,K13>=버전기준!$B$18,L13>=버전기준!$B$20),"관심","기준 이내")) -> 기준 이내 | N13: =IF(M13="중요","기존 이슈 상향·Review",IF(H13<>0,"현업 변경검토",IF(M13="관심","기존 관심 추적","추가 변경없음"))) -> 추가 변경없음
A14: RUN-F02-001 | B14: 46600 | C14: A-d | D14: =손익계산!D44 -> 4600 | E14: =손익계산!E44 -> 4646 | F14: =손익계산!F44 -> 4646 | G14: =IF(D14=0,"미산출",F14/D14) -> 1.01 | H14: =E14-F14 -> 0 | I14: =IF(E14=0,"미산출",ROUND(H14/E14,8)) -> 0 | J14: =(F14-E14)*손익계산!I44 -> 0 | K14: =MAX(-J14,0) -> 0 | L14: =IF(D14=0,"미산출",ROUND(MAX(1-G14,0),8)) -> 0 | M14: =IF(OR(I14>=버전기준!$B$17,K14>=버전기준!$B$19,L14>=버전기준!$B$21),"중요",IF(OR(I14>=버전기준!$B$16,K14>=버전기준!$B$18,L14>=버전기준!$B$20),"관심","기준 이내")) -> 기준 이내 | N14: =IF(M14="중요","기존 이슈 상향·Review",IF(H14<>0,"현업 변경검토",IF(M14="관심","기존 관심 추적","추가 변경없음"))) -> 추가 변경없음
A15: RUN-F02-001 | B15: 46600 | C15: A-e | D15: =손익계산!D45 -> 2760 | E15: =손익계산!E45 -> 2732 | F15: =손익계산!F45 -> 2732 | G15: =IF(D15=0,"미산출",F15/D15) -> 0.98985507 | H15: =E15-F15 -> 0 | I15: =IF(E15=0,"미산출",ROUND(H15/E15,8)) -> 0 | J15: =(F15-E15)*손익계산!I45 -> 0 | K15: =MAX(-J15,0) -> 0 | L15: =IF(D15=0,"미산출",ROUND(MAX(1-G15,0),8)) -> 0.01014493 | M15: =IF(OR(I15>=버전기준!$B$17,K15>=버전기준!$B$19,L15>=버전기준!$B$21),"중요",IF(OR(I15>=버전기준!$B$16,K15>=버전기준!$B$18,L15>=버전기준!$B$20),"관심","기준 이내")) -> 기준 이내 | N15: =IF(M15="중요","기존 이슈 상향·Review",IF(H15<>0,"현업 변경검토",IF(M15="관심","기존 관심 추적","추가 변경없음"))) -> 추가 변경없음
A16: RUN-F02-001 | B16: 46631 | C16: A-a | D16: =손익계산!D46 -> 4120 | E16: =손익계산!E46 -> 3914 | F16: =손익계산!F46 -> 3914 | G16: =IF(D16=0,"미산출",F16/D16) -> 0.95 | H16: =E16-F16 -> 0 | I16: =IF(E16=0,"미산출",ROUND(H16/E16,8)) -> 0 | J16: =(F16-E16)*손익계산!I46 -> 0 | K16: =MAX(-J16,0) -> 0 | L16: =IF(D16=0,"미산출",ROUND(MAX(1-G16,0),8)) -> 0.05 | M16: =IF(OR(I16>=버전기준!$B$17,K16>=버전기준!$B$19,L16>=버전기준!$B$21),"중요",IF(OR(I16>=버전기준!$B$16,K16>=버전기준!$B$18,L16>=버전기준!$B$20),"관심","기준 이내")) -> 관심 | N16: =IF(M16="중요","기존 이슈 상향·Review",IF(H16<>0,"현업 변경검토",IF(M16="관심","기존 관심 추적","추가 변경없음"))) -> 기존 관심 추적
A17: RUN-F02-001 | B17: 46631 | C17: A-b | D17: =손익계산!D47 -> 10300 | E17: =손익계산!E47 -> 9785 | F17: =손익계산!F47 -> 9785 | G17: =IF(D17=0,"미산출",F17/D17) -> 0.95 | H17: =E17-F17 -> 0 | I17: =IF(E17=0,"미산출",ROUND(H17/E17,8)) -> 0 | J17: =(F17-E17)*손익계산!I47 -> 0 | K17: =MAX(-J17,0) -> 0 | L17: =IF(D17=0,"미산출",ROUND(MAX(1-G17,0),8)) -> 0.05 | M17: =IF(OR(I17>=버전기준!$B$17,K17>=버전기준!$B$19,L17>=버전기준!$B$21),"중요",IF(OR(I17>=버전기준!$B$16,K17>=버전기준!$B$18,L17>=버전기준!$B$20),"관심","기준 이내")) -> 관심 | N17: =IF(M17="중요","기존 이슈 상향·Review",IF(H17<>0,"현업 변경검토",IF(M17="관심","기존 관심 추적","추가 변경없음"))) -> 기존 관심 추적
... A20: RUN-F02-001 | B20: 46631 | C20: A-e | D20: =손익계산!D50 -> 3090 | E20: =손익계산!E50 -> 3059 | F20: =손익계산!F50 -> 3059 | G20: =IF(D20=0,"미산출",F20/D20) -> 0.98996764 | H20: =E20-F20 -> 0 | I20: =IF(E20=0,"미산출",ROUND(H20/E20,8)) -> 0 | J20: =(F20-E20)*손익계산!I50 -> 0 | K20: =MAX(-J20,0) -> 0 | L20: =IF(D20=0,"미산출",ROUND(MAX(1-G20,0),8)) -> 0.01003236 | M20: =IF(OR(I20>=버전기준!$B$17,K20>=버전기준!$B$19,L20>=버전기준!$B$21),"중요",IF(OR(I20>=버전기준!$B$16,K20>=버전기준!$B$18,L20>=버전기준!$B$20),"관심","기준 이내")) -> 기준 이내 | N20: =IF(M20="중요","기존 이슈 상향·Review",IF(H20<>0,"현업 변경검토",IF(M20="관심","기존 관심 추적","추가 변경없음"))) -> 추가 변경없음

Sheet 손익계산
A2: 모델·월별 손익 계산
A3: 원. 모델별 고정비 배부 없음. F01/F02 동일 가격·원가로 사건의 물량 영향만 분리.
A5: period | B5: quarter | C5: model_id | D5: T_qty | E5: F01_qty | F5: F02_qty | G5: price | H5: variable_cost | I5: unit_cm | J5: T_revenue | K5: F01_revenue | L5: F02_revenue | M5: T_cm | N5: F01_cm | O5: F02_cm | P5: actual_qty | Q5: actual_revenue | R5: actual_cm
A6: 46388 | B6: 1 | C6: A-a | D6: =물량스냅샷!F6 -> 4080 | E6: =물량스냅샷!F66 -> 4080 | F6: =물량스냅샷!F126 -> 4080 | G6: =단위원가!F6 -> 300000 | H6: =단위원가!J6 -> 270000 | I6: =단위원가!K6 -> 30000 | J6: =D6*G6 -> 1224000000 | K6: =E6*G6 -> 1224000000 | L6: =F6*G6 -> 1224000000 | M6: =D6*I6 -> 122400000 | N6: =E6*I6 -> 122400000 | O6: =F6*I6 -> 122400000 | P6: =실적!H6 -> 4080 | Q6: =P6*G6 -> 1224000000 | R6: =P6*I6 -> 122400000
A7: 46388 | B7: 1 | C7: A-b | D7: =물량스냅샷!F7 -> 10200 | E7: =물량스냅샷!F67 -> 10200 | F7: =물량스냅샷!F127 -> 10200 | G7: =단위원가!F7 -> 180000 | H7: =단위원가!J7 -> 160000 | I7: =단위원가!K7 -> 20000 | J7: =D7*G7 -> 1836000000 | K7: =E7*G7 -> 1836000000 | L7: =F7*G7 -> 1836000000 | M7: =D7*I7 -> 204000000 | N7: =E7*I7 -> 204000000 | O7: =F7*I7 -> 204000000 | P7: =실적!H7 -> 10200 | Q7: =P7*G7 -> 1836000000 | R7: =P7*I7 -> 204000000
A8: 46388 | B8: 1 | C8: A-c | D8: =물량스냅샷!F8 -> 6120 | E8: =물량스냅샷!F68 -> 6059 | F8: =물량스냅샷!F128 -> 6059 | G8: =단위원가!F8 -> 230000 | H8: =단위원가!J8 -> 202000 | I8: =단위원가!K8 -> 28000 | J8: =D8*G8 -> 1407600000 | K8: =E8*G8 -> 1393570000 | L8: =F8*G8 -> 1393570000 | M8: =D8*I8 -> 171360000 | N8: =E8*I8 -> 169652000 | O8: =F8*I8 -> 169652000 | P8: =실적!H8 -> 6059 | Q8: =P8*G8 -> 1393570000 | R8: =P8*I8 -> 169652000
A9: 46388 | B9: 1 | C9: A-d | D9: =물량스냅샷!F9 -> 5100 | E9: =물량스냅샷!F69 -> 5151 | F9: =물량스냅샷!F129 -> 5151 | G9: =단위원가!F9 -> 210000 | H9: =단위원가!J9 -> 185000 | I9: =단위원가!K9 -> 25000 | J9: =D9*G9 -> 1071000000 | K9: =E9*G9 -> 1081710000 | L9: =F9*G9 -> 1081710000 | M9: =D9*I9 -> 127500000 | N9: =E9*I9 -> 128775000 | O9: =F9*I9 -> 128775000 | P9: =실적!H9 -> 5151 | Q9: =P9*G9 -> 1081710000 | R9: =P9*I9 -> 128775000
A10: 46388 | B10: 1 | C10: A-e | D10: =물량스냅샷!F10 -> 3060 | E10: =물량스냅샷!F70 -> 3029 | F10: =물량스냅샷!F130 -> 3029 | G10: =단위원가!F10 -> 150000 | H10: =단위원가!J10 -> 132000 | I10: =단위원가!K10 -> 18000 | J10: =D10*G10 -> 459000000 | K10: =E10*G10 -> 454350000 | L10: =F10*G10 -> 454350000 | M10: =D10*I10 -> 55080000 | N10: =E10*I10 -> 54522000 | O10: =F10*I10 -> 54522000 | P10: =실적!H10 -> 3029 | Q10: =P10*G10 -> 454350000 | R10: =P10*I10 -> 54522000
A11: 46419 | B11: 1 | C11: A-a | D11: =물량스냅샷!F11 -> 3600 | E11: =물량스냅샷!F71 -> 3564 | F11: =물량스냅샷!F131 -> 3564 | G11: =단위원가!F11 -> 300000 | H11: =단위원가!J11 -> 270000 | I11: =단위원가!K11 -> 30000 | J11: =D11*G11 -> 1080000000 | K11: =E11*G11 -> 1069200000 | L11: =F11*G11 -> 1069200000 | M11: =D11*I11 -> 108000000 | N11: =E11*I11 -> 106920000 | O11: =F11*I11 -> 106920000 | P11: =실적!H11 -> 3564 | Q11: =P11*G11 -> 1069200000 | R11: =P11*I11 -> 106920000
A12: 46419 | B12: 1 | C12: A-b | D12: =물량스냅샷!F12 -> 9000 | E12: =물량스냅샷!F72 -> 8910 | F12: =물량스냅샷!F132 -> 8910 | G12: =단위원가!F12 -> 180000 | H12: =단위원가!J12 -> 160000 | I12: =단위원가!K12 -> 20000 | J12: =D12*G12 -> 1620000000 | K12: =E12*G12 -> 1603800000 | L12: =F12*G12 -> 1603800000 | M12: =D12*I12 -> 180000000 | N12: =E12*I12 -> 178200000 | O12: =F12*I12 -> 178200000 | P12: =실적!H12 -> 8910 | Q12: =P12*G12 -> 1603800000 | R12: =P12*I12 -> 178200000
A13: 46419 | B13: 1 | C13: A-c | D13: =물량스냅샷!F13 -> 5400 | E13: =물량스냅샷!F73 -> 5346 | F13: =물량스냅샷!F133 -> 5346 | G13: =단위원가!F13 -> 230000 | H13: =단위원가!J13 -> 202000 | I13: =단위원가!K13 -> 28000 | J13: =D13*G13 -> 1242000000 | K13: =E13*G13 -> 1229580000 | L13: =F13*G13 -> 1229580000 | M13: =D13*I13 -> 151200000 | N13: =E13*I13 -> 149688000 | O13: =F13*I13 -> 149688000 | P13: =실적!H13 -> 5346 | Q13: =P13*G13 -> 1229580000 | R13: =P13*I13 -> 149688000
A14: 46419 | B14: 1 | C14: A-d | D14: =물량스냅샷!F14 -> 4500 | E14: =물량스냅샷!F74 -> 4545 | F14: =물량스냅샷!F134 -> 4545 | G14: =단위원가!F14 -> 210000 | H14: =단위원가!J14 -> 185000 | I14: =단위원가!K14 -> 25000 | J14: =D14*G14 -> 945000000 | K14: =E14*G14 -> 954450000 | L14: =F14*G14 -> 954450000 | M14: =D14*I14 -> 112500000 | N14: =E14*I14 -> 113625000 | O14: =F14*I14 -> 113625000 | P14: =실적!H14 -> 4545 | Q14: =P14*G14 -> 954450000 | R14: =P14*I14 -> 113625000
A15: 46419 | B15: 1 | C15: A-e | D15: =물량스냅샷!F15 -> 2700 | E15: =물량스냅샷!F75 -> 2673 | F15: =물량스냅샷!F135 -> 2673 | G15: =단위원가!F15 -> 150000 | H15: =단위원가!J15 -> 132000 | I15: =단위원가!K15 -> 18000 | J15: =D15*G15 -> 405000000 | K15: =E15*G15 -> 400950000 | L15: =F15*G15 -> 400950000 | M15: =D15*I15 -> 48600000 | N15: =E15*I15 -> 48114000 | O15: =F15*I15 -> 48114000 | P15: =실적!H15 -> 2673 | Q15: =P15*G15 -> 400950000 | R15: =P15*I15 -> 48114000
A16: 46447 | B16: 1 | C16: A-a | D16: =물량스냅샷!F16 -> 4200 | E16: =물량스냅샷!F76 -> 4116 | F16: =물량스냅샷!F136 -> 4116 | G16: =단위원가!F16 -> 300000 | H16: =단위원가!J16 -> 270000 | I16: =단위원가!K16 -> 30000 | J16: =D16*G16 -> 1260000000 | K16: =E16*G16 -> 1234800000 | L16: =F16*G16 -> 1234800000 | M16: =D16*I16 -> 126000000 | N16: =E16*I16 -> 123480000 | O16: =F16*I16 -> 123480000 | P16: =실적!H16 -> 4116 | Q16: =P16*G16 -> 1234800000 | R16: =P16*I16 -> 123480000
A17: 46447 | B17: 1 | C17: A-b | D17: =물량스냅샷!F17 -> 10500 | E17: =물량스냅샷!F77 -> 10290 | F17: =물량스냅샷!F137 -> 10290 | G17: =단위원가!F17 -> 180000 | H17: =단위원가!J17 -> 160000 | I17: =단위원가!K17 -> 20000 | J17: =D17*G17 -> 1890000000 | K17: =E17*G17 -> 1852200000 | L17: =F17*G17 -> 1852200000 | M17: =D17*I17 -> 210000000 | N17: =E17*I17 -> 205800000 | O17: =F17*I17 -> 205800000 | P17: =실적!H17 -> 10290 | Q17: =P17*G17 -> 1852200000 | R17: =P17*I17 -> 205800000
... A35: 46539 | B35: 2 | C35: A-e | D35: =물량스냅샷!F35 -> 3000 | E35: =물량스냅샷!F95 -> 2970 | F35: =물량스냅샷!F155 -> 2970 | G35: =단위원가!F35 -> 150000 | H35: =단위원가!J35 -> 132000 | I35: =단위원가!K35 -> 18000 | J35: =D35*G35 -> 450000000 | K35: =E35*G35 -> 445500000 | L35: =F35*G35 -> 445500000 | M35: =D35*I35 -> 54000000 | N35: =E35*I35 -> 53460000 | O35: =F35*I35 -> 53460000 | P35: =실적!H35 -> 1336 | Q35: =P35*G35 -> 200400000 | R35: =P35*I35 -> 24048000
A36: 46569 | B36: 3 | C36: A-a | D36: =물량스냅샷!F36 -> 4000 | E36: =물량스냅샷!F96 -> 3800 | F36: =물량스냅샷!F156 -> 3800 | G36: =단위원가!F36 -> 300000 | H36: =단위원가!J36 -> 270000 | I36: =단위원가!K36 -> 30000 | J36: =D36*G36 -> 1200000000 | K36: =E36*G36 -> 1140000000 | L36: =F36*G36 -> 1140000000 | M36: =D36*I36 -> 120000000 | N36: =E36*I36 -> 114000000 | O36: =F36*I36 -> 114000000
A37: 46569 | B37: 3 | C37: A-b | D37: =물량스냅샷!F37 -> 10000 | E37: =물량스냅샷!F97 -> 9500 | F37: =물량스냅샷!F157 -> 8800 | G37: =단위원가!F37 -> 180000 | H37: =단위원가!J37 -> 160000 | I37: =단위원가!K37 -> 20000 | J37: =D37*G37 -> 1800000000 | K37: =E37*G37 -> 1710000000 | L37: =F37*G37 -> 1584000000 | M37: =D37*I37 -> 200000000 | N37: =E37*I37 -> 190000000 | O37: =F37*I37 -> 176000000
A38: 46569 | B38: 3 | C38: A-c | D38: =물량스냅샷!F38 -> 6000 | E38: =물량스냅샷!F98 -> 5940 | F38: =물량스냅샷!F158 -> 5940 | G38: =단위원가!F38 -> 230000 | H38: =단위원가!J38 -> 202000 | I38: =단위원가!K38 -> 28000 | J38: =D38*G38 -> 1380000000 | K38: =E38*G38 -> 1366200000 | L38: =F38*G38 -> 1366200000 | M38: =D38*I38 -> 168000000 | N38: =E38*I38 -> 166320000 | O38: =F38*I38 -> 166320000
A39: 46569 | B39: 3 | C39: A-d | D39: =물량스냅샷!F39 -> 5000 | E39: =물량스냅샷!F99 -> 5050 | F39: =물량스냅샷!F159 -> 5050 | G39: =단위원가!F39 -> 210000 | H39: =단위원가!J39 -> 185000 | I39: =단위원가!K39 -> 25000 | J39: =D39*G39 -> 1050000000 | K39: =E39*G39 -> 1060500000 | L39: =F39*G39 -> 1060500000 | M39: =D39*I39 -> 125000000 | N39: =E39*I39 -> 126250000 | O39: =F39*I39 -> 126250000
A40: 46569 | B40: 3 | C40: A-e | D40: =물량스냅샷!F40 -> 3000 | E40: =물량스냅샷!F100 -> 2970 | F40: =물량스냅샷!F160 -> 2970 | G40: =단위원가!F40 -> 150000 | H40: =단위원가!J40 -> 132000 | I40: =단위원가!K40 -> 18000 | J40: =D40*G40 -> 450000000 | K40: =E40*G40 -> 445500000 | L40: =F40*G40 -> 445500000 | M40: =D40*I40 -> 54000000 | N40: =E40*I40 -> 53460000 | O40: =F40*I40 -> 53460000
A41: 46600 | B41: 3 | C41: A-a | D41: =물량스냅샷!F41 -> 3680 | E41: =물량스냅샷!F101 -> 3496 | F41: =물량스냅샷!F161 -> 3496 | G41: =단위원가!F41 -> 300000 | H41: =단위원가!J41 -> 270000 | I41: =단위원가!K41 -> 30000 | J41: =D41*G41 -> 1104000000 | K41: =E41*G41 -> 1048800000 | L41: =F41*G41 -> 1048800000 | M41: =D41*I41 -> 110400000 | N41: =E41*I41 -> 104880000 | O41: =F41*I41 -> 104880000
A42: 46600 | B42: 3 | C42: A-b | D42: =물량스냅샷!F42 -> 9200 | E42: =물량스냅샷!F102 -> 8740 | F42: =물량스냅샷!F162 -> 8740 | G42: =단위원가!F42 -> 180000 | H42: =단위원가!J42 -> 160000 | I42: =단위원가!K42 -> 20000 | J42: =D42*G42 -> 1656000000 | K42: =E42*G42 -> 1573200000 | L42: =F42*G42 -> 1573200000 | M42: =D42*I42 -> 184000000 | N42: =E42*I42 -> 174800000 | O42: =F42*I42 -> 174800000
A43: 46600 | B43: 3 | C43: A-c | D43: =물량스냅샷!F43 -> 5520 | E43: =물량스냅샷!F103 -> 5465 | F43: =물량스냅샷!F163 -> 5465 | G43: =단위원가!F43 -> 230000 | H43: =단위원가!J43 -> 202000 | I43: =단위원가!K43 -> 28000 | J43: =D43*G43 -> 1269600000 | K43: =E43*G43 -> 1256950000 | L43: =F43*G43 -> 1256950000 | M43: =D43*I43 -> 154560000 | N43: =E43*I43 -> 153020000 | O43: =F43*I43 -> 153020000
A44: 46600 | B44: 3 | C44: A-d | D44: =물량스냅샷!F44 -> 4600 | E44: =물량스냅샷!F104 -> 4646 | F44: =물량스냅샷!F164 -> 4646 | G44: =단위원가!F44 -> 210000 | H44: =단위원가!J44 -> 185000 | I44: =단위원가!K44 -> 25000 | J44: =D44*G44 -> 966000000 | K44: =E44*G44 -> 975660000 | L44: =F44*G44 -> 975660000 | M44: =D44*I44 -> 115000000 | N44: =E44*I44 -> 116150000 | O44: =F44*I44 -> 116150000
A45: 46600 | B45: 3 | C45: A-e | D45: =물량스냅샷!F45 -> 2760 | E45: =물량스냅샷!F105 -> 2732 | F45: =물량스냅샷!F165 -> 2732 | G45: =단위원가!F45 -> 150000 | H45: =단위원가!J45 -> 132000 | I45: =단위원가!K45 -> 18000 | J45: =D45*G45 -> 414000000 | K45: =E45*G45 -> 409800000 | L45: =F45*G45 -> 409800000 | M45: =D45*I45 -> 49680000 | N45: =E45*I45 -> 49176000 | O45: =F45*I45 -> 49176000
A46: 46631 | B46: 3 | C46: A-a | D46: =물량스냅샷!F46 -> 4120 | E46: =물량스냅샷!F106 -> 3914 | F46: =물량스냅샷!F166 -> 3914 | G46: =단위원가!F46 -> 300000 | H46: =단위원가!J46 -> 270000 | I46: =단위원가!K46 -> 30000 | J46: =D46*G46 -> 1236000000 | K46: =E46*G46 -> 1174200000 | L46: =F46*G46 -> 1174200000 | M46: =D46*I46 -> 123600000 | N46: =E46*I46 -> 117420000 | O46: =F46*I46 -> 117420000
A47: 46631 | B47: 3 | C47: A-b | D47: =물량스냅샷!F47 -> 10300 | E47: =물량스냅샷!F107 -> 9785 | F47: =물량스냅샷!F167 -> 9785 | G47: =단위원가!F47 -> 180000 | H47: =단위원가!J47 -> 160000 | I47: =단위원가!K47 -> 20000 | J47: =D47*G47 -> 1854000000 | K47: =E47*G47 -> 1761300000 | L47: =F47*G47 -> 1761300000 | M47: =D47*I47 -> 206000000 | N47: =E47*I47 -> 195700000 | O47: =F47*I47 -> 195700000
... A65: 46722 | B65: 4 | C65: A-e | D65: =물량스냅샷!F65 -> 2850 | E65: =물량스냅샷!F125 -> 2822 | F65: =물량스냅샷!F185 -> 2822 | G65: =단위원가!F65 -> 150000 | H65: =단위원가!J65 -> 132000 | I65: =단위원가!K65 -> 18000 | J65: =D65*G65 -> 427500000 | K65: =E65*G65 -> 423300000 | L65: =F65*G65 -> 423300000 | M65: =D65*I65 -> 51300000 | N65: =E65*I65 -> 50796000 | O65: =F65*I65 -> 50796000

Sheet 모델기준
A2: 모델·단위원가 기준 가정
A3: 모든 원가·가격은 가상 제안. b는 외주비 비중이 높음. A-a 수익성 우위를 전제하지 않음.
A5: model_id | B5: 성격 | C5: customer_id | D5: plant_id | E5: 기준월수량 | F5: 단가_원 | G5: 재료비_원 | H5: 외주비_원 | I5: 변동가공비_원 | J5: 미래전망계수 | K5: 변동비_원 | L5: 공헌이익_원
A6: A-a | B6: 고급차종 | C6: CUS-HK | D6: ULS | E6: 4000 | F6: 300000 | G6: 175000 | H6: 75000 | I6: 20000 | J6: 0.95 | K6: =SUM(G6:I6) -> 270000 | L6: =F6-K6 -> 30000
A7: A-b | B7: 소형차종 | C7: CUS-HK | D7: ULS | E7: 10000 | F7: 180000 | G7: 55000 | H7: 95000 | I7: 10000 | J7: 0.95 | K7: =SUM(G7:I7) -> 160000 | L7: =F7-K7 -> 20000
A8: A-c | B8: 일반차종1 | C8: CUS-HK | D8: ULS | E8: 6000 | F8: 230000 | G8: 125000 | H8: 60000 | I8: 17000 | J8: 0.99 | K8: =SUM(G8:I8) -> 202000 | L8: =F8-K8 -> 28000
A9: A-d | B9: 일반차종2 | C9: CUS-HK | D9: ULS | E9: 5000 | F9: 210000 | G9: 105000 | H9: 65000 | I9: 15000 | J9: 1.01 | K9: =SUM(G9:I9) -> 185000 | L9: =F9-K9 -> 25000
A10: A-e | B10: 일반차종3 | C10: CUS-HK | D10: ULS | E10: 3000 | F10: 150000 | G10: 70000 | H10: 50000 | I10: 12000 | J10: 0.99 | K10: =SUM(G10:I10) -> 132000 | L10: =F10-K10 -> 18000

Sheet 버전기준
A2: 버전과 적용 시점
A3: 시각은 KST 표시 문자열; 구현 시 ISO8601 +09:00으로 변환. 원천 수신 시각과 실적 컷오프를 구분.
A5: version_id | B5: 종류 | C5: 기준시각 | D5: 대상기간 | E5: 상태 | F5: source_id | G5: actual_cutoff | H5: 설명 | I5: 비고
A6: T01 | B6: Target | C6: 2026-12-20 18:00:00 KST | D6: 2027-01~12 | E6: 승인 | F6: NONE | G6: NONE | H6: 2027연간목표 | I6: 원본 유지
A7: CP01 | B7: CustomerPlan | C7: 2027-06-01 09:00:00 KST | D7: 2027-07~09 | E7: 고객확인 | F7: SRC01 | G7: NONE | H7: 당사배정 월전체 | I7: 40% 재적용 금지
A8: F01 | B8: Forecast | C8: 2027-06-15 18:00:00 KST | D8: 2027-01~12 | E8: 승인 | F8: SRC01 | G8: 2027-06-15 | H8: 직전 승인 전망 | I8: 과거=실적,10~12=내부가정
A9: CP02 | B9: CustomerPlan | C9: 2027-06-16 09:00:00 KST | D9: 2027-07~09 | E9: 수신→확인 | F9: SRC02 | G9: NONE | H9: 당사배정 월전체 | I9: 7월b만700감소
A10: F02 | B10: Forecast | C10: 2027-06-16 10:10:00 KST | D10: 2027-01~12 | E10: 확인·검토중 | F10: SRC02 | G10: 2027-06-15 | H10: 사건 후 검토 전망 | I10: 승인 전. 기존 승인값F01 유지
A11: C01 | B11: Cost | C11: 2027-06-01 00:00:00 KST | D11: 2027-01~12 | E11: 승인 | F11: SYNTHETIC | G11: NONE | H11: 같은 단가·원가 기준 | I11: 장면2는 C02로 확장
A12: R01-v1 | B12: Rule | C12: 2027-06-01 00:00:00 KST | D12: 2027-01~12 | E12: Pilot기준 | F12: v0.5합의 | G12: NONE | H12: 모델·월별 경보 | I12: 규칙은 아래 수치표
A15: rule_key | B15: value
A16: 감소율_관심 | B16: 0.03
A17: 감소율_중요 | B17: 0.05
A18: 감소액_관심 | B18: 5000000
A19: 감소액_중요 | B19: 10000000
A20: 부족률_관심 | B20: 0.05
A21: 부족률_중요 | B21: 0.1

Sheet 고객원천
A2: 고객 생산계획 시드
A3: 30행=2버전×3개월×5모델. 원천은 당사 배정물량이며 원본을 보존.
A5: source_id | B5: customer_plan_id | C5: customer_id | D5: plant_id | E5: model_id | F5: period | G5: quantity | H5: unit | I5: quantity_scope | J5: allocation_scope | K5: mapping_basis | L5: certainty
A6: SRC01 | B6: CP01 | C6: CUS-HK | D6: ULS | E6: A-a | F6: 46569 | G6: 3800 | H6: 대분 | I6: FULL_MONTH | J6: ASSIGNED_SUPPLY | K6: 직접매핑 | L6: 고객계획상 물량
A7: SRC01 | B7: CP01 | C7: CUS-HK | D7: ULS | E7: A-b | F7: 46569 | G7: 9500 | H7: 대분 | I7: FULL_MONTH | J7: ASSIGNED_SUPPLY | K7: 직접매핑 | L7: 고객계획상 물량
A8: SRC01 | B8: CP01 | C8: CUS-HK | D8: ULS | E8: A-c | F8: 46569 | G8: 5940 | H8: 대분 | I8: FULL_MONTH | J8: ASSIGNED_SUPPLY | K8: 직접매핑 | L8: 고객계획상 물량
A9: SRC01 | B9: CP01 | C9: CUS-HK | D9: ULS | E9: A-d | F9: 46569 | G9: 5050 | H9: 대분 | I9: FULL_MONTH | J9: ASSIGNED_SUPPLY | K9: 직접매핑 | L9: 고객계획상 물량
A10: SRC01 | B10: CP01 | C10: CUS-HK | D10: ULS | E10: A-e | F10: 46569 | G10: 2970 | H10: 대분 | I10: FULL_MONTH | J10: ASSIGNED_SUPPLY | K10: 직접매핑 | L10: 고객계획상 물량
A11: SRC01 | B11: CP01 | C11: CUS-HK | D11: ULS | E11: A-a | F11: 46600 | G11: 3496 | H11: 대분 | I11: FULL_MONTH | J11: ASSIGNED_SUPPLY | K11: 직접매핑 | L11: 고객계획상 물량
A12: SRC01 | B12: CP01 | C12: CUS-HK | D12: ULS | E12: A-b | F12: 46600 | G12: 8740 | H12: 대분 | I12: FULL_MONTH | J12: ASSIGNED_SUPPLY | K12: 직접매핑 | L12: 고객계획상 물량
A13: SRC01 | B13: CP01 | C13: CUS-HK | D13: ULS | E13: A-c | F13: 46600 | G13: 5465 | H13: 대분 | I13: FULL_MONTH | J13: ASSIGNED_SUPPLY | K13: 직접매핑 | L13: 고객계획상 물량
A14: SRC01 | B14: CP01 | C14: CUS-HK | D14: ULS | E14: A-d | F14: 46600 | G14: 4646 | H14: 대분 | I14: FULL_MONTH | J14: ASSIGNED_SUPPLY | K14: 직접매핑 | L14: 고객계획상 물량
A15: SRC01 | B15: CP01 | C15: CUS-HK | D15: ULS | E15: A-e | F15: 46600 | G15: 2732 | H15: 대분 | I15: FULL_MONTH | J15: ASSIGNED_SUPPLY | K15: 직접매핑 | L15: 고객계획상 물량
A16: SRC01 | B16: CP01 | C16: CUS-HK | D16: ULS | E16: A-a | F16: 46631 | G16: 3914 | H16: 대분 | I16: FULL_MONTH | J16: ASSIGNED_SUPPLY | K16: 직접매핑 | L16: 고객계획상 물량
A17: SRC01 | B17: CP01 | C17: CUS-HK | D17: ULS | E17: A-b | F17: 46631 | G17: 9785 | H17: 대분 | I17: FULL_MONTH | J17: ASSIGNED_SUPPLY | K17: 직접매핑 | L17: 고객계획상 물량
... A35: SRC02 | B35: CP02 | C35: CUS-HK | D35: ULS | E35: A-e | F35: 46631 | G35: 3059 | H35: 대분 | I35: FULL_MONTH | J35: ASSIGNED_SUPPLY | K35: 직접매핑 | L35: 고객계획상 물량

Sheet 물량스냅샷
A2: 목표·직전·최신 공급물량
A3: 180행=3버전×12개월×5모델. PK=version/customer/plant/model/period. 계획 전체월 값에 누계 재가산 금지.
A5: version_id | B5: customer_id | C5: plant_id | D5: model_id | E5: period | F5: quantity | G5: basis | H5: source_ref | I5: certainty | J5: status | K5: quantity_scope
A6: T01 | B6: CUS-HK | C6: ULS | D6: A-a | E6: 46388 | F6: 4080 | G6: TARGET | H6: T01 | I6: 목표 | J6: 승인 | K6: FULL_MONTH
A7: T01 | B7: CUS-HK | C7: ULS | D7: A-b | E7: 46388 | F7: 10200 | G7: TARGET | H7: T01 | I7: 목표 | J7: 승인 | K7: FULL_MONTH
A8: T01 | B8: CUS-HK | C8: ULS | D8: A-c | E8: 46388 | F8: 6120 | G8: TARGET | H8: T01 | I8: 목표 | J8: 승인 | K8: FULL_MONTH
A9: T01 | B9: CUS-HK | C9: ULS | D9: A-d | E9: 46388 | F9: 5100 | G9: TARGET | H9: T01 | I9: 목표 | J9: 승인 | K9: FULL_MONTH
A10: T01 | B10: CUS-HK | C10: ULS | D10: A-e | E10: 46388 | F10: 3060 | G10: TARGET | H10: T01 | I10: 목표 | J10: 승인 | K10: FULL_MONTH
A11: T01 | B11: CUS-HK | C11: ULS | D11: A-a | E11: 46419 | F11: 3600 | G11: TARGET | H11: T01 | I11: 목표 | J11: 승인 | K11: FULL_MONTH
A12: T01 | B12: CUS-HK | C12: ULS | D12: A-b | E12: 46419 | F12: 9000 | G12: TARGET | H12: T01 | I12: 목표 | J12: 승인 | K12: FULL_MONTH
A13: T01 | B13: CUS-HK | C13: ULS | D13: A-c | E13: 46419 | F13: 5400 | G13: TARGET | H13: T01 | I13: 목표 | J13: 승인 | K13: FULL_MONTH
A14: T01 | B14: CUS-HK | C14: ULS | D14: A-d | E14: 46419 | F14: 4500 | G14: TARGET | H14: T01 | I14: 목표 | J14: 승인 | K14: FULL_MONTH
A15: T01 | B15: CUS-HK | C15: ULS | D15: A-e | E15: 46419 | F15: 2700 | G15: TARGET | H15: T01 | I15: 목표 | J15: 승인 | K15: FULL_MONTH
A16: T01 | B16: CUS-HK | C16: ULS | D16: A-a | E16: 46447 | F16: 4200 | G16: TARGET | H16: T01 | I16: 목표 | J16: 승인 | K16: FULL_MONTH
A17: T01 | B17: CUS-HK | C17: ULS | D17: A-b | E17: 46447 | F17: 10500 | G17: TARGET | H17: T01 | I17: 목표 | J17: 승인 | K17: FULL_MONTH
... A185: F02 | B185: CUS-HK | C185: ULS | D185: A-e | E185: 46722 | F185: 2822 | G185: FORECAST | H185: INTERNAL | I185: 내부가정 | J185: 확인·검토중 | K185: FULL_MONTH

Sheet 실적
A2: 확정 월실적과 6월 누계
A3: 30행. 6월16일 이후 실적은 존재하지 않음. 6월 누계비중45%는 가상 가정.
A5: actual_version | B5: customer_id | C5: plant_id | D5: model_id | E5: period | F5: cutoff_date | G5: coverage | H5: quantity | I5: status
A6: ACT01 | B6: CUS-HK | C6: ULS | D6: A-a | E6: 46388 | F6: 46418 | G6: CLOSED_MONTH | H6: 4080 | I6: 확정
A7: ACT01 | B7: CUS-HK | C7: ULS | D7: A-b | E7: 46388 | F7: 46418 | G7: CLOSED_MONTH | H7: 10200 | I7: 확정
A8: ACT01 | B8: CUS-HK | C8: ULS | D8: A-c | E8: 46388 | F8: 46418 | G8: CLOSED_MONTH | H8: 6059 | I8: 확정
A9: ACT01 | B9: CUS-HK | C9: ULS | D9: A-d | E9: 46388 | F9: 46418 | G9: CLOSED_MONTH | H9: 5151 | I9: 확정
A10: ACT01 | B10: CUS-HK | C10: ULS | D10: A-e | E10: 46388 | F10: 46418 | G10: CLOSED_MONTH | H10: 3029 | I10: 확정
A11: ACT01 | B11: CUS-HK | C11: ULS | D11: A-a | E11: 46419 | F11: 46446 | G11: CLOSED_MONTH | H11: 3564 | I11: 확정
A12: ACT01 | B12: CUS-HK | C12: ULS | D12: A-b | E12: 46419 | F12: 46446 | G12: CLOSED_MONTH | H12: 8910 | I12: 확정
A13: ACT01 | B13: CUS-HK | C13: ULS | D13: A-c | E13: 46419 | F13: 46446 | G13: CLOSED_MONTH | H13: 5346 | I13: 확정
A14: ACT01 | B14: CUS-HK | C14: ULS | D14: A-d | E14: 46419 | F14: 46446 | G14: CLOSED_MONTH | H14: 4545 | I14: 확정
A15: ACT01 | B15: CUS-HK | C15: ULS | D15: A-e | E15: 46419 | F15: 46446 | G15: CLOSED_MONTH | H15: 2673 | I15: 확정
A16: ACT01 | B16: CUS-HK | C16: ULS | D16: A-a | E16: 46447 | F16: 46477 | G16: CLOSED_MONTH | H16: 4116 | I16: 확정
A17: ACT01 | B17: CUS-HK | C17: ULS | D17: A-b | E17: 46447 | F17: 46477 | G17: CLOSED_MONTH | H17: 10290 | I17: 확정
... A35: ACT06 | B35: CUS-HK | C35: ULS | D35: A-e | E35: 46539 | F35: 46553 | G35: MONTH_TO_DATE | H35: 1336 | I35: 누계확인

Sheet 단위원가
A2: 모델·월별 단가 및 변동비
A3: 60행. 원가버전C01. 원/대분. 가격·재료·외주·변동가공비만으로 공헌이익 계산.
A5: cost_version | B5: customer_id | C5: plant_id | D5: model_id | E5: period | F5: unit_price | G5: material | H5: outsource | I5: variable_conversion | J5: unit_variable_cost | K5: unit_cm
A6: C01 | B6: CUS-HK | C6: ULS | D6: A-a | E6: 46388 | F6: =모델기준!F6 -> 300000 | G6: =모델기준!G6 -> 175000 | H6: =모델기준!H6 -> 75000 | I6: =모델기준!I6 -> 20000 | J6: =SUM(G6:I6) -> 270000 | K6: =F6-J6 -> 30000
A7: C01 | B7: CUS-HK | C7: ULS | D7: A-b | E7: 46388 | F7: =모델기준!F7 -> 180000 | G7: =모델기준!G7 -> 55000 | H7: =모델기준!H7 -> 95000 | I7: =모델기준!I7 -> 10000 | J7: =SUM(G7:I7) -> 160000 | K7: =F7-J7 -> 20000
A8: C01 | B8: CUS-HK | C8: ULS | D8: A-c | E8: 46388 | F8: =모델기준!F8 -> 230000 | G8: =모델기준!G8 -> 125000 | H8: =모델기준!H8 -> 60000 | I8: =모델기준!I8 -> 17000 | J8: =SUM(G8:I8) -> 202000 | K8: =F8-J8 -> 28000
A9: C01 | B9: CUS-HK | C9: ULS | D9: A-d | E9: 46388 | F9: =모델기준!F9 -> 210000 | G9: =모델기준!G9 -> 105000 | H9: =모델기준!H9 -> 65000 | I9: =모델기준!I9 -> 15000 | J9: =SUM(G9:I9) -> 185000 | K9: =F9-J9 -> 25000
A10: C01 | B10: CUS-HK | C10: ULS | D10: A-e | E10: 46388 | F10: =모델기준!F10 -> 150000 | G10: =모델기준!G10 -> 70000 | H10: =모델기준!H10 -> 50000 | I10: =모델기준!I10 -> 12000 | J10: =SUM(G10:I10) -> 132000 | K10: =F10-J10 -> 18000
A11: C01 | B11: CUS-HK | C11: ULS | D11: A-a | E11: 46419 | F11: =모델기준!F6 -> 300000 | G11: =모델기준!G6 -> 175000 | H11: =모델기준!H6 -> 75000 | I11: =모델기준!I6 -> 20000 | J11: =SUM(G11:I11) -> 270000 | K11: =F11-J11 -> 30000
A12: C01 | B12: CUS-HK | C12: ULS | D12: A-b | E12: 46419 | F12: =모델기준!F7 -> 180000 | G12: =모델기준!G7 -> 55000 | H12: =모델기준!H7 -> 95000 | I12: =모델기준!I7 -> 10000 | J12: =SUM(G12:I12) -> 160000 | K12: =F12-J12 -> 20000
A13: C01 | B13: CUS-HK | C13: ULS | D13: A-c | E13: 46419 | F13: =모델기준!F8 -> 230000 | G13: =모델기준!G8 -> 125000 | H13: =모델기준!H8 -> 60000 | I13: =모델기준!I8 -> 17000 | J13: =SUM(G13:I13) -> 202000 | K13: =F13-J13 -> 28000
A14: C01 | B14: CUS-HK | C14: ULS | D14: A-d | E14: 46419 | F14: =모델기준!F9 -> 210000 | G14: =모델기준!G9 -> 105000 | H14: =모델기준!H9 -> 65000 | I14: =모델기준!I9 -> 15000 | J14: =SUM(G14:I14) -> 185000 | K14: =F14-J14 -> 25000
A15: C01 | B15: CUS-HK | C15: ULS | D15: A-e | E15: 46419 | F15: =모델기준!F10 -> 150000 | G15: =모델기준!G10 -> 70000 | H15: =모델기준!H10 -> 50000 | I15: =모델기준!I10 -> 12000 | J15: =SUM(G15:I15) -> 132000 | K15: =F15-J15 -> 18000
A16: C01 | B16: CUS-HK | C16: ULS | D16: A-a | E16: 46447 | F16: =모델기준!F6 -> 300000 | G16: =모델기준!G6 -> 175000 | H16: =모델기준!H6 -> 75000 | I16: =모델기준!I6 -> 20000 | J16: =SUM(G16:I16) -> 270000 | K16: =F16-J16 -> 30000
A17: C01 | B17: CUS-HK | C17: ULS | D17: A-b | E17: 46447 | F17: =모델기준!F7 -> 180000 | G17: =모델기준!G7 -> 55000 | H17: =모델기준!H7 -> 95000 | I17: =모델기준!I7 -> 10000 | J17: =SUM(G17:I17) -> 160000 | K17: =F17-J17 -> 20000
A18: C01 | B18: CUS-HK | C18: ULS | D18: A-c | E18: 46447 | F18: =모델기준!F8 -> 230000 | G18: =모델기준!G8 -> 125000 | H18: =모델기준!H8 -> 60000 | I18: =모델기준!I8 -> 17000 | J18: =SUM(G18:I18) -> 202000 | K18: =F18-J18 -> 28000
A19: C01 | B19: CUS-HK | C19: ULS | D19: A-d | E19: 46447 | F19: =모델기준!F9 -> 210000 | G19: =모델기준!G9 -> 105000 | H19: =모델기준!H9 -> 65000 | I19: =모델기준!I9 -> 15000 | J19: =SUM(G19:I19) -> 185000 | K19: =F19-J19 -> 25000
A20: C01 | B20: CUS-HK | C20: ULS | D20: A-e | E20: 46447 | F20: =모델기준!F10 -> 150000 | G20: =모델기준!G10 -> 70000 | H20: =모델기준!H10 -> 50000 | I20: =모델기준!I10 -> 12000 | J20: =SUM(G20:I20) -> 132000 | K20: =F20-J20 -> 18000
A21: C01 | B21: CUS-HK | C21: ULS | D21: A-a | E21: 46478 | F21: =모델기준!F6 -> 300000 | G21: =모델기준!G6 -> 175000 | H21: =모델기준!H6 -> 75000 | I21: =모델기준!I6 -> 20000 | J21: =SUM(G21:I21) -> 270000 | K21: =F21-J21 -> 30000
A22: C01 | B22: CUS-HK | C22: ULS | D22: A-b | E22: 46478 | F22: =모델기준!F7 -> 180000 | G22: =모델기준!G7 -> 55000 | H22: =모델기준!H7 -> 95000 | I22: =모델기준!I7 -> 10000 | J22: =SUM(G22:I22) -> 160000 | K22: =F22-J22 -> 20000
A23: C01 | B23: CUS-HK | C23: ULS | D23: A-c | E23: 46478 | F23: =모델기준!F8 -> 230000 | G23: =모델기준!G8 -> 125000 | H23: =모델기준!H8 -> 60000 | I23: =모델기준!I8 -> 17000 | J23: =SUM(G23:I23) -> 202000 | K23: =F23-J23 -> 28000
A24: C01 | B24: CUS-HK | C24: ULS | D24: A-d | E24: 46478 | F24: =모델기준!F9 -> 210000 | G24: =모델기준!G9 -> 105000 | H24: =모델기준!H9 -> 65000 | I24: =모델기준!I9 -> 15000 | J24: =SUM(G24:I24) -> 185000 | K24: =F24-J24 -> 25000
A25: C01 | B25: CUS-HK | C25: ULS | D25: A-e | E25: 46478 | F25: =모델기준!F10 -> 150000 | G25: =모델기준!G10 -> 70000 | H25: =모델기준!H10 -> 50000 | I25: =모델기준!I10 -> 12000 | J25: =SUM(G25:I25) -> 132000 | K25: =F25-J25 -> 18000
A26: C01 | B26: CUS-HK | C26: ULS | D26: A-a | E26: 46508 | F26: =모델기준!F6 -> 300000 | G26: =모델기준!G6 -> 175000 | H26: =모델기준!H6 -> 75000 | I26: =모델기준!I6 -> 20000 | J26: =SUM(G26:I26) -> 270000 | K26: =F26-J26 -> 30000
A27: C01 | B27: CUS-HK | C27: ULS | D27: A-b | E27: 46508 | F27: =모델기준!F7 -> 180000 | G27: =모델기준!G7 -> 55000 | H27: =모델기준!H7 -> 95000 | I27: =모델기준!I7 -> 10000 | J27: =SUM(G27:I27) -> 160000 | K27: =F27-J27 -> 20000
A28: C01 | B28: CUS-HK | C28: ULS | D28: A-c | E28: 46508 | F28: =모델기준!F8 -> 230000 | G28: =모델기준!G8 -> 125000 | H28: =모델기준!H8 -> 60000 | I28: =모델기준!I8 -> 17000 | J28: =SUM(G28:I28) -> 202000 | K28: =F28-J28 -> 28000
A29: C01 | B29: CUS-HK | C29: ULS | D29: A-d | E29: 46508 | F29: =모델기준!F9 -> 210000 | G29: =모델기준!G9 -> 105000 | H29: =모델기준!H9 -> 65000 | I29: =모델기준!I9 -> 15000 | J29: =SUM(G29:I29) -> 185000 | K29: =F29-J29 -> 25000
A30: C01 | B30: CUS-HK | C30: ULS | D30: A-e | E30: 46508 | F30: =모델기준!F10 -> 150000 | G30: =모델기준!G10 -> 70000 | H30: =모델기준!H10 -> 50000 | I30: =모델기준!I10 -> 12000 | J30: =SUM(G30:I30) -> 132000 | K30: =F30-J30 -> 18000
A31: C01 | B31: CUS-HK | C31: ULS | D31: A-a | E31: 46539 | F31: =모델기준!F6 -> 300000 | G31: =모델기준!G6 -> 175000 | H31: =모델기준!H6 -> 75000 | I31: =모델기준!I6 -> 20000 | J31: =SUM(G31:I31) -> 270000 | K31: =F31-J31 -> 30000
A32: C01 | B32: CUS-HK | C32: ULS | D32: A-b | E32: 46539 | F32: =모델기준!F7 -> 180000 | G32: =모델기준!G7 -> 55000 | H32: =모델기준!H7 -> 95000 | I32: =모델기준!I7 -> 10000 | J32: =SUM(G32:I32) -> 160000 | K32: =F32-J32 -> 20000
A33: C01 | B33: CUS-HK | C33: ULS | D33: A-c | E33: 46539 | F33: =모델기준!F8 -> 230000 | G33: =모델기준!G8 -> 125000 | H33: =모델기준!H8 -> 60000 | I33: =모델기준!I8 -> 17000 | J33: =SUM(G33:I33) -> 202000 | K33: =F33-J33 -> 28000
A34: C01 | B34: CUS-HK | C34: ULS | D34: A-d | E34: 46539 | F34: =모델기준!F9 -> 210000 | G34: =모델기준!G9 -> 105000 | H34: =모델기준!H9 -> 65000 | I34: =모델기준!I9 -> 15000 | J34: =SUM(G34:I34) -> 185000 | K34: =F34-J34 -> 25000
A35: C01 | B35: CUS-HK | C35: ULS | D35: A-e | E35: 46539 | F35: =모델기준!F10 -> 150000 | G35: =모델기준!G10 -> 70000 | H35: =모델기준!H10 -> 50000 | I35: =모델기준!I10 -> 12000 | J35: =SUM(G35:I35) -> 132000 | K35: =F35-J35 -> 18000
A36: C01 | B36: CUS-HK | C36: ULS | D36: A-a | E36: 46569 | F36: =모델기준!F6 -> 300000 | G36: =모델기준!G6 -> 175000 | H36: =모델기준!H6 -> 75000 | I36: =모델기준!I6 -> 20000 | J36: =SUM(G36:I36) -> 270000 | K36: =F36-J36 -> 30000
A37: C01 | B37: CUS-HK | C37: ULS | D37: A-b | E37: 46569 | F37: =모델기준!F7 -> 180000 | G37: =모델기준!G7 -> 55000 | H37: =모델기준!H7 -> 95000 | I37: =모델기준!I7 -> 10000 | J37: =SUM(G37:I37) -> 160000 | K37: =F37-J37 -> 20000
A38: C01 | B38: CUS-HK | C38: ULS | D38: A-c | E38: 46569 | F38: =모델기준!F8 -> 230000 | G38: =모델기준!G8 -> 125000 | H38: =모델기준!H8 -> 60000 | I38: =모델기준!I8 -> 17000 | J38: =SUM(G38:I38) -> 202000 | K38: =F38-J38 -> 28000
A39: C01 | B39: CUS-HK | C39: ULS | D39: A-d | E39: 46569 | F39: =모델기준!F9 -> 210000 | G39: =모델기준!G9 -> 105000 | H39: =모델기준!H9 -> 65000 | I39: =모델기준!I9 -> 15000 | J39: =SUM(G39:I39) -> 185000 | K39: =F39-J39 -> 25000
A40: C01 | B40: CUS-HK | C40: ULS | D40: A-e | E40: 46569 | F40: =모델기준!F10 -> 150000 | G40: =모델기준!G10 -> 70000 | H40: =모델기준!H10 -> 50000 | I40: =모델기준!I10 -> 12000 | J40: =SUM(G40:I40) -> 132000 | K40: =F40-J40 -> 18000
A41: C01 | B41: CUS-HK | C41: ULS | D41: A-a | E41: 46600 | F41: =모델기준!F6 -> 300000 | G41: =모델기준!G6 -> 175000 | H41: =모델기준!H6 -> 75000 | I41: =모델기준!I6 -> 20000 | J41: =SUM(G41:I41) -> 270000 | K41: =F41-J41 -> 30000
A42: C01 | B42: CUS-HK | C42: ULS | D42: A-b | E42: 46600 | F42: =모델기준!F7 -> 180000 | G42: =모델기준!G7 -> 55000 | H42: =모델기준!H7 -> 95000 | I42: =모델기준!I7 -> 10000 | J42: =SUM(G42:I42) -> 160000 | K42: =F42-J42 -> 20000
...

Sheet 고정비
A2: 공장 고정비 기준
A3: 원. 월 고정비 3억7천만원. 실제비용은1~5월 월액동일,6/15누계50% 가정. 미래실적은 빈칸.
A5: plant_id | B5: period | C5: fixed_labor | D5: depreciation | E5: facility | F5: other_fixed | G5: extra_fixed | H5: 설명 | I5: total_fixed | J5: actual_fixed
A6: ULS | B6: 46388 | C6: 120000000 | D6: 150000000 | E6: 80000000 | F6: 20000000 | G6: 0 | H6: 월전체 고정비. 세 전망 동일 | I6: =SUM(C6:G6) -> 370000000 | J6: =I6 -> 370000000
A7: ULS | B7: 46419 | C7: 120000000 | D7: 150000000 | E7: 80000000 | F7: 20000000 | G7: 0 | H7: 월전체 고정비. 세 전망 동일 | I7: =SUM(C7:G7) -> 370000000 | J7: =I7 -> 370000000
A8: ULS | B8: 46447 | C8: 120000000 | D8: 150000000 | E8: 80000000 | F8: 20000000 | G8: 0 | H8: 월전체 고정비. 세 전망 동일 | I8: =SUM(C8:G8) -> 370000000 | J8: =I8 -> 370000000
A9: ULS | B9: 46478 | C9: 120000000 | D9: 150000000 | E9: 80000000 | F9: 20000000 | G9: 0 | H9: 월전체 고정비. 세 전망 동일 | I9: =SUM(C9:G9) -> 370000000 | J9: =I9 -> 370000000
A10: ULS | B10: 46508 | C10: 120000000 | D10: 150000000 | E10: 80000000 | F10: 20000000 | G10: 0 | H10: 월전체 고정비. 세 전망 동일 | I10: =SUM(C10:G10) -> 370000000 | J10: =I10 -> 370000000
A11: ULS | B11: 46539 | C11: 120000000 | D11: 150000000 | E11: 80000000 | F11: 20000000 | G11: 0 | H11: 월전체 고정비. 세 전망 동일 | I11: =SUM(C11:G11) -> 370000000 | J11: =I11*0.5 -> 185000000
A12: ULS | B12: 46569 | C12: 120000000 | D12: 150000000 | E12: 80000000 | F12: 20000000 | G12: 0 | H12: 월전체 고정비. 세 전망 동일 | I12: =SUM(C12:G12) -> 370000000
A13: ULS | B13: 46600 | C13: 120000000 | D13: 150000000 | E13: 80000000 | F13: 20000000 | G13: 0 | H13: 월전체 고정비. 세 전망 동일 | I13: =SUM(C13:G13) -> 370000000
A14: ULS | B14: 46631 | C14: 120000000 | D14: 150000000 | E14: 80000000 | F14: 20000000 | G14: 0 | H14: 월전체 고정비. 세 전망 동일 | I14: =SUM(C14:G14) -> 370000000
A15: ULS | B15: 46661 | C15: 120000000 | D15: 150000000 | E15: 80000000 | F15: 20000000 | G15: 0 | H15: 월전체 고정비. 세 전망 동일 | I15: =SUM(C15:G15) -> 370000000
A16: ULS | B16: 46692 | C16: 120000000 | D16: 150000000 | E16: 80000000 | F16: 20000000 | G16: 0 | H16: 월전체 고정비. 세 전망 동일 | I16: =SUM(C16:G16) -> 370000000
A17: ULS | B17: 46722 | C17: 120000000 | D17: 150000000 | E17: 80000000 | F17: 20000000 | G17: 0 | H17: 월전체 고정비. 세 전망 동일 | I17: =SUM(C17:G17) -> 370000000

Sheet 업무이력
A2: 기본 시연의 상태 전개와 시드
A3: 이 표는 이벤트 실행명세. UI에는 현재 단계까지의 행만 노출. 묶인 task는 적재시 개별 행 생성.
A5: event_id | B5: event_at | C5: event_type | D5: issue_id | E5: run_id | F5: risk_level | G5: task_state | H5: actor_role | I5: due_at | J5: evidence | K5: 종료·처리 조건
A6: S0 | B6: 2027-06-15 18:00:00 KST | C6: 기준적재 | D6: ISSUE-A07/ISSUE-B07 | E6: RUN-F01-001 | F6: 관심/관심 | G6: 기존 이슈 관리중 | H6: 영업팀장 | I6: NONE | J6: T01·F01·CP01·ACT·C01·R01 | K6: F02/SRC02 미노출. 7월a,b 부족률5%
A7: EV01 | B7: 2027-06-16 09:00:00 KST | C7: 새계획수신 | D7: ISSUE-B07 | E7: NONE | F7: 이전수준 유지 | G7: TASK-DQ 접수 | H7: 영업담당 | I7: 2027-06-17 18:00:00 KST | J7: SRC02/CP02 | K7: a~e 7~9월. b7월만 감소
A8: EV02 | B8: 2027-06-16 10:00:00 KST | C8: 원천확인 | D8: ISSUE-B07 | E8: NONE | F8: 이전수준 유지 | G8: TASK-DQ 완료 | H8: 영업담당 | I8: 2027-06-17 18:00:00 KST | J8: source_id=SRC02 | K8: 매핑·단위·월전체·배정물량 확인
A9: EV03 | B9: 2027-06-16 10:10:00 KST | C9: 비교계산 | D9: ISSUE-B07 | E9: RUN-F02-001 | F9: 중요 | G9: TASK-SALES 검토중 | H9: 영업팀장 | I9: 2027-06-17 18:00:00 KST | J9: F02/T01/F01/C01/R01-v1 | K9: F02는 확인·검토중. 자동 승인 없음
A10: EV04 | B10: 2027-06-16 11:00:00 KST | C10: 후속배정 | D10: ISSUE-B07 | E10: RUN-F02-001 | F10: 중요 | G10: TASK-PROD/TASK-MAT 접수 | H10: 생산담당/자재담당 | I10: 2027-06-17 18:00:00 KST | J10: 생산·자재영향 검토요청 | K10: 변경승인 임원상신은 권한에 따름
A11: EV05 | B11: 2027-06-16 11:05:00 KST | C11: Review요청 | D11: ISSUE-B07 | E11: RUN-F02-001 | F11: 중요 | G11: TASK-FIN 접수 | H11: 경영관리담당 | I11: 2027-06-18 18:00:00 KST | J11: 통합손익 보고요청 | K11: 장면1 종료 시 분석완료 아님
A12: EV06 | B12: 2027-06-16 11:30:00 KST | C12: 현업인수 | D12: ISSUE-B07 | E12: RUN-F02-001 | F12: 중요 | G12: TASK-PROD/TASK-MAT 확인중 | H12: 생산담당/자재담당 | I12: 2027-06-17 18:00:00 KST | J12: 각 인수자·시각 기록 | K12: 두 task는 구현시 각각 행 생성
A13: EV07 | B13: 2027-06-16 11:45:00 KST | C13: 경영관리인수 | D13: ISSUE-B07 | E13: RUN-F02-001 | F13: 중요 | G13: TASK-FIN 작성중 / SC01완료 | H13: 경영관리담당 | I13: 2027-06-18 18:00:00 KST | J13: 인계완료·후속추적 | K13: F02 승인상태는 검토중 유지

Sheet 예외케이스
A2: 기본 데이터에서 분리한 예외 변형
A3: 각 변형은 BASE 시드를 복원한 후 지정 필드만 변경. 실제 구현 시 입력 파일·응답 검증으로 전환.
A5: case_id | B5: 목적 | C5: 기준 | D5: 변경할 값 | E5: 기대 계산·표시 | F5: 기대 업무 | G5: 초기화·주의
A6: BASE | B6: 기본 | C6: SRC02 | D6: 7월b 8800 | E6: 중요,700감소,14백만원감소 | F6: 기존 ISSUE-B07 갱신 | G6: 기본 S0부터 실행
A7: EX01 | B7: 경보없는 변경 | C7: SRC02 변형 | D7: 7월c 5940→5900 | E7: 감소율0.6734%,목표부족1.6667%,감소액112만원; 기준이내 | F7: 현업검토 필요, 중요Review 자동생성 없음 | G7: BASE와 별도 실행
A8: EX02 | B8: 누락 | C8: SRC02 변형 | D8: 7월b quantity=NULL | E8: 데이터보완,확정 계산·승인보류 | F8: 0으로 대체 금지 | G8: 오류행은 정상 시드에 미적재
A9: EX03 | B9: 정정 | C9: SRC03 / CP03 | D9: 7월b 8800→9000; 다른 값CP02 유지 | E9: F03,새run. 직전승인F01대비500감소·1천만원→중요 | F9: F02대비+200은 정정내역,공식 비교는F01 | G9: 이전run 보존
A10: EX04 | B10: 합계상쇄 | C10: SRC02 변형 | D10: 7월c 5940→6500, b8800 유지 | E10: c 순효과+1568만원; b−1400만원;합계+168만원 | F10: b 중요경보 유지 | G10: 현재 단위공헌이익 적용
A11: EX05 | B11: 확인된0 | C11: SRC02 변형 | D11: 7월b quantity=0 | E11: 9500감소,100%추가감소,1억9천만원감소 | F11: 중요·현업/경영검토 | G11: 누락과 구분
A12: EX06 | B12: 직전0 | C12: 독립 테스트 | D12: b Prior0,Latest100,Target100 | E12: 감소율 미산출,절대변화·손익 검토 | F12: 신규/재개 모델 별도검토 | G12: 기본 계산시트는 양의 분모 전용
A13: EX07 | B13: 기한초과 | C13: EV04 이후 | D13: 미인수 상태로6/17 18시 경과 | E13: 담당/상위검토자 알림 | F13: 장면종료 조건 미충족 | G13: 가상시계 이동
A14: EX08 | B14: Agent실패 | C14: EV02 | D14: 요약생성실패 | E14: 원천·규칙 계산은 보존,수동 검토 가능 | F14: 업무 완료로 오표시 금지 | G14: 실패로그와 대체입력

Sheet 데이터사전
A2: 적재·연결 및 자료형 계약
A3: 영문 헤더=키. 한글 헤더는 분석 표시용. 이 설계는 논리 데이터 계약이며 물리DB/API는 후속 구현명세.
A5: 데이터 | B5: 기본키 / 항목 | C5: 자료형·성격 | D5: 행수 / 값 | E5: 연결·처리 기준
A6: 모델기준 | B6: model_id | C6: 문자,PK | D6: A-a~A-e | E6: 고객·공장 고정 범위. 숫자 드라이버는 가상값
A7: 버전기준 | B7: version_id | C7: 문자,PK | D7: T01/F01/F02/CP01/CP02/C01/R01-v1 | E7: plan_kind·기준시점·확인/승인상태·actual_cutoff 참조
A8: 고객원천 | B8: customer_plan_id+customer_id+plant_id+model_id+period | C8: 복합PK | D8: 2×3×5=30행 | E8: period=월초DATE,quantity=정수대분,전체월·당사배정
A9: 물량스냅샷 | B9: version_id+customer_id+plant_id+model_id+period | C9: 복합PK | D9: 3×12×5=180행 | E9: 기초 데이터. basis ACTUAL/ACTUAL_PLUS_FORECAST/FORECAST/TARGET
A10: 실적 | B10: actual_version+customer_id+plant_id+model_id+period | C10: 복합PK | D10: 6×5=30행 | E10: cutoff_date=DATE. 6월행은월누계, 이후실적 없음
A11: 단위원가 | B11: cost_version+customer_id+plant_id+model_id+period | C11: 복합PK | D11: 12×5=60행 | E11: 원/대분 DECIMAL. 금액=수량×단가. Excel은기준에서계산
A12: 고정비 | B12: plant_id+period | C12: 복합PK | D12: 12행 | E12: 원 DECIMAL. 세 전망 동일. 공장합계에서1회 차감
A13: 손익계산 | B13: period+model_id | C13: 파생 뷰 키 | D13: 60행 | E13: 원천버전별 수량·매출·공헌이익. 미래 actual은NULL
A14: 월분기연간 | B14: 기간 | C14: 출력 뷰 | D14: 12개월+4분기+연간 | E14: 월합계→분기→연간. 비율 단순평균 금지
A15: SC01검증 | B15: run_id+period+model_id | C15: 파생 결과키 | D15: 15행 | E15: 지표ID는열→적재시long 형태변환. 원가·규칙버전run에고정
A16: 업무이력 | B16: event_id | C16: 이벤트 명세 키 | D16: 8단계 | E16: task_id/issue_id/run_id FK. 실제 task·actor·상태이력은개별행
... A21: 연간전망 | B21: 실적+잔여전망 | C21: 적용 규칙 | D21: 1~5월 actual,6월누계+잔여,7~12전망 | E21: 기준일 이후확정실적 유출 금지. 승인값과검토값 구분

Sheet 정합성검증
A2: 데이터 정합성 검증
A3: 차이0=일치. PK·FK·행수·원천버전·예외값은 생성 코드에서 추가 검증. Excel native앱 실행은 미검증.
A5: ID | B5: 검증 내용 | C5: 기대값 | D5: 계산값 | E5: 차이
A6: V01 | B6: 기본 시드행수 | C6: 180 | D6: 180 | E6: =D6-C6 -> 0
A7: V02 | B7: b7월추가감소 | C7: 700 | D7: =SC01검증!H7 -> 700 | E7: =D7-C7 -> 0
A8: V03 | B8: b7월감소액 | C8: 14000000 | D8: =SC01검증!K7 -> 14000000 | E8: =D8-C8 -> 0
A9: V04 | B9: 연간사건순효과 | C9: -14000000 | D9: =월분기연간!O22 -> -14000000 | E9: =D9-C9 -> 0
A10: V05 | B10: Q3사건순효과 | C10: -14000000 | D10: =월분기연간!O20 -> -14000000 | E10: =D10-C10 -> 0
A11: V06 | B11: 연간매출=분기합 | C11: 0 | D11: =월분기연간!E22-SUM(월분기연간!E18:E21) -> 0 | E11: =D11-C11 -> 0
A12: V07 | B12: 연간손익=분기합 | C12: 0 | D12: =월분기연간!N22-SUM(월분기연간!N18:N21) -> 0 | E12: =D12-C12 -> 0
A13: V08 | B13: 6월누계+잔여=월전망 | C13: 0 | D13: =SUM(실적!H31:H35)+월분기연간!Q11-SUM(손익계산!F31:F35) -> 0 | E13: =D13-C13 -> 0
A14: V09 | B14: a7월추가감소 | C14: 0 | D14: =SC01검증!H6 -> 0 | E14: =D14-C14 -> 0
A15: V10 | B15: 원천CP02와F02의7~9월 차이 | C15: 0 | D15: =SUM(고객원천!G21:G35)-SUM(물량스냅샷!F156:F170) -> 0 | E15: =D15-C15 -> 0
A16: V11 | B16: 1~5월F02물량=마감실적 | C16: 0 | D16: =SUM(실적!H6:H30)-SUM(물량스냅샷!F126:F150) -> 0 | E16: =D16-C16 -> 0
A17: V12 | B17: 공장고정비=12개월합 | C17: 4440000000 | D17: =SUM(고정비!I6:I17) -> 4440000000 | E17: =D17-C17 -> 0
A18: V13 | B18: 가격−변동비=기준공헌이익 | C18: 0 | D18: =SUM(단위원가!K6:K65)-SUM(손익계산!I6:I65) -> 0 | E18: =D18-C18 -> 0
